Workbook

Sheet Rohdaten
A1: Tag 1 Zuoz | B1: Course | G1: Manu | AK1: Parli | BO1: Meiky | CS1: Pulfer | DW1: Sutti | FA1: Jens | GE1: Köbi | HI1: Lenz | IM1: Aui
B2: Abschnitt | C2: Loch | D2: Loch kum | E2: Par | F2: Par kum | G2: Schläge | H2: Schläge kum | I2: Putts | J2: Putts kum | K2: GIR | L2: GIR kum | M2: Scramble | N2: Scramble kum | O2: Unnötige Putts | P2: Birdie | Q2: Birdie kum | R2: Pars | S2: Pars kum | T2: Bogeys | U2: Bogeys kum | V2: D.Bogey+ | W2: D.Bogey+ kum | X2: Chip in | Y2: Chip in kum | Z2: 1 Put | AA2: 1 Put kum | AB2: 2 Put | AC2: 2 Put kum | AD2: 3+ Put | AE2: 3+ Put kum | AF2: Par3 Perf | AG2: Par4 Perf | AH2: Par5 Perf | AI2: Netto | AJ2: Netto kum | AK2: Schläge | AL2: Schläge kum | AM2: Putts | AN2: Putts kum | AO2: GIR | AP2: GIR kum | AQ2: Scramble | AR2: Scramble kum | AS2: Unnötige Putts | AT2: Birdie | AU2: Birdie kum | AV2: Pars | AW2: Pars kum | AX2: Bogeys | AY2: Bogeys kum | AZ2: D.Bogey+ | BA2: D.Bogey+ kum | BB2: Chip in | BC2: Chip in kum | BD2: 1 Put | BE2: 1 Put kum | BF2: 2 Put | BG2: 2 Put kum | BH2: 3+ Put | BI2: 3+ Put kum | BJ2: Par3 Perf | BK2: Par4 Perf | BL2: Par5 Perf | BM2: Netto | BN2: Netto kum | BO2: Schläge | BP2: Schläge kum | BQ2: Putts | BR2: Putts kum | BS2: GIR | BT2: GIR kum | BU2: Scramble | BV2: Scramble kum | BW2: Unnötige Putts | BX2: Birdie | BY2: Birdie kum | BZ2: Pars | CA2: Pars kum | CB2: Bogeys | CC2: Bogeys kum | CD2: D.Bogey+ | CE2: D.Bogey+ kum | CF2: Chip in | CG2: Chip in kum | CH2: 1 Put | CI2: 1 Put kum | CJ2: 2 Put | CK2: 2 Put kum | CL2: 3+ Put | CM2: 3+ Put kum | CN2: Par3 Perf | CO2: Par4 Perf | CP2: Par5 Perf | CQ2: Netto | CR2: Netto kum | CS2: Schläge | CT2: Schläge kum | CU2: Putts | CV2: Putts kum | CW2: GIR | CX2: GIR kum | CY2: Scramble | CZ2: Scramble kum | DA2: Unnötige Putts | DB2: Birdie | DC2: Birdie kum | DD2: Pars | DE2: Pars kum | DF2: Bogeys | DG2: Bogeys kum | DH2: D.Bogey+ | DI2: D.Bogey+ kum | DJ2: Chip in | DK2: Chip in kum | DL2: 1 Put | DM2: 1 Put kum | DN2: 2 Put | DO2: 2 Put kum | DP2: 3+ Put | DQ2: 3+ Put kum | DR2: Par3 Perf | DS2: Par4 Perf | DT2: Par5 Perf | DU2: Netto | DV2: Netto kum | DW2: Schläge | DX2: Schläge kum | DY2: Putts | DZ2: Putts kum | EA2: GIR | EB2: GIR kum | EC2: Scramble | ED2: Scramble kum | EE2: Unnötige Putts | EF2: Birdie | EG2: Birdie kum | EH2: Pars | EI2: Pars kum | EJ2: Bogeys | EK2: Bogeys kum | EL2: D.Bogey+ | EM2: D.Bogey+ kum | EN2: Chip in | EO2: Chip in kum | EP2: 1 Put | EQ2: 1 Put kum | ER2: 2 Put | ES2: 2 Put kum | ET2: 3+ Put | EU2: 3+ Put kum | EV2: Par3 Perf | EW2: Par4 Perf | EX2: Par5 Perf | EY2: Netto | EZ2: Netto kum | FA2: Schläge | FB2: Schläge kum | FC2: Putts | FD2: Putts kum | FE2: GIR | FF2: GIR kum | FG2: Scramble | FH2: Scramble kum | FI2: Unnötige Putts | FJ2: Birdie | FK2: Birdie kum | FL2: Pars | FM2: Pars kum | FN2: Bogeys | FO2: Bogeys kum | FP2: D.Bogey+ | FQ2: D.Bogey+ kum | FR2: Chip in | FS2: Chip in kum | FT2: 1 Put | FU2: 1 Put kum | FV2: 2 Put | FW2: 2 Put kum | FX2: 3+ Put | FY2: 3+ Put kum | FZ2: Par3 Perf | GA2: Par4 Perf | GB2: Par5 Perf | GC2: Netto | GD2: Netto kum | GE2: Schläge | GF2: Schläge kum | GG2: Putts | GH2: Putts kum | GI2: GIR | GJ2: GIR kum | GK2: Scramble | GL2: Scramble kum | GM2: Unnötige Putts | GN2: Birdie | GO2: Birdie kum | GP2: Pars | GQ2: Pars kum | GR2: Bogeys | GS2: Bogeys kum | GT2: D.Bogey+ | GU2: D.Bogey+ kum | GV2: Chip in | GW2: Chip in kum | GX2: 1 Put | GY2: 1 Put kum | GZ2: 2 Put | HA2: 2 Put kum | HB2: 3+ Put | HC2: 3+ Put kum | HD2: Par3 Perf | HE2: Par4 Perf | HF2: Par5 Perf | HG2: Netto | HH2: Netto kum | HI2: Schläge | HJ2: Schläge kum | HK2: Putts | HL2: Putts kum | HM2: GIR | HN2: GIR kum | HO2: Scramble | HP2: Scramble kum | HQ2: Unnötige Putts | HR2: Birdie | HS2: Birdie kum | HT2: Pars | HU2: Pars kum | HV2: Bogeys | HW2: Bogeys kum | HX2: D.Bogey+ | HY2: D.Bogey+ kum | HZ2: Chip in | IA2: Chip in kum | IB2: 1 Put | IC2: 1 Put kum | ID2: 2 Put | IE2: 2 Put kum | IF2: 3+ Put | IG2: 3+ Put kum | IH2: Par3 Perf | II2: Par4 Perf | IJ2: Par5 Perf | IK2: Netto | IL2: Netto kum | IM2: Schläge | IN2: Schläge kum | IO2: Putts | IP2: Putts kum | IQ2: GIR | IR2: GIR kum | IS2: Scramble | IT2: Scramble kum | IU2: Unnötige Putts | IV2: Birdie | IW2: Birdie kum | IX2: Pars | IY2: Pars kum | IZ2: Bogeys | JA2: Bogeys kum | JB2: D.Bogey+ | JC2: D.Bogey+ kum | JD2: Chip in | JE2: Chip in kum | JF2: 1 Put | JG2: 1 Put kum | JH2: 2 Put | JI2: 2 Put kum | JJ2: 3+ Put | JK2: 3+ Put kum | JL2: Par3 Perf | JM2: Par4 Perf | JN2: Par5 Perf | JO2: Netto | JP2: Netto kum | JQ2: Schläge | JR2: Schläge kum | JS2: Putts | JT2: Putts kum | JU2: GIR | JV2: GIR kum | JW2: Scramble | JX2: Scramble kum | JY2: Unnötige Putts | JZ2: Birdie | KA2: Birdie kum | KB2: Pars | KC2: Pars kum | KD2: Bogeys | KE2: Bogeys kum | KF2: D.Bogey+ | KG2: D.Bogey+ kum | KH2: Chip in | KI2: Chip in kum | KJ2: 1 Put | KK2: 1 Put kum | KL2: 2 Put | KM2: 2 Put kum | KN2: 3+ Put | KO2: 3+ Put kum | KP2: Par3 Perf | KQ2: Par4 Perf | KR2: Par5 Perf | KS2: Netto | KT2: Netto kum
B3: Front Nine | C3: 1 | D3: =C3 -> 1 | E3: 4 | F3: =E3 -> 4 | G3: 5 | H3: =G3 -> 5 | I3: 2 | J3: =I3 -> 2 | K3: =IF(G3-I3<=$E3-2,1,0) -> 0 | L3: =K3 -> 0 | M3: =IF(K3=0,IF(G3=$E3,1,0),0) -> 0 | N3: =M3 -> 0 | P3: =IF($E3-G3=1,1,0) -> 0 | Q3: =P3 -> 0 | R3: =IF(G3=$E3,1,0) -> 0 | S3: =R3 -> 0 | T3: =IF(G3-$E3=1,1,0) -> 1 | U3: =T3 -> 1 | V3: =IF(G3-$E3>=2,1,0) -> 0 | W3: =V3 -> 0 | X3: =IF(I3=0,1,0) -> 0 | Y3: =X3 -> 0 | Z3: =IF(I3=1,1,0) -> 0 | AA3: =Z3 -> 0 | AB3: =IF(I3=2,1,0) -> 1 | AC3: =AB3 -> 1 | AD3: =IF(I3>=3,1,0) -> 0 | AE3: =AD3 -> 0 | AG3: =IF($E3=4,G3-4,NA()) -> 1 | AI3: =G3-'Zusammenfassung Tag1-4'!$B$2/18 -> 4.1666667 | AJ3: =AI3 -> 4.1666667 | AK3: 4 | AL3: =AK3 -> 4 | AM3: 2 | AN3: =AM3 -> 2 | AO3: =IF(AK3-AM3<=$E3-2,1,0) -> 1 | AP3: =AO3 -> 1 | AQ3: =IF(AO3=0,IF(AK3=$E3,1,0),0) -> 0 | AR3: =AQ3 -> 0 | AT3: =IF($E3-AK3=1,1,0) -> 0 | AU3: =AT3 -> 0 | AV3: =IF(AK3=$E3,1,0) -> 1 | AW3: =AV3 -> 1 | AX3: =IF(AK3-$E3=1,1,0) -> 0 | AY3: =AX3 -> 0 | AZ3: =IF(AK3-$E3>=2,1,0) -> 0 | BA3: =AZ3 -> 0 | BB3: =IF(AM3=0,1,0) -> 0 | BC3: =BB3 -> 0 | BD3: =IF(AM3=1,1,0) -> 0 | BE3: =BD3 -> 0 | BF3: =IF(AM3=2,1,0) -> 1 | BG3: =BF3 -> 1 | BH3: =IF(AM3>=3,1,0) -> 0 | BI3: =BH3 -> 0 | BK3: =IF($E3=4,AK3-4,NA()) -> 0 | BM3: =AK3-'Zusammenfassung Tag1-4'!$C$2/18 -> 3.4444444 | BN3: =BM3 -> 3.4444444 | BO3: 8 | BP3: =BO3 -> 8 | BQ3: 2 | BR3: =BQ3 -> 2 | BS3: =IF(BO3-BQ3<=$E3-2,1,0) -> 0 | BT3: =BS3 -> 0 | BU3: =IF(BS3=0,IF(BO3=$E3,1,0),0) -> 0 | BV3: =BU3 -> 0 | BX3: =IF($E3-BO3=1,1,0) -> 0 | BY3: =BX3 -> 0 | BZ3: =IF(BO3=$E3,1,0) -> 0 | CA3: =BZ3 -> 0 | CB3: =IF(BO3-$E3=1,1,0) -> 0 | CC3: =CB3 -> 0 | CD3: =IF(BO3-$E3>=2,1,0) -> 1 | CE3: =CD3 -> 1 | CF3: =IF(BQ3=0,1,0) -> 0 | CG3: =CF3 -> 0 | CH3: =IF(BQ3=1,1,0) -> 0 | CI3: =CH3 -> 0 | CJ3: =IF(BQ3=2,1,0) -> 1 | CK3: =CJ3 -> 1 | CL3: =IF(BQ3>=3,1,0) -> 0 | CM3: =CL3 -> 0 | CO3: =IF($E3=4,BO3-4,NA()) -> 4 | CQ3: =BO3-'Zusammenfassung Tag1-4'!$D$2/18 -> 6.9444444 | CR3: =CQ3 -> 6.9444444 | CS3: 4 | CT3: =CS3 -> 4 | CU3: 2 | CV3: =CU3 -> 2 | CW3: =IF(CS3-CU3<=$E3-2,1,0) -> 1 | CX3: =CW3 -> 1 | CY3: =IF(CW3=0,IF(CS3=$E3,1,0),0) -> 0 | CZ3: =CY3 -> 0 | DB3: =IF($E3-CS3=1,1,0) -> 0 | DC3: =DB3 -> 0 | DD3: =IF(CS3=$E3,1,0) -> 1 | DE3: =DD3 -> 1 | DF3: =IF(CS3-$E3=1,1,0) -> 0 | DG3: =DF3 -> 0 | DH3: =IF(CS3-$E3>=2,1,0) -> 0 | DI3: =DH3 -> 0 | DJ3: =IF(CU3=0,1,0) -> 0 | DK3: =DJ3 -> 0 | DL3: =IF(CU3=1,1,0) -> 0 | DM3: =DL3 -> 0 | DN3: =IF(CU3=2,1,0) -> 1 | DO3: =DN3 -> 1 | DP3: =IF(CU3>=3,1,0) -> 0 | DQ3: =DP3 -> 0 | DS3: =IF($E3=4,CS3-4,NA()) -> 0 | DU3: =CS3-'Zusammenfassung Tag1-4'!$E$2/18 -> 3 | DV3: =DU3 -> 3 | DW3: 9 | DX3: 89 | DY3: 2 | DZ3: =DY3 -> 2 | EA3: =IF(DW3-DY3<=$E3-2,1,0) -> 0 | EB3: =EA3 -> 0 | EC3: =IF(EA3=0,IF(DW3=$E3,1,0),0) -> 0 | ED3: =EC3 -> 0 | EF3: =IF($E3-DW3=1,1,0) -> 0 | EG3: =EF3 -> 0 | EH3: =IF(DW3=$E3,1,0) -> 0 | EI3: =EH3 -> 0 | EJ3: =IF(DW3-$E3=1,1,0) -> 0 | EK3: =EJ3 -> 0 | EL3: =IF(DW3-$E3>=2,1,0) -> 1 | EM3: =EL3 -> 1 | EN3: =IF(DY3=0,1,0) -> 0 | EO3: =EN3 -> 0 | EP3: =IF(DY3=1,1,0) -> 0 | EQ3: =EP3 -> 0 | ER3: =IF(DY3=2,1,0) -> 1 | ES3: =ER3 -> 1 | ET3: =IF(DY3>=3,1,0) -> 0 | EU3: =ET3 -> 0 | EW3: =IF($E3=4,DW3-4,NA()) -> 5 | EY3: =DW3-'Zusammenfassung Tag1-4'!$F$2/18 -> 6.5 | EZ3: =EY3 -> 6.5 | FA3: 8 | FB3: 4 | FC3: 3 | FD3: =FC3 -> 3 | FE3: =IF(FA3-FC3<=$E3-2,1,0) -> 0 | FF3: =FE3 -> 0 | FG3: =IF(FE3=0,IF(FA3=$E3,1,0),0) -> 0 | FH3: =FG3 -> 0 | FJ3: =IF($E3-FA3=1,1,0) -> 0 | FK3: =FJ3 -> 0 | FL3: =IF(FA3=$E3,1,0) -> 0 | FM3: =FL3 -> 0 | FN3: =IF(FA3-$E3=1,1,0) -> 0 | FO3: =FN3 -> 0 | FP3: =IF(FA3-$E3>=2,1,0) -> 1 | FQ3: =FP3 -> 1 | FR3: =IF(FC3=0,1,0) -> 0 | FS3: =FR3 -> 0 | FT3: =IF(FC3=1,1,0) -> 0 | FU3: =FT3 -> 0 | FV3: =IF(FC3=2,1,0) -> 0 | FW3: =FV3 -> 0 | FX3: =IF(FC3>=3,1,0) -> 1 | FY3: =FX3 -> 1 | GA3: =IF($E3=4,FA3-4,NA()) -> 4 | GC3: =FA3-'Zusammenfassung Tag1-4'!$G$2/18 -> 6.7222222 | GD3: =GC3 -> 6.7222222 | GE3: 5 | GF3: 5 | GG3: 2 | GH3: =GG3 -> 2 | GI3: =IF(GE3-GG3<=$E3-2,1,0) -> 0 | GJ3: =GI3 -> 0 | GK3: =IF(GI3=0,IF(GE3=$E3,1,0),0) -> 0 | GL3: =GK3 -> 0 | GN3: =IF($E3-GE3=1,1,0) -> 0 | GO3: =GN3 -> 0 | GP3: =IF(GE3=$E3,1,0) -> 0 | GQ3: =GP3 -> 0 | GR3: =IF(GE3-$E3=1,1,0) -> 1 | GS3: =GR3 -> 1 | GT3: =IF(GE3-$E3>=2,1,0) -> 0 | GU3: =GT3 -> 0 | GV3: =IF(GG3=0,1,0) -> 0 | GW3: =GV3 -> 0 | GX3: =IF(GG3=1,1,0) -> 0 | GY3: =GX3 -> 0 | GZ3: =IF(GG3=2,1,0) -> 1 | HA3: =GZ3 -> 1 | HB3: =IF(GG3>=3,1,0) -> 0 | HC3: =HB3 -> 0 | HE3: =IF($E3=4,GE3-4,NA()) -> 1 | HG3: =GE3-'Zusammenfassung Tag1-4'!$H$2/18 -> 3.2222222 | HH3: =HG3 -> 3.2222222 | HI3: 7 | HJ3: 5 | HK3: 2 | HL3: =HK3 -> 2 | HM3: =IF(HI3-HK3<=$E3-2,1,0) -> 0 | HN3: =HM3 -> 0 | HO3: =IF(HM3=0,IF(HI3=$E3,1,0),0) -> 0 | HP3: =HO3 -> 0 | HR3: =IF($E3-HI3=1,1,0) -> 0 | HS3: =HR3 -> 0 | HT3: =IF(HI3=$E3,1,0) -> 0 | HU3: =HT3 -> 0 | HV3: =IF(HI3-$E3=1,1,0) -> 0 | HW3: =HV3 -> 0 | HX3: =IF(HI3-$E3>=2,1,0) -> 1 | HY3: =HX3 -> 1 | HZ3: =IF(HK3=0,1,0) -> 0 | IA3: =HZ3 -> 0 | IB3: =IF(HK3=1,1,0) -> 0 | IC3: =IB3 -> 0 | ID3: =IF(HK3=2,1,0) -> 1 | IE3: =ID3 -> 1 | IF3: =IF(HK3>=3,1,0) -> 0 | IG3: =IF3 -> 0 | II3: =IF($E3=4,HI3-4,NA()) -> 3 | IK3: =HI3-'Zusammenfassung Tag1-4'!$I$2/18 -> 6.1111111 | IL3: =IK3 -> 6.1111111 | IM3: 9 | IN3: 140 | IO3: 3 | IP3: =IO3 -> 3 | IQ3: =IF(IM3-IO3<=$E3-2,1,0) -> 0 | IR3: =IQ3 -> 0 | IS3: =IF(IQ3=0,IF(IM3=$E3,1,0),0) -> 0 | IT3: =IS3 -> 0 | IV3: =IF($E3-IM3=1,1,0) -> 0 | IW3: =IV3 -> 0 | IX3: =IF(IM3=$E3,1,0) -> 0 | IY3: =IX3 -> 0 | IZ3: =IF(IM3-$E3=1,1,0) -> 0 | JA3: =IZ3 -> 0 | JB3: =IF(IM3-$E3>=2,1,0) -> 1 | JC3: =JB3 -> 1 | JD3: =IF(IO3=0,1,0) -> 0 | JE3: =JD3 -> 0 | JF3: =IF(IO3=1,1,0) -> 0 | JG3: =JF3 -> 0 | JH3: =IF(IO3=2,1,0) -> 0 | JI3: =JH3 -> 0 | JJ3: =IF(IO3>=3,1,0) -> 1 | JK3: =JJ3 -> 1 | JM3: =IF($E3=4,IM3-4,NA()) -> 5 | JO3: =IM3-'Zusammenfassung Tag1-4'!$J$2/18 -> 6.6666667 | JP3: =JO3 -> 6.6666667 | JT3: =JS3 -> 0 | JU3: =IF(JQ3-JS3<=$E3-2,1,0) -> 1 | JV3: =JU3 -> 1 | JW3: =IF(JU3=0,IF(JQ3=$E3,1,0),0) -> 0 | JX3: =JW3 -> 0 | JZ3: =IF($E3-JQ3=1,1,0) -> 0 | KA3: =JZ3 -> 0 | KB3: =IF(JQ3=$E3,1,0) -> 0 | KC3: =KB3 -> 0 | KD3: =IF(JQ3-$E3=1,1,0) -> 0 | KE3: =KD3 -> 0 | KF3: =IF(JQ3-$E3>=2,1,0) -> 0 | KG3: =KF3 -> 0 | KH3: =IF(JS3=0,1,0) -> 1 | KI3: =KH3 -> 1 | KJ3: =IF(JS3=1,1,0) -> 0 | KK3: =KJ3 -> 0 | KL3: =IF(JS3=2,1,0) -> 0 | KM3: =KL3 -> 0 | KN3: =IF(JS3>=3,1,0) -> 0 | KO3: =KN3 -> 0 | KQ3: =IF($E3=4,JQ3-4,NA()) -> -4 | KS3: =JQ3-'Zusammenfassung Tag1-4'!#REF!/18 -> #REF! | KT3: =KS3 -> #REF!
C4: 2 | D4: =D3+1 -> 2 | E4: 5 | F4: =E4+F3 -> 9 | G4: 6 | H4: =G4+H3 -> 11 | I4: 2 | J4: =I4+J3 -> 4 | K4: =IF(G4-I4<=$E4-2,1,0) -> 0 | L4: =K4+L3 -> 0 | M4: =IF(K4=0,IF(G4=$E4,1,0),0) -> 0 | N4: =M4+N3 -> 0 | P4: =IF($E4-G4=1,1,0) -> 0 | Q4: =P4+Q3 -> 0 | R4: =IF(G4=$E4,1,0) -> 0 | S4: =R4+S3 -> 0 | T4: =IF(G4-$E4=1,1,0) -> 1 | U4: =T4+U3 -> 2 | V4: =IF(G4-$E4>=2,1,0) -> 0 | W4: =V4+W3 -> 0 | X4: =IF(I4=0,1,0) -> 0 | Y4: =X4+Y3 -> 0 | Z4: =IF(I4=1,1,0) -> 0 | AA4: =Z4+AA3 -> 0 | AB4: =IF(I4=2,1,0) -> 1 | AC4: =AB4+AC3 -> 2 | AD4: =IF(I4>=3,1,0) -> 0 | AE4: =AD4+AE3 -> 0 | AH4: =IF($E4=5,G4-5,NA()) -> 1 | AI4: =G4-'Zusammenfassung Tag1-4'!$B$2/18 -> 5.1666667 | AJ4: =AI4+AJ3 -> 9.3333333 | AK4: 5 | AL4: =AK4+AL3 -> 9 | AM4: 1 | AN4: =AM4+AN3 -> 3 | AO4: =IF(AK4-AM4<=$E4-2,1,0) -> 0 | AP4: =AO4+AP3 -> 1 | AQ4: =IF(AO4=0,IF(AK4=$E4,1,0),0) -> 1 | AR4: =AQ4+AR3 -> 1 | AT4: =IF($E4-AK4=1,1,0) -> 0 | AU4: =AT4+AU3 -> 0 | AV4: =IF(AK4=$E4,1,0) -> 1 | AW4: =AV4+AW3 -> 2 | AX4: =IF(AK4-$E4=1,1,0) -> 0 | AY4: =AX4+AY3 -> 0 | AZ4: =IF(AK4-$E4>=2,1,0) -> 0 | BA4: =AZ4+BA3 -> 0 | BB4: =IF(AM4=0,1,0) -> 0 | BC4: =BB4+BC3 -> 0 | BD4: =IF(AM4=1,1,0) -> 1 | BE4: =BD4+BE3 -> 1 | BF4: =IF(AM4=2,1,0) -> 0 | BG4: =BF4+BG3 -> 1 | BH4: =IF(AM4>=3,1,0) -> 0 | BI4: =BH4+BI3 -> 0 | BL4: =IF($E4=5,AK4-5,NA()) -> 0 | BM4: =AK4-'Zusammenfassung Tag1-4'!$C$2/18 -> 4.4444444 | BN4: =BM4+BN3 -> 7.8888889 | BO4: 7 | BP4: =BO4+BP3 -> 15 | BQ4: 2 | BR4: =BQ4+BR3 -> 4 | BS4: =IF(BO4-BQ4<=$E4-2,1,0) -> 0 | BT4: =BS4+BT3 -> 0 | BU4: =IF(BS4=0,IF(BO4=$E4,1,0),0) -> 0 | BV4: =BU4+BV3 -> 0 | BX4: =IF($E4-BO4=1,1,0) -> 0 | BY4: =BX4+BY3 -> 0 | BZ4: =IF(BO4=$E4,1,0) -> 0 | CA4: =BZ4+CA3 -> 0 | CB4: =IF(BO4-$E4=1,1,0) -> 0 | CC4: =CB4+CC3 -> 0 | CD4: =IF(BO4-$E4>=2,1,0) -> 1 | CE4: =CD4+CE3 -> 2 | CF4: =IF(BQ4=0,1,0) -> 0 | CG4: =CF4+CG3 -> 0 | CH4: =IF(BQ4=1,1,0) -> 0 | CI4: =CH4+CI3 -> 0 | CJ4: =IF(BQ4=2,1,0) -> 1 | CK4: =CJ4+CK3 -> 2 | CL4: =IF(BQ4>=3,1,0) -> 0 | CM4: =CL4+CM3 -> 0 | CP4: =IF($E4=5,BO4-5,NA()) -> 2 | CQ4: =BO4-'Zusammenfassung Tag1-4'!$D$2/18 -> 5.9444444 | CR4: =CQ4+CR3 -> 12.888889 | CS4: 7 | CT4: =CS4+CT3 -> 11 | CU4: 2 | CV4: =CU4+CV3 -> 4 | CW4: =IF(CS4-CU4<=$E4-2,1,0) -> 0 | CX4: =CW4+CX3 -> 1 | CY4: =IF(CW4=0,IF(CS4=$E4,1,0),0) -> 0 | CZ4: =CY4+CZ3 -> 0 | DB4: =IF($E4-CS4=1,1,0) -> 0 | DC4: =DB4+DC3 -> 0 | DD4: =IF(CS4=$E4,1,0) -> 0 | DE4: =DD4+DE3 -> 1 | DF4: =IF(CS4-$E4=1,1,0) -> 0 | DG4: =DF4+DG3 -> 0 | DH4: =IF(CS4-$E4>=2,1,0) -> 1 | DI4: =DH4+DI3 -> 1 | DJ4: =IF(CU4=0,1,0) -> 0 | DK4: =DJ4+DK3 -> 0 | DL4: =IF(CU4=1,1,0) -> 0 | DM4: =DL4+DM3 -> 0 | DN4: =IF(CU4=2,1,0) -> 1 | DO4: =DN4+DO3 -> 2 | DP4: =IF(CU4>=3,1,0) -> 0 | DQ4: =DP4+DQ3 -> 0 | DT4: =IF($E4=5,CS4-5,NA()) -> 2 | DU4: =CS4-'Zusammenfassung Tag1-4'!$E$2/18 -> 6 | DV4: =DU4+DV3 -> 9 | DW4: 8 | DX4: 94 | DY4: 3 | DZ4: =DY4+DZ3 -> 5 | EA4: =IF(DW4-DY4<=$E4-2,1,0) -> 0 | EB4: =EA4+EB3 -> 0 | EC4: =IF(EA4=0,IF(DW4=$E4,1,0),0) -> 0 | ED4: =EC4+ED3 -> 0 | EF4: =IF($E4-DW4=1,1,0) -> 0 | EG4: =EF4+EG3 -> 0 | EH4: =IF(DW4=$E4,1,0) -> 0 | EI4: =EH4+EI3 -> 0 | EJ4: =IF(DW4-$E4=1,1,0) -> 0 | EK4: =EJ4+EK3 -> 0 | EL4: =IF(DW4-$E4>=2,1,0) -> 1 | EM4: =EL4+EM3 -> 2 | EN4: =IF(DY4=0,1,0) -> 0 | EO4: =EN4+EO3 -> 0 | EP4: =IF(DY4=1,1,0) -> 0 | EQ4: =EP4+EQ3 -> 0 | ER4: =IF(DY4=2,1,0) -> 0 | ES4: =ER4+ES3 -> 1 | ET4: =IF(DY4>=3,1,0) -> 1 | EU4: =ET4+EU3 -> 1 | EX4: =IF($E4=5,DW4-5,NA()) -> 3 | EY4: =DW4-'Zusammenfassung Tag1-4'!$F$2/18 -> 5.5 | EZ4: =EY4+EZ3 -> 12 | FA4: 7 | FB4: 10 | FC4: 2 | FD4: =FC4+FD3 -> 5 | FE4: =IF(FA4-FC4<=$E4-2,1,0) -> 0 | FF4: =FE4+FF3 -> 0 | FG4: =IF(FE4=0,IF(FA4=$E4,1,0),0) -> 0 | FH4: =FG4+FH3 -> 0 | FJ4: =IF($E4-FA4=1,1,0) -> 0 | FK4: =FJ4+FK3 -> 0 | FL4: =IF(FA4=$E4,1,0) -> 0 | FM4: =FL4+FM3 -> 0 | FN4: =IF(FA4-$E4=1,1,0) -> 0 | FO4: =FN4+FO3 -> 0 | FP4: =IF(FA4-$E4>=2,1,0) -> 1 | FQ4: =FP4+FQ3 -> 2 | FR4: =IF(FC4=0,1,0) -> 0 | FS4: =FR4+FS3 -> 0 | FT4: =IF(FC4=1,1,0) -> 0 | FU4: =FT4+FU3 -> 0 | FV4: =IF(FC4=2,1,0) -> 1 | FW4: =FV4+FW3 -> 1 | FX4: =IF(FC4>=3,1,0) -> 0 | FY4: =FX4+FY3 -> 1 | GB4: =IF($E4=5,FA4-5,NA()) -> 2 | GC4: =FA4-'Zusammenfassung Tag1-4'!$G$2/18 -> 5.7222222 | GD4: =GC4+GD3 -> 12.444444 | GE4: 10 | GF4: 13 | GG4: 2 | GH4: =GG4+GH3 -> 4 | GI4: =IF(GE4-GG4<=$E4-2,1,0) -> 0 | GJ4: =GI4+GJ3 -> 0 | GK4: =IF(GI4=0,IF(GE4=$E4,1,0),0) -> 0 | GL4: =GK4+GL3 -> 0 | GN4: =IF($E4-GE4=1,1,0) -> 0 | GO4: =GN4+GO3 -> 0 | GP4: =IF(GE4=$E4,1,0) -> 0 | GQ4: =GP4+GQ3 -> 0 | GR4: =IF(GE4-$E4=1,1,0) -> 0 | GS4: =GR4+GS3 -> 1 | GT4: =IF(GE4-$E4>=2,1,0) -> 1 | GU4: =GT4+GU3 -> 1 | GV4: =IF(GG4=0,1,0) -> 0 | GW4: =GV4+GW3 -> 0 | GX4: =IF(GG4=1,1,0) -> 0 | GY4: =GX4+GY3 -> 0 | GZ4: =IF(GG4=2,1,0) -> 1 | HA4: =GZ4+HA3 -> 2 | HB4: =IF(GG4>=3,1,0) -> 0 | HC4: =HB4+HC3 -> 0 | HF4: =IF($E4=5,GE4-5,NA()) -> 5 | HG4: =GE4-'Zusammenfassung Tag1-4'!$H$2/18 -> 8.2222222 | HH4: =HG4+HH3 -> 11.444444 | HI4: 7 | HJ4: 10 | HK4: 2 | HL4: =HK4+HL3 -> 4 | HM4: =IF(HI4-HK4<=$E4-2,1,0) -> 0 | HN4: =HM4+HN3 -> 0 | HO4: =IF(HM4=0,IF(HI4=$E4,1,0),0) -> 0 | HP4: =HO4+HP3 -> 0 | HR4: =IF($E4-HI4=1,1,0) -> 0 | HS4: =HR4+HS3 -> 0 | HT4: =IF(HI4=$E4,1,0) -> 0 | HU4: =HT4+HU3 -> 0 | HV4: =IF(HI4-$E4=1,1,0) -> 0 | HW4: =HV4+HW3 -> 0 | HX4: =IF(HI4-$E4>=2,1,0) -> 1 | HY4: =HX4+HY3 -> 2 | HZ4: =IF(HK4=0,1,0) -> 0 | IA4: =HZ4+IA3 -> 0 | IB4: =IF(HK4=1,1,0) -> 0 | IC4: =IB4+IC3 -> 0 | ID4: =IF(HK4=2,1,0) -> 1 | IE4: =ID4+IE3 -> 2 | IF4: =IF(HK4>=3,1,0) -> 0 | IG4: =IF4+IG3 -> 0 | IJ4: =IF($E4=5,HI4-5,NA()) -> 2 | IK4: =HI4-'Zusammenfassung Tag1-4'!$I$2/18 -> 6.1111111 | IL4: =IK4+IL3 -> 12.222222 | IM4: 5 | IN4: 148 | IO4: 2 | IP4: =IO4+IP3 -> 5 | IQ4: =IF(IM4-IO4<=$E4-2,1,0) -> 1 | IR4: =IQ4+IR3 -> 1 | IS4: =IF(IQ4=0,IF(IM4=$E4,1,0),0) -> 0 | IT4: =IS4+IT3 -> 0 | IV4: =IF($E4-IM4=1,1,0) -> 0 | IW4: =IV4+IW3 -> 0 | IX4: =IF(IM4=$E4,1,0) -> 1 | IY4: =IX4+IY3 -> 1 | IZ4: =IF(IM4-$E4=1,1,0) -> 0 | JA4: =IZ4+JA3 -> 0 | JB4: =IF(IM4-$E4>=2,1,0) -> 0 | JC4: =JB4+JC3 -> 1 | JD4: =IF(IO4=0,1,0) -> 0 | JE4: =JD4+JE3 -> 0 | JF4: =IF(IO4=1,1,0) -> 0 | JG4: =JF4+JG3 -> 0 | JH4: =IF(IO4=2,1,0) -> 1 | JI4: =JH4+JI3 -> 1 | JJ4: =IF(IO4>=3,1,0) -> 0 | JK4: =JJ4+JK3 -> 1 | JN4: =IF($E4=5,IM4-5,NA()) -> 0 | JO4: =IM4-'Zusammenfassung Tag1-4'!$J$2/18 -> 2.6666667 | JP4: =JO4+JP3 -> 9.3333333 | JT4: =JS4+JT3 -> 0 | JU4: =IF(JQ4-JS4<=$E4-2,1,0) -> 1 | JV4: =JU4+JV3 -> 2 | JW4: =IF(JU4=0,IF(JQ4=$E4,1,0),0) -> 0 | JX4: =JW4+JX3 -> 0 | JZ4: =IF($E4-JQ4=1,1,0) -> 0 | KA4: =JZ4+KA3 -> 0 | KB4: =IF(JQ4=$E4,1,0) -> 0 | KC4: =KB4+KC3 -> 0 | KD4: =IF(JQ4-$E4=1,1,0) -> 0 | KE4: =KD4+KE3 -> 0 | KF4: =IF(JQ4-$E4>=2,1,0) -> 0 | KG4: =KF4+KG3 -> 0 | KH4: =IF(JS4=0,1,0) -> 1 | KI4: =KH4+KI3 -> 2 | KJ4: =IF(JS4=1,1,0) -> 0 | KK4: =KJ4+KK3 -> 0 | KL4: =IF(JS4=2,1,0) -> 0 | KM4: =KL4+KM3 -> 0 | KN4: =IF(JS4>=3,1,0) -> 0 | KO4: =KN4+KO3 -> 0 | KR4: =IF($E4=5,JQ4-5,NA()) -> -5 | KS4: =JQ4-'Zusammenfassung Tag1-4'!#REF!/18 -> #REF! | KT4: =KS4+KT3 -> #REF!
C5: 3 | D5: =D4+1 -> 3 | E5: 4 | F5: =E5+F4 -> 13 | G5: 5 | H5: =G5+H4 -> 16 | I5: 2 | J5: =I5+J4 -> 6 | K5: =IF(G5-I5<=$E5-2,1,0) -> 0 | L5: =K5+L4 -> 0 | M5: =IF(K5=0,IF(G5=$E5,1,0),0) -> 0 | N5: =M5+N4 -> 0 | P5: =IF($E5-G5=1,1,0) -> 0 | Q5: =P5+Q4 -> 0 | R5: =IF(G5=$E5,1,0) -> 0 | S5: =R5+S4 -> 0 | T5: =IF(G5-$E5=1,1,0) -> 1 | U5: =T5+U4 -> 3 | V5: =IF(G5-$E5>=2,1,0) -> 0 | W5: =V5+W4 -> 0 | X5: =IF(I5=0,1,0) -> 0 | Y5: =X5+Y4 -> 0 | Z5: =IF(I5=1,1,0) -> 0 | AA5: =Z5+AA4 -> 0 | AB5: =IF(I5=2,1,0) -> 1 | AC5: =AB5+AC4 -> 3 | AD5: =IF(I5>=3,1,0) -> 0 | AE5: =AD5+AE4 -> 0 | AG5: =IF($E5=4,G5-4,NA()) -> 1 | AI5: =G5-'Zusammenfassung Tag1-4'!$B$2/18 -> 4.1666667 | AJ5: =AI5+AJ4 -> 13.5 | AK5: 4 | AL5: =AK5+AL4 -> 13 | AM5: 2 | AN5: =AM5+AN4 -> 5 | AO5: =IF(AK5-AM5<=$E5-2,1,0) -> 1 | AP5: =AO5+AP4 -> 2 | AQ5: =IF(AO5=0,IF(AK5=$E5,1,0),0) -> 0 | AR5: =AQ5+AR4 -> 1 | AT5: =IF($E5-AK5=1,1,0) -> 0 | AU5: =AT5+AU4 -> 0 | AV5: =IF(AK5=$E5,1,0) -> 1 | AW5: =AV5+AW4 -> 3 | AX5: =IF(AK5-$E5=1,1,0) -> 0 | AY5: =AX5+AY4 -> 0 | AZ5: =IF(AK5-$E5>=2,1,0) -> 0 | BA5: =AZ5+BA4 -> 0 | BB5: =IF(AM5=0,1,0) -> 0 | BC5: =BB5+BC4 -> 0 | BD5: =IF(AM5=1,1,0) -> 0 | BE5: =BD5+BE4 -> 1 | BF5: =IF(AM5=2,1,0) -> 1 | BG5: =BF5+BG4 -> 2 | BH5: =IF(AM5>=3,1,0) -> 0 | BI5: =BH5+BI4 -> 0 | BK5: =IF($E5=4,AK5-4,NA()) -> 0 | BM5: =AK5-'Zusammenfassung Tag1-4'!$C$2/18 -> 3.4444444 | BN5: =BM5+BN4 -> 11.333333 | BO5: 7 | BP5: =BO5+BP4 -> 22 | BQ5: 3 | BR5: =BQ5+BR4 -> 7 | BS5: =IF(BO5-BQ5<=$E5-2,1,0) -> 0 | BT5: =BS5+BT4 -> 0 | BU5: =IF(BS5=0,IF(BO5=$E5,1,0),0) -> 0 | BV5: =BU5+BV4 -> 0 | BX5: =IF($E5-BO5=1,1,0) -> 0 | BY5: =BX5+BY4 -> 0 | BZ5: =IF(BO5=$E5,1,0) -> 0 | CA5: =BZ5+CA4 -> 0 | CB5: =IF(BO5-$E5=1,1,0) -> 0 | CC5: =CB5+CC4 -> 0 | CD5: =IF(BO5-$E5>=2,1,0) -> 1 | CE5: =CD5+CE4 -> 3 | CF5: =IF(BQ5=0,1,0) -> 0 | CG5: =CF5+CG4 -> 0 | CH5: =IF(BQ5=1,1,0) -> 0 | CI5: =CH5+CI4 -> 0 | CJ5: =IF(BQ5=2,1,0) -> 0 | CK5: =CJ5+CK4 -> 2 | CL5: =IF(BQ5>=3,1,0) -> 1 | CM5: =CL5+CM4 -> 1 | CO5: =IF($E5=4,BO5-4,NA()) -> 3 | CQ5: =BO5-'Zusammenfassung Tag1-4'!$D$2/18 -> 5.9444444 | CR5: =CQ5+CR4 -> 18.833333 | CS5: 6 | CT5: =CS5+CT4 -> 17 | CU5: 3 | CV5: =CU5+CV4 -> 7 | CW5: =IF(CS5-CU5<=$E5-2,1,0) -> 0 | CX5: =CW5+CX4 -> 1 | CY5: =IF(CW5=0,IF(CS5=$E5,1,0),0) -> 0 | CZ5: =CY5+CZ4 -> 0 | DB5: =IF($E5-CS5=1,1,0) -> 0 | DC5: =DB5+DC4 -> 0 | DD5: =IF(CS5=$E5,1,0) -> 0 | DE5: =DD5+DE4 -> 1 | DF5: =IF(CS5-$E5=1,1,0) -> 0 | DG5: =DF5+DG4 -> 0 | DH5: =IF(CS5-$E5>=2,1,0) -> 1 | DI5: =DH5+DI4 -> 2 | DJ5: =IF(CU5=0,1,0) -> 0 | DK5: =DJ5+DK4 -> 0 | DL5: =IF(CU5=1,1,0) -> 0 | DM5: =DL5+DM4 -> 0 | DN5: =IF(CU5=2,1,0) -> 0 | DO5: =DN5+DO4 -> 2 | DP5: =IF(CU5>=3,1,0) -> 1 | DQ5: =DP5+DQ4 -> 1 | DS5: =IF($E5=4,CS5-4,NA()) -> 2 | DU5: =CS5-'Zusammenfassung Tag1-4'!$E$2/18 -> 5 | DV5: =DU5+DV4 -> 14 | DW5: 6 | DX5: 98 | DY5: 3 | DZ5: =DY5+DZ4 -> 8 | EA5: =IF(DW5-DY5<=$E5-2,1,0) -> 0 | EB5: =EA5+EB4 -> 0 | EC5: =IF(EA5=0,IF(DW5=$E5,1,0),0) -> 0 | ED5: =EC5+ED4 -> 0 | EF5: =IF($E5-DW5=1,1,0) -> 0 | EG5: =EF5+EG4 -> 0 | EH5: =IF(DW5=$E5,1,0) -> 0 | EI5: =EH5+EI4 -> 0 | EJ5: =IF(DW5-$E5=1,1,0) -> 0 | EK5: =EJ5+EK4 -> 0 | EL5: =IF(DW5-$E5>=2,1,0) -> 1 | EM5: =EL5+EM4 -> 3 | EN5: =IF(DY5=0,1,0) -> 0 | EO5: =EN5+EO4 -> 0 | EP5: =IF(DY5=1,1,0) -> 0 | EQ5: =EP5+EQ4 -> 0 | ER5: =IF(DY5=2,1,0) -> 0 | ES5: =ER5+ES4 -> 1 | ET5: =IF(DY5>=3,1,0) -> 1 | EU5: =ET5+EU4 -> 2 | EW5: =IF($E5=4,DW5-4,NA()) -> 2 | EY5: =DW5-'Zusammenfassung Tag1-4'!$F$2/18 -> 3.5 | EZ5: =EY5+EZ4 -> 15.5 | FA5: 6 | FB5: 17 | FC5: 2 | FD5: =FC5+FD4 -> 7 | FE5: =IF(FA5-FC5<=$E5-2,1,0) -> 0 | FF5: =FE5+FF4 -> 0 | FG5: =IF(FE5=0,IF(FA5=$E5,1,0),0) -> 0 | FH5: =FG5+FH4 -> 0 | FJ5: =IF($E5-FA5=1,1,0) -> 0 | FK5: =FJ5+FK4 -> 0 | FL5: =IF(FA5=$E5,1,0) -> 0 | FM5: =FL5+FM4 -> 0 | FN5: =IF(FA5-$E5=1,1,0) -> 0 | FO5: =FN5+FO4 -> 0 | FP5: =IF(FA5-$E5>=2,1,0) -> 1 | FQ5: =FP5+FQ4 -> 3 | FR5: =IF(FC5=0,1,0) -> 0 | FS5: =FR5+FS4 -> 0 | FT5: =IF(FC5=1,1,0) -> 0 | FU5: =FT5+FU4 -> 0 | FV5: =IF(FC5=2,1,0) -> 1 | FW5: =FV5+FW4 -> 2 | FX5: =IF(FC5>=3,1,0) -> 0 | FY5: =FX5+FY4 -> 1 | GA5: =IF($E5=4,FA5-4,NA()) -> 2 | GC5: =FA5-'Zusammenfassung Tag1-4'!$G$2/18 -> 4.7222222 | GD5: =GC5+GD4 -> 17.166667 | GE5: 9 | GF5: 23 | GG5: 3 | GH5: =GG5+GH4 -> 7 | GI5: =IF(GE5-GG5<=$E5-2,1,0) -> 0 | GJ5: =GI5+GJ4 -> 0 | GK5: =IF(GI5=0,IF(GE5=$E5,1,0),0) -> 0 | GL5: =GK5+GL4 -> 0 | GN5: =IF($E5-GE5=1,1,0) -> 0 | GO5: =GN5+GO4 -> 0 | GP5: =IF(GE5=$E5,1,0) -> 0 | GQ5: =GP5+GQ4 -> 0 | GR5: =IF(GE5-$E5=1,1,0) -> 0 | GS5: =GR5+GS4 -> 1 | GT5: =IF(GE5-$E5>=2,1,0) -> 1 | GU5: =GT5+GU4 -> 2 | GV5: =IF(GG5=0,1,0) -> 0 | GW5: =GV5+GW4 -> 0 | GX5: =IF(GG5=1,1,0) -> 0 | GY5: =GX5+GY4 -> 0 | GZ5: =IF(GG5=2,1,0) -> 0 | HA5: =GZ5+HA4 -> 2 | HB5: =IF(GG5>=3,1,0) -> 1 | HC5: =HB5+HC4 -> 1 | HE5: =IF($E5=4,GE5-4,NA()) -> 5 | HG5: =GE5-'Zusammenfassung Tag1-4'!$H$2/18 -> 7.2222222 | HH5: =HG5+HH4 -> 18.666667 | HI5: 6 | HJ5: 14 | HK5: 2 | HL5: =HK5+HL4 -> 6 | HM5: =IF(HI5-HK5<=$E5-2,1,0) -> 0 | HN5: =HM5+HN4 -> 0 | HO5: =IF(HM5=0,IF(HI5=$E5,1,0),0) -> 0 | HP5: =HO5+HP4 -> 0 | HR5: =IF($E5-HI5=1,1,0) -> 0 | HS5: =HR5+HS4 -> 0 | HT5: =IF(HI5=$E5,1,0) -> 0 | HU5: =HT5+HU4 -> 0 | HV5: =IF(HI5-$E5=1,1,0) -> 0 | HW5: =HV5+HW4 -> 0 | HX5: =IF(HI5-$E5>=2,1,0) -> 1 | HY5: =HX5+HY4 -> 3 | HZ5: =IF(HK5=0,1,0) -> 0 | IA5: =HZ5+IA4 -> 0 | IB5: =IF(HK5=1,1,0) -> 0 | IC5: =IB5+IC4 -> 0 | ID5: =IF(HK5=2,1,0) -> 1 | IE5: =ID5+IE4 -> 3 | IF5: =IF(HK5>=3,1,0) -> 0 | IG5: =IF5+IG4 -> 0 | II5: =IF($E5=4,HI5-4,NA()) -> 2 | IK5: =HI5-'Zusammenfassung Tag1-4'!$I$2/18 -> 5.1111111 | IL5: =IK5+IL4 -> 17.333333 | IM5: 7 | IN5: 155 | IO5: 5 | IP5: =IO5+IP4 -> 10 | IQ5: =IF(IM5-IO5<=$E5-2,1,0) -> 1 | IR5: =IQ5+IR4 -> 2 | IS5: =IF(IQ5=0,IF(IM5=$E5,1,0),0) -> 0 | IT5: =IS5+IT4 -> 0 | IV5: =IF($E5-IM5=1,1,0) -> 0 | IW5: =IV5+IW4 -> 0 | IX5: =IF(IM5=$E5,1,0) -> 0 | IY5: =IX5+IY4 -> 1 | IZ5: =IF(IM5-$E5=1,1,0) -> 0 | JA5: =IZ5+JA4 -> 0 | JB5: =IF(IM5-$E5>=2,1,0) -> 1 | JC5: =JB5+JC4 -> 2 | JD5: =IF(IO5=0,1,0) -> 0 | JE5: =JD5+JE4 -> 0 | JF5: =IF(IO5=1,1,0) -> 0 | JG5: =JF5+JG4 -> 0 | JH5: =IF(IO5=2,1,0) -> 0 | JI5: =JH5+JI4 -> 1 | JJ5: =IF(IO5>=3,1,0) -> 1 | JK5: =JJ5+JK4 -> 2 | JM5: =IF($E5=4,IM5-4,NA()) -> 3 | JO5: =IM5-'Zusammenfassung Tag1-4'!$J$2/18 -> 4.6666667 | JP5: =JO5+JP4 -> 14 | JT5: =JS5+JT4 -> 0 | JU5: =IF(JQ5-JS5<=$E5-2,1,0) -> 1 | JV5: =JU5+JV4 -> 3 | JW5: =IF(JU5=0,IF(JQ5=$E5,1,0),0) -> 0 | JX5: =JW5+JX4 -> 0 | JZ5: =IF($E5-JQ5=1,1,0) -> 0 | KA5: =JZ5+KA4 -> 0 | KB5: =IF(JQ5=$E5,1,0) -> 0 | KC5: =KB5+KC4 -> 0 | KD5: =IF(JQ5-$E5=1,1,0) -> 0 | KE5: =KD5+KE4 -> 0 | KF5: =IF(JQ5-$E5>=2,1,0) -> 0 | KG5: =KF5+KG4 -> 0 | KH5: =IF(JS5=0,1,0) -> 1 | KI5: =KH5+KI4 -> 3 | KJ5: =IF(JS5=1,1,0) -> 0 | KK5: =KJ5+KK4 -> 0 | KL5: =IF(JS5=2,1,0) -> 0 | KM5: =KL5+KM4 -> 0 | KN5: =IF(JS5>=3,1,0) -> 0 | KO5: =KN5+KO4 -> 0 | KQ5: =IF($E5=4,JQ5-4,NA()) -> -4 | KS5: =JQ5-'Zusammenfassung Tag1-4'!#REF!/18 -> #REF! | KT5: =KS5+KT4 -> #REF!
C6: 4 | D6: =D5+1 -> 4 | E6: 3 | F6: =E6+F5 -> 16 | G6: 4 | H6: =G6+H5 -> 20 | I6: 2 | J6: =I6+J5 -> 8 | K6: =IF(G6-I6<=$E6-2,1,0) -> 0 | L6: =K6+L5 -> 0 | M6: =IF(K6=0,IF(G6=$E6,1,0),0) -> 0 | N6: =M6+N5 -> 0 | P6: =IF($E6-G6=1,1,0) -> 0 | Q6: =P6+Q5 -> 0 | R6: =IF(G6=$E6,1,0) -> 0 | S6: =R6+S5 -> 0 | T6: =IF(G6-$E6=1,1,0) -> 1 | U6: =T6+U5 -> 4 | V6: =IF(G6-$E6>=2,1,0) -> 0 | W6: =V6+W5 -> 0 | X6: =IF(I6=0,1,0) -> 0 | Y6: =X6+Y5 -> 0 | Z6: =IF(I6=1,1,0) -> 0 | AA6: =Z6+AA5 -> 0 | AB6: =IF(I6=2,1,0) -> 1 | AC6: =AB6+AC5 -> 4 | AD6: =IF(I6>=3,1,0) -> 0 | AE6: =AD6+AE5 -> 0 | AF6: =IF($E6=3,G6-3,NA()) -> 1 | AI6: =G6-'Zusammenfassung Tag1-4'!$B$2/18 -> 3.1666667 | AJ6: =AI6+AJ5 -> 16.666667 | AK6: 4 | AL6: =AK6+AL5 -> 17 | AM6: 3 | AN6: =AM6+AN5 -> 8 | AO6: =IF(AK6-AM6<=$E6-2,1,0) -> 1 | AP6: =AO6+AP5 -> 3 | AQ6: =IF(AO6=0,IF(AK6=$E6,1,0),0) -> 0 | AR6: =AQ6+AR5 -> 1 | AT6: =IF($E6-AK6=1,1,0) -> 0 | AU6: =AT6+AU5 -> 0 | AV6: =IF(AK6=$E6,1,0) -> 0 | AW6: =AV6+AW5 -> 3 | AX6: =IF(AK6-$E6=1,1,0) -> 1 | AY6: =AX6+AY5 -> 1 | AZ6: =IF(AK6-$E6>=2,1,0) -> 0 | BA6: =AZ6+BA5 -> 0 | BB6: =IF(AM6=0,1,0) -> 0 | BC6: =BB6+BC5 -> 0 | BD6: =IF(AM6=1,1,0) -> 0 | BE6: =BD6+BE5 -> 1 | BF6: =IF(AM6=2,1,0) -> 0 | BG6: =BF6+BG5 -> 2 | BH6: =IF(AM6>=3,1,0) -> 1 | BI6: =BH6+BI5 -> 1 | BJ6: =IF($E6=3,AK6-3,NA()) -> 1 | BM6: =AK6-'Zusammenfassung Tag1-4'!$C$2/18 -> 3.4444444 | BN6: =BM6+BN5 -> 14.777778 | BO6: 4 | BP6: =BO6+BP5 -> 26 | BQ6: 3 | BR6: =BQ6+BR5 -> 10 | BS6: =IF(BO6-BQ6<=$E6-2,1,0) -> 1 | BT6: =BS6+BT5 -> 1 | BU6: =IF(BS6=0,IF(BO6=$E6,1,0),0) -> 0 | BV6: =BU6+BV5 -> 0 | BX6: =IF($E6-BO6=1,1,0) -> 0 | BY6: =BX6+BY5 -> 0 | BZ6: =IF(BO6=$E6,1,0) -> 0 | CA6: =BZ6+CA5 -> 0 | CB6: =IF(BO6-$E6=1,1,0) -> 1 | CC6: =CB6+CC5 -> 1 | CD6: =IF(BO6-$E6>=2,1,0) -> 0 | CE6: =CD6+CE5 -> 3 | CF6: =IF(BQ6=0,1,0) -> 0 | CG6: =CF6+CG5 -> 0 | CH6: =IF(BQ6=1,1,0) -> 0 | CI6: =CH6+CI5 -> 0 | CJ6: =IF(BQ6=2,1,0) -> 0 | CK6: =CJ6+CK5 -> 2 | CL6: =IF(BQ6>=3,1,0) -> 1 | CM6: =CL6+CM5 -> 2 | CN6: =IF($E6=3,BO6-3,NA()) -> 1 | CQ6: =BO6-'Zusammenfassung Tag1-4'!$D$2/18 -> 2.9444444 | CR6: =CQ6+CR5 -> 21.777778 | CS6: 4 | CT6: =CS6+CT5 -> 21 | CU6: 3 | CV6: =CU6+CV5 -> 10 | CW6: =IF(CS6-CU6<=$E6-2,1,0) -> 1 | CX6: =CW6+CX5 -> 2 | CY6: =IF(CW6=0,IF(CS6=$E6,1,0),0) -> 0 | CZ6: =CY6+CZ5 -> 0 | DB6: =IF($E6-CS6=1,1,0) -> 0 | DC6: =DB6+DC5 -> 0 | DD6: =IF(CS6=$E6,1,0) -> 0 | DE6: =DD6+DE5 -> 1 | DF6: =IF(CS6-$E6=1,1,0) -> 1 | DG6: =DF6+DG5 -> 1 | DH6: =IF(CS6-$E6>=2,1,0) -> 0 | DI6: =DH6+DI5 -> 2 | DJ6: =IF(CU6=0,1,0) -> 0 | DK6: =DJ6+DK5 -> 0 | DL6: =IF(CU6=1,1,0) -> 0 | DM6: =DL6+DM5 -> 0 | DN6: =IF(CU6=2,1,0) -> 0 | DO6: =DN6+DO5 -> 2 | DP6: =IF(CU6>=3,1,0) -> 1 | DQ6: =DP6+DQ5 -> 2 | DR6: =IF($E6=3,CS6-3,NA()) -> 1 | DU6: =CS6-'Zusammenfassung Tag1-4'!$E$2/18 -> 3 | DV6: =DU6+DV5 -> 17 | DW6: 6 | DX6: 103 | DY6: 2 | DZ6: =DY6+DZ5 -> 10 | EA6: =IF(DW6-DY6<=$E6-2,1,0) -> 0 | EB6: =EA6+EB5 -> 0 | EC6: =IF(EA6=0,IF(DW6=$E6,1,0),0) -> 0 | ED6: =EC6+ED5 -> 0 | EF6: =IF($E6-DW6=1,1,0) -> 0 | EG6: =EF6+EG5 -> 0 | EH6: =IF(DW6=$E6,1,0) -> 0 | EI6: =EH6+EI5 -> 0 | EJ6: =IF(DW6-$E6=1,1,0) -> 0 | EK6: =EJ6+EK5 -> 0 | EL6: =IF(DW6-$E6>=2,1,0) -> 1 | EM6: =EL6+EM5 -> 4 | EN6: =IF(DY6=0,1,0) -> 0 | EO6: =EN6+EO5 -> 0 | EP6: =IF(DY6=1,1,0) -> 0 | EQ6: =EP6+EQ5 -> 0 | ER6: =IF(DY6=2,1,0) -> 1 | ES6: =ER6+ES5 -> 2 | ET6: =IF(DY6>=3,1,0) -> 0 | EU6: =ET6+EU5 -> 2 | EV6: =IF($E6=3,DW6-3,NA()) -> 3 | EY6: =DW6-'Zusammenfassung Tag1-4'!$F$2/18 -> 3.5 | EZ6: =EY6+EZ5 -> 19 | FA6: 4 | FB6: 22 | FC6: 2 | FD6: =FC6+FD5 -> 9 | FE6: =IF(FA6-FC6<=$E6-2,1,0) -> 0 | FF6: =FE6+FF5 -> 0 | FG6: =IF(FE6=0,IF(FA6=$E6,1,0),0) -> 0 | FH6: =FG6+FH5 -> 0 | FJ6: =IF($E6-FA6=1,1,0) -> 0 | FK6: =FJ6+FK5 -> 0 | FL6: =IF(FA6=$E6,1,0) -> 0 | FM6: =FL6+FM5 -> 0 | FN6: =IF(FA6-$E6=1,1,0) -> 1 | FO6: =FN6+FO5 -> 1 | FP6: =IF(FA6-$E6>=2,1,0) -> 0 | FQ6: =FP6+FQ5 -> 3 | FR6: =IF(FC6=0,1,0) -> 0 | FS6: =FR6+FS5 -> 0 | FT6: =IF(FC6=1,1,0) -> 0 | FU6: =FT6+FU5 -> 0 | FV6: =IF(FC6=2,1,0) -> 1 | FW6: =FV6+FW5 -> 3 | FX6: =IF(FC6>=3,1,0) -> 0 | FY6: =FX6+FY5 -> 1 | FZ6: =IF($E6=3,FA6-3,NA()) -> 1 | GC6: =FA6-'Zusammenfassung Tag1-4'!$G$2/18 -> 2.7222222 | GD6: =GC6+GD5 -> 19.888889 | GE6: 6 | GF6: 30 | GG6: 2 | GH6: =GG6+GH5 -> 9 | GI6: =IF(GE6-GG6<=$E6-2,1,0) -> 0 | GJ6: =GI6+GJ5 -> 0 | GK6: =IF(GI6=0,IF(GE6=$E6,1,0),0) -> 0 | GL6: =GK6+GL5 -> 0 | GN6: =IF($E6-GE6=1,1,0) -> 0 | GO6: =GN6+GO5 -> 0 | GP6: =IF(GE6=$E6,1,0) -> 0 | GQ6: =GP6+GQ5 -> 0 | GR6: =IF(GE6-$E6=1,1,0) -> 0 | GS6: =GR6+GS5 -> 1 | GT6: =IF(GE6-$E6>=2,1,0) -> 1 | GU6: =GT6+GU5 -> 3 | GV6: =IF(GG6=0,1,0) -> 0 | GW6: =GV6+GW5 -> 0 | GX6: =IF(GG6=1,1,0) -> 0 | GY6: =GX6+GY5 -> 0 | GZ6: =IF(GG6=2,1,0) -> 1 | HA6: =GZ6+HA5 -> 3 | HB6: =IF(GG6>=3,1,0) -> 0 | HC6: =HB6+HC5 -> 1 | HD6: =IF($E6=3,GE6-3,NA()) -> 3 | HG6: =GE6-'Zusammenfassung Tag1-4'!$H$2/18 -> 4.2222222 | HH6: =HG6+HH5 -> 22.888889 | HI6: 6 | HJ6: 18 | HK6: 2 | HL6: =HK6+HL5 -> 8 | HM6: =IF(HI6-HK6<=$E6-2,1,0) -> 0 | HN6: =HM6+HN5 -> 0 | HO6: =IF(HM6=0,IF(HI6=$E6,1,0),0) -> 0 | HP6: =HO6+HP5 -> 0 | HR6: =IF($E6-HI6=1,1,0) -> 0 | HS6: =HR6+HS5 -> 0 | HT6: =IF(HI6=$E6,1,0) -> 0 | HU6: =HT6+HU5 -> 0 | HV6: =IF(HI6-$E6=1,1,0) -> 0 | HW6: =HV6+HW5 -> 0 | HX6: =IF(HI6-$E6>=2,1,0) -> 1 | HY6: =HX6+HY5 -> 4 | HZ6: =IF(HK6=0,1,0) -> 0 | IA6: =HZ6+IA5 -> 0 | IB6: =IF(HK6=1,1,0) -> 0 | IC6: =IB6+IC5 -> 0 | ID6: =IF(HK6=2,1,0) -> 1 | IE6: =ID6+IE5 -> 4 | IF6: =IF(HK6>=3,1,0) -> 0 | IG6: =IF6+IG5 -> 0 | IH6: =IF($E6=3,HI6-3,NA()) -> 3 | IK6: =HI6-'Zusammenfassung Tag1-4'!$I$2/18 -> 5.1111111 | IL6: =IK6+IL5 -> 22.444444 | IM6: 5 | IN6: 165 | IO6: 2 | IP6: =IO6+IP5 -> 12 | IQ6: =IF(IM6-IO6<=$E6-2,1,0) -> 0 | IR6: =IQ6+IR5 -> 2 | IS6: =IF(IQ6=0,IF(IM6=$E6,1,0),0) -> 0 | IT6: =IS6+IT5 -> 0 | IV6: =IF($E6-IM6=1,1,0) -> 0 | IW6: =IV6+IW5 -> 0 | IX6: =IF(IM6=$E6,1,0) -> 0 | IY6: =IX6+IY5 -> 1 | IZ6: =IF(IM6-$E6=1,1,0) -> 0 | JA6: =IZ6+JA5 -> 0 | JB6: =IF(IM6-$E6>=2,1,0) -> 1 | JC6: =JB6+JC5 -> 3 | JD6: =IF(IO6=0,1,0) -> 0 | JE6: =JD6+JE5 -> 0 | JF6: =IF(IO6=1,1,0) -> 0 | JG6: =JF6+JG5 -> 0 | JH6: =IF(IO6=2,1,0) -> 1 | JI6: =JH6+JI5 -> 2 | JJ6: =IF(IO6>=3,1,0) -> 0 | JK6: =JJ6+JK5 -> 2 | JL6: =IF($E6=3,IM6-3,NA()) -> 2 | JO6: =IM6-'Zusammenfassung Tag1-4'!$J$2/18 -> 2.6666667 | JP6: =JO6+JP5 -> 16.666667 | JT6: =JS6+JT5 -> 0 | JU6: =IF(JQ6-JS6<=$E6-2,1,0) -> 1 | JV6: =JU6+JV5 -> 4 | JW6: =IF(JU6=0,IF(JQ6=$E6,1,0),0) -> 0 | JX6: =JW6+JX5 -> 0 | JZ6: =IF($E6-JQ6=1,1,0) -> 0 | KA6: =JZ6+KA5 -> 0 | KB6: =IF(JQ6=$E6,1,0) -> 0 | KC6: =KB6+KC5 -> 0 | KD6: =IF(JQ6-$E6=1,1,0) -> 0 | KE6: =KD6+KE5 -> 0 | KF6: =IF(JQ6-$E6>=2,1,0) -> 0 | KG6: =KF6+KG5 -> 0 | KH6: =IF(JS6=0,1,0) -> 1 | KI6: =KH6+KI5 -> 4 | KJ6: =IF(JS6=1,1,0) -> 0 | KK6: =KJ6+KK5 -> 0 | KL6: =IF(JS6=2,1,0) -> 0 | KM6: =KL6+KM5 -> 0 | KN6: =IF(JS6>=3,1,0) -> 0 | KO6: =KN6+KO5 -> 0 | KP6: =IF($E6=3,JQ6-3,NA()) -> -3 | KS6: =JQ6-'Zusammenfassung Tag1-4'!#REF!/18 -> #REF! | KT6: =KS6+KT5 -> #REF!
C7: 5 | D7: =D6+1 -> 5 | E7: 4 | F7: =E7+F6 -> 20 | G7: 4 | H7: =G7+H6 -> 24 | I7: 2 | J7: =I7+J6 -> 10 | K7: =IF(G7-I7<=$E7-2,1,0) -> 1 | L7: =K7+L6 -> 1 | M7: =IF(K7=0,IF(G7=$E7,1,0),0) -> 0 | N7: =M7+N6 -> 0 | P7: =IF($E7-G7=1,1,0) -> 0 | Q7: =P7+Q6 -> 0 | R7: =IF(G7=$E7,1,0) -> 1 | S7: =R7+S6 -> 1 | T7: =IF(G7-$E7=1,1,0) -> 0 | U7: =T7+U6 -> 4 | V7: =IF(G7-$E7>=2,1,0) -> 0 | W7: =V7+W6 -> 0 | X7: =IF(I7=0,1,0) -> 0 | Y7: =X7+Y6 -> 0 | Z7: =IF(I7=1,1,0) -> 0 | AA7: =Z7+AA6 -> 0 | AB7: =IF(I7=2,1,0) -> 1 | AC7: =AB7+AC6 -> 5 | AD7: =IF(I7>=3,1,0) -> 0 | AE7: =AD7+AE6 -> 0 | AG7: =IF($E7=4,G7-4,NA()) -> 0 | AI7: =G7-'Zusammenfassung Tag1-4'!$B$2/18 -> 3.1666667 | AJ7: =AI7+AJ6 -> 19.833333 | AK7: 5 | AL7: =AK7+AL6 -> 22 | AM7: 2 | AN7: =AM7+AN6 -> 10 | AO7: =IF(AK7-AM7<=$E7-2,1,0) -> 0 | AP7: =AO7+AP6 -> 3 | AQ7: =IF(AO7=0,IF(AK7=$E7,1,0),0) -> 0 | AR7: =AQ7+AR6 -> 1 | AT7: =IF($E7-AK7=1,1,0) -> 0 | AU7: =AT7+AU6 -> 0 | AV7: =IF(AK7=$E7,1,0) -> 0 | AW7: =AV7+AW6 -> 3 | AX7: =IF(AK7-$E7=1,1,0) -> 1 | AY7: =AX7+AY6 -> 2 | AZ7: =IF(AK7-$E7>=2,1,0) -> 0 | BA7: =AZ7+BA6 -> 0 | BB7: =IF(AM7=0,1,0) -> 0 | BC7: =BB7+BC6 -> 0 | BD7: =IF(AM7=1,1,0) -> 0 | BE7: =BD7+BE6 -> 1 | BF7: =IF(AM7=2,1,0) -> 1 | BG7: =BF7+BG6 -> 3 | BH7: =IF(AM7>=3,1,0) -> 0 | BI7: =BH7+BI6 -> 1 | BK7: =IF($E7=4,AK7-4,NA()) -> 1 | BM7: =AK7-'Zusammenfassung Tag1-4'!$C$2/18 -> 4.4444444 | BN7: =BM7+BN6 -> 19.222222 | BO7: 4 | BP7: =BO7+BP6 -> 30 | BQ7: 2 | BR7: =BQ7+BR6 -> 12 | BS7: =IF(BO7-BQ7<=$E7-2,1,0) -> 1 | BT7: =BS7+BT6 -> 2 | BU7: =IF(BS7=0,IF(BO7=$E7,1,0),0) -> 0 | BV7: =BU7+BV6 -> 0 | BX7: =IF($E7-BO7=1,1,0) -> 0 | BY7: =BX7+BY6 -> 0 | BZ7: =IF(BO7=$E7,1,0) -> 1 | CA7: =BZ7+CA6 -> 1 | CB7: =IF(BO7-$E7=1,1,0) -> 0 | CC7: =CB7+CC6 -> 1 | CD7: =IF(BO7-$E7>=2,1,0) -> 0 | CE7: =CD7+CE6 -> 3 | CF7: =IF(BQ7=0,1,0) -> 0 | CG7: =CF7+CG6 -> 0 | CH7: =IF(BQ7=1,1,0) -> 0 | CI7: =CH7+CI6 -> 0 | CJ7: =IF(BQ7=2,1,0) -> 1 | CK7: =CJ7+CK6 -> 3 | CL7: =IF(BQ7>=3,1,0) -> 0 | CM7: =CL7+CM6 -> 2 | CO7: =IF($E7=4,BO7-4,NA()) -> 0 | CQ7: =BO7-'Zusammenfassung Tag1-4'!$D$2/18 -> 2.9444444 | CR7: =CQ7+CR6 -> 24.722222 | CS7: 5 | CT7: =CS7+CT6 -> 26 | CU7: 3 | CV7: =CU7+CV6 -> 13 | CW7: =IF(CS7-CU7<=$E7-2,1,0) -> 1 | CX7: =CW7+CX6 -> 3 | CY7: =IF(CW7=0,IF(CS7=$E7,1,0),0) -> 0 | CZ7: =CY7+CZ6 -> 0 | DB7: =IF($E7-CS7=1,1,0) -> 0 | DC7: =DB7+DC6 -> 0 | DD7: =IF(CS7=$E7,1,0) -> 0 | DE7: =DD7+DE6 -> 1 | DF7: =IF(CS7-$E7=1,1,0) -> 1 | DG7: =DF7+DG6 -> 2 | DH7: =IF(CS7-$E7>=2,1,0) -> 0 | DI7: =DH7+DI6 -> 2 | DJ7: =IF(CU7=0,1,0) -> 0 | DK7: =DJ7+DK6 -> 0 | DL7: =IF(CU7=1,1,0) -> 0 | DM7: =DL7+DM6 -> 0 | DN7: =IF(CU7=2,1,0) -> 0 | DO7: =DN7+DO6 -> 2 | DP7: =IF(CU7>=3,1,0) -> 1 | DQ7: =DP7+DQ6 -> 3 | DS7: =IF($E7=4,CS7-4,NA()) -> 1 | DU7: =CS7-'Zusammenfassung Tag1-4'!$E$2/18 -> 4 | DV7: =DU7+DV6 -> 21 | DW7: 6 | DX7: 108 | DY7: 3 | DZ7: =DY7+DZ6 -> 13 | EA7: =IF(DW7-DY7<=$E7-2,1,0) -> 0 | EB7: =EA7+EB6 -> 0 | EC7: =IF(EA7=0,IF(DW7=$E7,1,0),0) -> 0 | ED7: =EC7+ED6 -> 0 | EF7: =IF($E7-DW7=1,1,0) -> 0 | EG7: =EF7+EG6 -> 0 | EH7: =IF(DW7=$E7,1,0) -> 0 | EI7: =EH7+EI6 -> 0 | EJ7: =IF(DW7-$E7=1,1,0) -> 0 | EK7: =EJ7+EK6 -> 0 | EL7: =IF(DW7-$E7>=2,1,0) -> 1 | EM7: =EL7+EM6 -> 5 | EN7: =IF(DY7=0,1,0) -> 0 | EO7: =EN7+EO6 -> 0 | EP7: =IF(DY7=1,1,0) -> 0 | EQ7: =EP7+EQ6 -> 0 | ER7: =IF(DY7=2,1,0) -> 0 | ES7: =ER7+ES6 -> 2 | ET7: =IF(DY7>=3,1,0) -> 1 | EU7: =ET7+EU6 -> 3 | EW7: =IF($E7=4,DW7-4,NA()) -> 2 | EY7: =DW7-'Zusammenfassung Tag1-4'!$F$2/18 -> 3.5 | EZ7: =EY7+EZ6 -> 22.5 | FA7: 5 | FB7: 28 | FC7: 2 | FD7: =FC7+FD6 -> 11 | FE7: =IF(FA7-FC7<=$E7-2,1,0) -> 0 | FF7: =FE7+FF6 -> 0 | FG7: =IF(FE7=0,IF(FA7=$E7,1,0),0) -> 0 | FH7: =FG7+FH6 -> 0 | FJ7: =IF($E7-FA7=1,1,0) -> 0 | FK7: =FJ7+FK6 -> 0 | FL7: =IF(FA7=$E7,1,0) -> 0 | FM7: =FL7+FM6 -> 0 | FN7: =IF(FA7-$E7=1,1,0) -> 1 | FO7: =FN7+FO6 -> 2 | FP7: =IF(FA7-$E7>=2,1,0) -> 0 | FQ7: =FP7+FQ6 -> 3 | FR7: =IF(FC7=0,1,0) -> 0 | FS7: =FR7+FS6 -> 0 | FT7: =IF(FC7=1,1,0) -> 0 | FU7: =FT7+FU6 -> 0 | FV7: =IF(FC7=2,1,0) -> 1 | FW7: =FV7+FW6 -> 4 | FX7: =IF(FC7>=3,1,0) -> 0 | FY7: =FX7+FY6 -> 1 | GA7: =IF($E7=4,FA7-4,NA()) -> 1 | GC7: =FA7-'Zusammenfassung Tag1-4'!$G$2/18 -> 3.7222222 | GD7: =GC7+GD6 -> 23.611111 | GE7: 6 | GF7: 38 | GG7: 2 | GH7: =GG7+GH6 -> 11 | GI7: =IF(GE7-GG7<=$E7-2,1,0) -> 0 | GJ7: =GI7+GJ6 -> 0 | GK7: =IF(GI7=0,IF(GE7=$E7,1,0),0) -> 0 | GL7: =GK7+GL6 -> 0 | GN7: =IF($E7-GE7=1,1,0) -> 0 | GO7: =GN7+GO6 -> 0 | GP7: =IF(GE7=$E7,1,0) -> 0 | GQ7: =GP7+GQ6 -> 0 | GR7: =IF(GE7-$E7=1,1,0) -> 0 | GS7: =GR7+GS6 -> 1 | GT7: =IF(GE7-$E7>=2,1,0) -> 1 | GU7: =GT7+GU6 -> 4 | GV7: =IF(GG7=0,1,0) -> 0 | GW7: =GV7+GW6 -> 0 | GX7: =IF(GG7=1,1,0) -> 0 | GY7: =GX7+GY6 -> 0 | GZ7: =IF(GG7=2,1,0) -> 1 | HA7: =GZ7+HA6 -> 4 | HB7: =IF(GG7>=3,1,0) -> 0 | HC7: =HB7+HC6 -> 1 | HE7: =IF($E7=4,GE7-4,NA()) -> 2 | HG7: =GE7-'Zusammenfassung Tag1-4'!$H$2/18 -> 4.2222222 | HH7: =HG7+HH6 -> 27.111111 | HI7: 4 | HJ7: 25 | HK7: 1 | HL7: =HK7+HL6 -> 9 | HM7: =IF(HI7-HK7<=$E7-2,1,0) -> 0 | HN7: =HM7+HN6 -> 0 | HO7: =IF(HM7=0,IF(HI7=$E7,1,0),0) -> 1 | HP7: =HO7+HP6 -> 1 | HR7: =IF($E7-HI7=1,1,0) -> 0 | HS7: =HR7+HS6 -> 0 | HT7: =IF(HI7=$E7,1,0) -> 1 | HU7: =HT7+HU6 -> 1 | HV7: =IF(HI7-$E7=1,1,0) -> 0 | HW7: =HV7+HW6 -> 0 | HX7: =IF(HI7-$E7>=2,1,0) -> 0 | HY7: =HX7+HY6 -> 4 | HZ7: =IF(HK7=0,1,0) -> 0 | IA7: =HZ7+IA6 -> 0 | IB7: =IF(HK7=1,1,0) -> 1 | IC7: =IB7+IC6 -> 1 | ID7: =IF(HK7=2,1,0) -> 0 | IE7: =ID7+IE6 -> 4 | IF7: =IF(HK7>=3,1,0) -> 0 | IG7: =IF7+IG6 -> 0 | II7: =IF($E7=4,HI7-4,NA()) -> 0 | IK7: =HI7-'Zusammenfassung Tag1-4'!$I$2/18 -> 3.1111111 | IL7: =IK7+IL6 -> 25.555556 | IM7: 9 | IN7: 172 | IO7: 3 | IP7: =IO7+IP6 -> 15 | IQ7: =IF(IM7-IO7<=$E7-2,1,0) -> 0 | IR7: =IQ7+IR6 -> 2 | IS7: =IF(IQ7=0,IF(IM7=$E7,1,0),0) -> 0 | IT7: =IS7+IT6 -> 0 | IV7: =IF($E7-IM7=1,1,0) -> 0 | IW7: =IV7+IW6 -> 0 | IX7: =IF(IM7=$E7,1,0) -> 0 | IY7: =IX7+IY6 -> 1 | IZ7: =IF(IM7-$E7=1,1,0) -> 0 | JA7: =IZ7+JA6 -> 0 | JB7: =IF(IM7-$E7>=2,1,0) -> 1 | JC7: =JB7+JC6 -> 4 | JD7: =IF(IO7=0,1,0) -> 0 | JE7: =JD7+JE6 -> 0 | JF7: =IF(IO7=1,1,0) -> 0 | JG7: =JF7+JG6 -> 0 | JH7: =IF(IO7=2,1,0) -> 0 | JI7: =JH7+JI6 -> 2 | JJ7: =IF(IO7>=3,1,0) -> 1 | JK7: =JJ7+JK6 -> 3 | JM7: =IF($E7=4,IM7-4,NA()) -> 5 | JO7: =IM7-'Zusammenfassung Tag1-4'!$J$2/18 -> 6.6666667 | JP7: =JO7+JP6 -> 23.333333 | JT7: =JS7+JT6 -> 0 | JU7: =IF(JQ7-JS7<=$E7-2,1,0) -> 1 | JV7: =JU7+JV6 -> 5 | JW7: =IF(JU7=0,IF(JQ7=$E7,1,0),0) -> 0 | JX7: =JW7+JX6 -> 0 | JZ7: =IF($E7-JQ7=1,1,0) -> 0 | KA7: =JZ7+KA6 -> 0 | KB7: =IF(JQ7=$E7,1,0) -> 0 | KC7: =KB7+KC6 -> 0 | KD7: =IF(JQ7-$E7=1,1,0) -> 0 | KE7: =KD7+KE6 -> 0 | KF7: =IF(JQ7-$E7>=2,1,0) -> 0 | KG7: =KF7+KG6 -> 0 | KH7: =IF(JS7=0,1,0) -> 1 | KI7: =KH7+KI6 -> 5 | KJ7: =IF(JS7=1,1,0) -> 0 | KK7: =KJ7+KK6 -> 0 | KL7: =IF(JS7=2,1,0) -> 0 | KM7: =KL7+KM6 -> 0 | KN7: =IF(JS7>=3,1,0) -> 0 | KO7: =KN7+KO6 -> 0 | KQ7: =IF($E7=4,JQ7-4,NA()) -> -4 | KS7: =JQ7-'Zusammenfassung Tag1-4'!#REF!/18 -> #REF! | KT7: =KS7+KT6 -> #REF!
C8: 6 | D8: =D7+1 -> 6 | E8: 4 | F8: =E8+F7 -> 24 | G8: 4 | H8: =G8+H7 -> 28 | I8: 1 | J8: =I8+J7 -> 11 | K8: =IF(G8-I8<=$E8-2,1,0) -> 0 | L8: =K8+L7 -> 1 | M8: =IF(K8=0,IF(G8=$E8,1,0),0) -> 1 | N8: =M8+N7 -> 1 | P8: =IF($E8-G8=1,1,0) -> 0 | Q8: =P8+Q7 -> 0 | R8: =IF(G8=$E8,1,0) -> 1 | S8: =R8+S7 -> 2 | T8: =IF(G8-$E8=1,1,0) -> 0 | U8: =T8+U7 -> 4 | V8: =IF(G8-$E8>=2,1,0) -> 0 | W8: =V8+W7 -> 0 | X8: =IF(I8=0,1,0) -> 0 | Y8: =X8+Y7 -> 0 | Z8: =IF(I8=1,1,0) -> 1 | AA8: =Z8+AA7 -> 1 | AB8: =IF(I8=2,1,0) -> 0 | AC8: =AB8+AC7 -> 5 | AD8: =IF(I8>=3,1,0) -> 0 | AE8: =AD8+AE7 -> 0 | AG8: =IF($E8=4,G8-4,NA()) -> 0 | AI8: =G8-'Zusammenfassung Tag1-4'!$B$2/18 -> 3.1666667 | AJ8: =AI8+AJ7 -> 23 | AK8: 9 | AL8: =AK8+AL7 -> 31 | AM8: 2 | AN8: =AM8+AN7 -> 12 | AO8: =IF(AK8-AM8<=$E8-2,1,0) -> 0 | AP8: =AO8+AP7 -> 3 | AQ8: =IF(AO8=0,IF(AK8=$E8,1,0),0) -> 0 | AR8: =AQ8+AR7 -> 1 | AT8: =IF($E8-AK8=1,1,0) -> 0 | AU8: =AT8+AU7 -> 0 | AV8: =IF(AK8=$E8,1,0) -> 0 | AW8: =AV8+AW7 -> 3 | AX8: =IF(AK8-$E8=1,1,0) -> 0 | AY8: =AX8+AY7 -> 2 | AZ8: =IF(AK8-$E8>=2,1,0) -> 1 | BA8: =AZ8+BA7 -> 1 | BB8: =IF(AM8=0,1,0) -> 0 | BC8: =BB8+BC7 -> 0 | BD8: =IF(AM8=1,1,0) -> 0 | BE8: =BD8+BE7 -> 1 | BF8: =IF(AM8=2,1,0) -> 1 | BG8: =BF8+BG7 -> 4 | BH8: =IF(AM8>=3,1,0) -> 0 | BI8: =BH8+BI7 -> 1 | BK8: =IF($E8=4,AK8-4,NA()) -> 5 | BM8: =AK8-'Zusammenfassung Tag1-4'!$C$2/18 -> 8.4444444 | BN8: =BM8+BN7 -> 27.666667 | BO8: 5 | BP8: =BO8+BP7 -> 35 | BQ8: 2 | BR8: =BQ8+BR7 -> 14 | BS8: =IF(BO8-BQ8<=$E8-2,1,0) -> 0 | BT8: =BS8+BT7 -> 2 | BU8: =IF(BS8=0,IF(BO8=$E8,1,0),0) -> 0 | BV8: =BU8+BV7 -> 0 | BX8: =IF($E8-BO8=1,1,0) -> 0 | BY8: =BX8+BY7 -> 0 | BZ8: =IF(BO8=$E8,1,0) -> 0 | CA8: =BZ8+CA7 -> 1 | CB8: =IF(BO8-$E8=1,1,0) -> 1 | CC8: =CB8+CC7 -> 2 | CD8: =IF(BO8-$E8>=2,1,0) -> 0 | CE8: =CD8+CE7 -> 3 | CF8: =IF(BQ8=0,1,0) -> 0 | CG8: =CF8+CG7 -> 0 | CH8: =IF(BQ8=1,1,0) -> 0 | CI8: =CH8+CI7 -> 0 | CJ8: =IF(BQ8=2,1,0) -> 1 | CK8: =CJ8+CK7 -> 4 | CL8: =IF(BQ8>=3,1,0) -> 0 | CM8: =CL8+CM7 -> 2 | CO8: =IF($E8=4,BO8-4,NA()) -> 1 | CQ8: =BO8-'Zusammenfassung Tag1-4'!$D$2/18 -> 3.9444444 | CR8: =CQ8+CR7 -> 28.666667 | CS8: 5 | CT8: =CS8+CT7 -> 31 | CU8: 3 | CV8: =CU8+CV7 -> 16 | CW8: =IF(CS8-CU8<=$E8-2,1,0) -> 1 | CX8: =CW8+CX7 -> 4 | CY8: =IF(CW8=0,IF(CS8=$E8,1,0),0) -> 0 | CZ8: =CY8+CZ7 -> 0 | DB8: =IF($E8-CS8=1,1,0) -> 0 | DC8: =DB8+DC7 -> 0 | DD8: =IF(CS8=$E8,1,0) -> 0 | DE8: =DD8+DE7 -> 1 | DF8: =IF(CS8-$E8=1,1,0) -> 1 | DG8: =DF8+DG7 -> 3 | DH8: =IF(CS8-$E8>=2,1,0) -> 0 | DI8: =DH8+DI7 -> 2 | DJ8: =IF(CU8=0,1,0) -> 0 | DK8: =DJ8+DK7 -> 0 | DL8: =IF(CU8=1,1,0) -> 0 | DM8: =DL8+DM7 -> 0 | DN8: =IF(CU8=2,1,0) -> 0 | DO8: =DN8+DO7 -> 2 | DP8: =IF(CU8>=3,1,0) -> 1 | DQ8: =DP8+DQ7 -> 4 | DS8: =IF($E8=4,CS8-4,NA()) -> 1 | DU8: =CS8-'Zusammenfassung Tag1-4'!$E$2/18 -> 4 | DV8: =DU8+DV7 -> 25 | DW8: 9 | DX8: 112 | DY8: 2 | DZ8: =DY8+DZ7 -> 15 | EA8: =IF(DW8-DY8<=$E8-2,1,0) -> 0 | EB8: =EA8+EB7 -> 0 | EC8: =IF(EA8=0,IF(DW8=$E8,1,0),0) -> 0 | ED8: =EC8+ED7 -> 0 | EF8: =IF($E8-DW8=1,1,0) -> 0 | EG8: =EF8+EG7 -> 0 | EH8: =IF(DW8=$E8,1,0) -> 0 | EI8: =EH8+EI7 -> 0 | EJ8: =IF(DW8-$E8=1,1,0) -> 0 | EK8: =EJ8+EK7 -> 0 | EL8: =IF(DW8-$E8>=2,1,0) -> 1 | EM8: =EL8+EM7 -> 6 | EN8: =IF(DY8=0,1,0) -> 0 | EO8: =EN8+EO7 -> 0 | EP8: =IF(DY8=1,1,0) -> 0 | EQ8: =EP8+EQ7 -> 0 | ER8: =IF(DY8=2,1,0) -> 1 | ES8: =ER8+ES7 -> 3 | ET8: =IF(DY8>=3,1,0) -> 0 | EU8: =ET8+EU7 -> 3 | EW8: =IF($E8=4,DW8-4,NA()) -> 5 | EY8: =DW8-'Zusammenfassung Tag1-4'!$F$2/18 -> 6.5 | EZ8: =EY8+EZ7 -> 29 | FA8: 6 | FB8: 34 | FC8: 2 | FD8: =FC8+FD7 -> 13 | FE8: =IF(FA8-FC8<=$E8-2,1,0) -> 0 | FF8: =FE8+FF7 -> 0 | FG8: =IF(FE8=0,IF(FA8=$E8,1,0),0) -> 0 | FH8: =FG8+FH7 -> 0 | FJ8: =IF($E8-FA8=1,1,0) -> 0 | FK8: =FJ8+FK7 -> 0 | FL8: =IF(FA8=$E8,1,0) -> 0 | FM8: =FL8+FM7 -> 0 | FN8: =IF(FA8-$E8=1,1,0) -> 0 | FO8: =FN8+FO7 -> 2 | FP8: =IF(FA8-$E8>=2,1,0) -> 1 | FQ8: =FP8+FQ7 -> 4 | FR8: =IF(FC8=0,1,0) -> 0 | FS8: =FR8+FS7 -> 0 | FT8: =IF(FC8=1,1,0) -> 0 | FU8: =FT8+FU7 -> 0 | FV8: =IF(FC8=2,1,0) -> 1 | FW8: =FV8+FW7 -> 5 | FX8: =IF(FC8>=3,1,0) -> 0 | FY8: =FX8+FY7 -> 1 | GA8: =IF($E8=4,FA8-4,NA()) -> 2 | GC8: =FA8-'Zusammenfassung Tag1-4'!$G$2/18 -> 4.7222222 | GD8: =GC8+GD7 -> 28.333333 | GE8: 7 | GF8: 45 | GG8: 1 | GH8: =GG8+GH7 -> 12 | GI8: =IF(GE8-GG8<=$E8-2,1,0) -> 0 | GJ8: =GI8+GJ7 -> 0 | GK8: =IF(GI8=0,IF(GE8=$E8,1,0),0) -> 0 | GL8: =GK8+GL7 -> 0 | GN8: =IF($E8-GE8=1,1,0) -> 0 | GO8: =GN8+GO7 -> 0 | GP8: =IF(GE8=$E8,1,0) -> 0 | GQ8: =GP8+GQ7 -> 0 | GR8: =IF(GE8-$E8=1,1,0) -> 0 | GS8: =GR8+GS7 -> 1 | GT8: =IF(GE8-$E8>=2,1,0) -> 1 | GU8: =GT8+GU7 -> 5 | GV8: =IF(GG8=0,1,0) -> 0 | GW8: =GV8+GW7 -> 0 | GX8: =IF(GG8=1,1,0) -> 1 | GY8: =GX8+GY7 -> 1 | GZ8: =IF(GG8=2,1,0) -> 0 | HA8: =GZ8+HA7 -> 4 | HB8: =IF(GG8>=3,1,0) -> 0 | HC8: =HB8+HC7 -> 1 | HE8: =IF($E8=4,GE8-4,NA()) -> 3 | HG8: =GE8-'Zusammenfassung Tag1-4'!$H$2/18 -> 5.2222222 | HH8: =HG8+HH7 -> 32.333333 | HI8: 6 | HJ8: 30 | HK8: 2 | HL8: =HK8+HL7 -> 11 | HM8: =IF(HI8-HK8<=$E8-2,1,0) -> 0 | HN8: =HM8+HN7 -> 0 | HO8: =IF(HM8=0,IF(HI8=$E8,1,0),0) -> 0 | HP8: =HO8+HP7 -> 1 | HR8: =IF($E8-HI8=1,1,0) -> 0 | HS8: =HR8+HS7 -> 0 | HT8: =IF(HI8=$E8,1,0) -> 0 | HU8: =HT8+HU7 -> 1 | HV8: =IF(HI8-$E8=1,1,0) -> 0 | HW8: =HV8+HW7 -> 0 | HX8: =IF(HI8-$E8>=2,1,0) -> 1 | HY8: =HX8+HY7 -> 5 | HZ8: =IF(HK8=0,1,0) -> 0 | IA8: =HZ8+IA7 -> 0 | IB8: =IF(HK8=1,1,0) -> 0 | IC8: =IB8+IC7 -> 1 | ID8: =IF(HK8=2,1,0) -> 1 | IE8: =ID8+IE7 -> 5 | IF8: =IF(HK8>=3,1,0) -> 0 | IG8: =IF8+IG7 -> 0 | II8: =IF($E8=4,HI8-4,NA()) -> 2 | IK8: =HI8-'Zusammenfassung Tag1-4'!$I$2/18 -> 5.1111111 | IL8: =IK8+IL7 -> 30.666667 | IM8: 7 | IN8: 182 | IO8: 4 | IP8: =IO8+IP7 -> 19 | IQ8: =IF(IM8-IO8<=$E8-2,1,0) -> 0 | IR8: =IQ8+IR7 -> 2 | IS8: =IF(IQ8=0,IF(IM8=$E8,1,0),0) -> 0 | IT8: =IS8+IT7 -> 0 | IV8: =IF($E8-IM8=1,1,0) -> 0 | IW8: =IV8+IW7 -> 0 | IX8: =IF(IM8=$E8,1,0) -> 0 | IY8: =IX8+IY7 -> 1 | IZ8: =IF(IM8-$E8=1,1,0) -> 0 | JA8: =IZ8+JA7 -> 0 | JB8: =IF(IM8-$E8>=2,1,0) -> 1 | JC8: =JB8+JC7 -> 5 | JD8: =IF(IO8=0,1,0) -> 0 | JE8: =JD8+JE7 -> 0 | JF8: =IF(IO8=1,1,0) -> 0 | JG8: =JF8+JG7 -> 0 | JH8: =IF(IO8=2,1,0) -> 0 | JI8: =JH8+JI7 -> 2 | JJ8: =IF(IO8>=3,1,0) -> 1 | JK8: =JJ8+JK7 -> 4 | JM8: =IF($E8=4,IM8-4,NA()) -> 3 | JO8: =IM8-'Zusammenfassung Tag1-4'!$J$2/18 -> 4.6666667 | JP8: =JO8+JP7 -> 28 | JT8: =JS8+JT7 -> 0 | JU8: =IF(JQ8-JS8<=$E8-2,1,0) -> 1 | JV8: =JU8+JV7 -> 6 | JW8: =IF(JU8=0,IF(JQ8=$E8,1,0),0) -> 0 | JX8: =JW8+JX7 -> 0 | JZ8: =IF($E8-JQ8=1,1,0) -> 0 | KA8: =JZ8+KA7 -> 0 | KB8: =IF(JQ8=$E8,1,0) -> 0 | KC8: =KB8+KC7 -> 0 | KD8: =IF(JQ8-$E8=1,1,0) -> 0 | KE8: =KD8+KE7 -> 0 | KF8: =IF(JQ8-$E8>=2,1,0) -> 0 | KG8: =KF8+KG7 -> 0 | KH8: =IF(JS8=0,1,0) -> 1 | KI8: =KH8+KI7 -> 6 | KJ8: =IF(JS8=1,1,0) -> 0 | KK8: =KJ8+KK7 -> 0 | KL8: =IF(JS8=2,1,0) -> 0 | KM8: =KL8+KM7 -> 0 | KN8: =IF(JS8>=3,1,0) -> 0 | KO8: =KN8+KO7 -> 0 | KQ8: =IF($E8=4,JQ8-4,NA()) -> -4 | KS8: =JQ8-'Zusammenfassung Tag1-4'!#REF!/18 -> #REF! | KT8: =KS8+KT7 -> #REF!
C9: 7 | D9: =D8+1 -> 7 | E9: 5 | F9: =E9+F8 -> 29 | G9: 6 | H9: =G9+H8 -> 34 | I9: 2 | J9: =I9+J8 -> 13 | K9: =IF(G9-I9<=$E9-2,1,0) -> 0 | L9: =K9+L8 -> 1 | M9: =IF(K9=0,IF(G9=$E9,1,0),0) -> 0 | N9: =M9+N8 -> 1 | P9: =IF($E9-G9=1,1,0) -> 0 | Q9: =P9+Q8 -> 0 | R9: =IF(G9=$E9,1,0) -> 0 | S9: =R9+S8 -> 2 | T9: =IF(G9-$E9=1,1,0) -> 1 | U9: =T9+U8 -> 5 | V9: =IF(G9-$E9>=2,1,0) -> 0 | W9: =V9+W8 -> 0 | X9: =IF(I9=0,1,0) -> 0 | Y9: =X9+Y8 -> 0 | Z9: =IF(I9=1,1,0) -> 0 | AA9: =Z9+AA8 -> 1 | AB9: =IF(I9=2,1,0) -> 1 | AC9: =AB9+AC8 -> 6 | AD9: =IF(I9>=3,1,0) -> 0 | AE9: =AD9+AE8 -> 0 | AH9: =IF($E9=5,G9-5,NA()) -> 1 | AI9: =G9-'Zusammenfassung Tag1-4'!$B$2/18 -> 5.1666667 | AJ9: =AI9+AJ8 -> 28.166667 | AK9: 8 | AL9: =AK9+AL8 -> 39 | AM9: 2 | AN9: =AM9+AN8 -> 14 | AO9: =IF(AK9-AM9<=$E9-2,1,0) -> 0 | AP9: =AO9+AP8 -> 3 | AQ9: =IF(AO9=0,IF(AK9=$E9,1,0),0) -> 0 | AR9: =AQ9+AR8 -> 1 | AT9: =IF($E9-AK9=1,1,0) -> 0 | AU9: =AT9+AU8 -> 0 | AV9: =IF(AK9=$E9,1,0) -> 0 | AW9: =AV9+AW8 -> 3 | AX9: =IF(AK9-$E9=1,1,0) -> 0 | AY9: =AX9+AY8 -> 2 | AZ9: =IF(AK9-$E9>=2,1,0) -> 1 | BA9: =AZ9+BA8 -> 2 | BB9: =IF(AM9=0,1,0) -> 0 | BC9: =BB9+BC8 -> 0 | BD9: =IF(AM9=1,1,0) -> 0 | BE9: =BD9+BE8 -> 1 | BF9: =IF(AM9=2,1,0) -> 1 | BG9: =BF9+BG8 -> 5 | BH9: =IF(AM9>=3,1,0) -> 0 | BI9: =BH9+BI8 -> 1 | BL9: =IF($E9=5,AK9-5,NA()) -> 3 | BM9: =AK9-'Zusammenfassung Tag1-4'!$C$2/18 -> 7.4444444 | BN9: =BM9+BN8 -> 35.111111 | BO9: 6 | BP9: =BO9+BP8 -> 41 | BQ9: 2 | BR9: =BQ9+BR8 -> 16 | BS9: =IF(BO9-BQ9<=$E9-2,1,0) -> 0 | BT9: =BS9+BT8 -> 2 | BU9: =IF(BS9=0,IF(BO9=$E9,1,0),0) -> 0 | BV9: =BU9+BV8 -> 0 | BX9: =IF($E9-BO9=1,1,0) -> 0 | BY9: =BX9+BY8 -> 0 | BZ9: =IF(BO9=$E9,1,0) -> 0 | CA9: =BZ9+CA8 -> 1 | CB9: =IF(BO9-$E9=1,1,0) -> 1 | CC9: =CB9+CC8 -> 3 | CD9: =IF(BO9-$E9>=2,1,0) -> 0 | CE9: =CD9+CE8 -> 3 | CF9: =IF(BQ9=0,1,0) -> 0 | CG9: =CF9+CG8 -> 0 | CH9: =IF(BQ9=1,1,0) -> 0 | CI9: =CH9+CI8 -> 0 | CJ9: =IF(BQ9=2,1,0) -> 1 | CK9: =CJ9+CK8 -> 5 | CL9: =IF(BQ9>=3,1,0) -> 0 | CM9: =CL9+CM8 -> 2 | CP9: =IF($E9=5,BO9-5,NA()) -> 1 | CQ9: =BO9-'Zusammenfassung Tag1-4'!$D$2/18 -> 4.9444444 | CR9: =CQ9+CR8 -> 33.611111 | CS9: 8 | CT9: =CS9+CT8 -> 39 | CU9: 2 | CV9: =CU9+CV8 -> 18 | CW9: =IF(CS9-CU9<=$E9-2,1,0) -> 0 | CX9: =CW9+CX8 -> 4 | CY9: =IF(CW9=0,IF(CS9=$E9,1,0),0) -> 0 | CZ9: =CY9+CZ8 -> 0 | DB9: =IF($E9-CS9=1,1,0) -> 0 | DC9: =DB9+DC8 -> 0 | DD9: =IF(CS9=$E9,1,0) -> 0 | DE9: =DD9+DE8 -> 1 | DF9: =IF(CS9-$E9=1,1,0) -> 0 | DG9: =DF9+DG8 -> 3 | DH9: =IF(CS9-$E9>=2,1,0) -> 1 | DI9: =DH9+DI8 -> 3 | DJ9: =IF(CU9=0,1,0) -> 0 | DK9: =DJ9+DK8 -> 0 | DL9: =IF(CU9=1,1,0) -> 0 | DM9: =DL9+DM8 -> 0 | DN9: =IF(CU9=2,1,0) -> 1 | DO9: =DN9+DO8 -> 3 | DP9: =IF(CU9>=3,1,0) -> 0 | DQ9: =DP9+DQ8 -> 4 | DT9: =IF($E9=5,CS9-5,NA()) -> 3 | DU9: =CS9-'Zusammenfassung Tag1-4'!$E$2/18 -> 7 | DV9: =DU9+DV8 -> 32 | DW9: 10 | DX9: 118 | DY9: 3 | DZ9: =DY9+DZ8 -> 18 | EA9: =IF(DW9-DY9<=$E9-2,1,0) -> 0 | EB9: =EA9+EB8 -> 0 | EC9: =IF(EA9=0,IF(DW9=$E9,1,0),0) -> 0 | ED9: =EC9+ED8 -> 0 | EF9: =IF($E9-DW9=1,1,0) -> 0 | EG9: =EF9+EG8 -> 0 | EH9: =IF(DW9=$E9,1,0) -> 0 | EI9: =EH9+EI8 -> 0 | EJ9: =IF(DW9-$E9=1,1,0) -> 0 | EK9: =EJ9+EK8 -> 0 | EL9: =IF(DW9-$E9>=2,1,0) -> 1 | EM9: =EL9+EM8 -> 7 | EN9: =IF(DY9=0,1,0) -> 0 | EO9: =EN9+EO8 -> 0 | EP9: =IF(DY9=1,1,0) -> 0 | EQ9: =EP9+EQ8 -> 0 | ER9: =IF(DY9=2,1,0) -> 0 | ES9: =ER9+ES8 -> 3 | ET9: =IF(DY9>=3,1,0) -> 1 | EU9: =ET9+EU8 -> 4 | EX9: =IF($E9=5,DW9-5,NA()) -> 5 | EY9: =DW9-'Zusammenfassung Tag1-4'!$F$2/18 -> 7.5 | EZ9: =EY9+EZ8 -> 36.5 | FA9: 8 | FB9: 41 | FC9: 1 | FD9: =FC9+FD8 -> 14 | FE9: =IF(FA9-FC9<=$E9-2,1,0) -> 0 | FF9: =FE9+FF8 -> 0 | FG9: =IF(FE9=0,IF(FA9=$E9,1,0),0) -> 0 | FH9: =FG9+FH8 -> 0 | FJ9: =IF($E9-FA9=1,1,0) -> 0 | FK9: =FJ9+FK8 -> 0 | FL9: =IF(FA9=$E9,1,0) -> 0 | FM9: =FL9+FM8 -> 0 | FN9: =IF(FA9-$E9=1,1,0) -> 0 | FO9: =FN9+FO8 -> 2 | FP9: =IF(FA9-$E9>=2,1,0) -> 1 | FQ9: =FP9+FQ8 -> 5 | FR9: =IF(FC9=0,1,0) -> 0 | FS9: =FR9+FS8 -> 0 | FT9: =IF(FC9=1,1,0) -> 1 | FU9: =FT9+FU8 -> 1 | FV9: =IF(FC9=2,1,0) -> 0 | FW9: =FV9+FW8 -> 5 | FX9: =IF(FC9>=3,1,0) -> 0 | FY9: =FX9+FY8 -> 1 | GB9: =IF($E9=5,FA9-5,NA()) -> 3 | GC9: =FA9-'Zusammenfassung Tag1-4'!$G$2/18 -> 6.7222222 | GD9: =GC9+GD8 -> 35.055556 | GE9: 10 | GF9: 55 | GG9: 2 | GH9: =GG9+GH8 -> 14 | GI9: =IF(GE9-GG9<=$E9-2,1,0) -> 0 | GJ9: =GI9+GJ8 -> 0 | GK9: =IF(GI9=0,IF(GE9=$E9,1,0),0) -> 0 | GL9: =GK9+GL8 -> 0 | GN9: =IF($E9-GE9=1,1,0) -> 0 | GO9: =GN9+GO8 -> 0 | GP9: =IF(GE9=$E9,1,0) -> 0 | GQ9: =GP9+GQ8 -> 0 | GR9: =IF(GE9-$E9=1,1,0) -> 0 | GS9: =GR9+GS8 -> 1 | GT9: =IF(GE9-$E9>=2,1,0) -> 1 | GU9: =GT9+GU8 -> 6 | GV9: =IF(GG9=0,1,0) -> 0 | GW9: =GV9+GW8 -> 0 | GX9: =IF(GG9=1,1,0) -> 0 | GY9: =GX9+GY8 -> 1 | GZ9: =IF(GG9=2,1,0) -> 1 | HA9: =GZ9+HA8 -> 5 | HB9: =IF(GG9>=3,1,0) -> 0 | HC9: =HB9+HC8 -> 1 | HF9: =IF($E9=5,GE9-5,NA()) -> 5 | HG9: =GE9-'Zusammenfassung Tag1-4'!$H$2/18 -> 8.2222222 | HH9: =HG9+HH8 -> 40.555556 | HI9: 7 | HJ9: 36 | HK9: 1 | HL9: =HK9+HL8 -> 12 | HM9: =IF(HI9-HK9<=$E9-2,1,0) -> 0 | HN9: =HM9+HN8 -> 0 | HO9: =IF(HM9=0,IF(HI9=$E9,1,0),0) -> 0 | HP9: =HO9+HP8 -> 1 | HR9: =IF($E9-HI9=1,1,0) -> 0 | HS9: =HR9+HS8 -> 0 | HT9: =IF(HI9=$E9,1,0) -> 0 | HU9: =HT9+HU8 -> 1 | HV9: =IF(HI9-$E9=1,1,0) -> 0 | HW9: =HV9+HW8 -> 0 | HX9: =IF(HI9-$E9>=2,1,0) -> 1 | HY9: =HX9+HY8 -> 6 | HZ9: =IF(HK9=0,1,0) -> 0 | IA9: =HZ9+IA8 -> 0 | IB9: =IF(HK9=1,1,0) -> 1 | IC9: =IB9+IC8 -> 2 | ID9: =IF(HK9=2,1,0) -> 0 | IE9: =ID9+IE8 -> 5 | IF9: =IF(HK9>=3,1,0) -> 0 | IG9: =IF9+IG8 -> 0 | IJ9: =IF($E9=5,HI9-5,NA()) -> 2 | IK9: =HI9-'Zusammenfassung Tag1-4'!$I$2/18 -> 6.1111111 | IL9: =IK9+IL8 -> 36.777778 | IM9: 9 | IN9: 189 | IO9: 2 | IP9: =IO9+IP8 -> 21 | IQ9: =IF(IM9-IO9<=$E9-2,1,0) -> 0 | IR9: =IQ9+IR8 -> 2 | IS9: =IF(IQ9=0,IF(IM9=$E9,1,0),0) -> 0 | IT9: =IS9+IT8 -> 0 | IV9: =IF($E9-IM9=1,1,0) -> 0 | IW9: =IV9+IW8 -> 0 | IX9: =IF(IM9=$E9,1,0) -> 0 | IY9: =IX9+IY8 -> 1 | IZ9: =IF(IM9-$E9=1,1,0) -> 0 | JA9: =IZ9+JA8 -> 0 | JB9: =IF(IM9-$E9>=2,1,0) -> 1 | JC9: =JB9+JC8 -> 6 | JD9: =IF(IO9=0,1,0) -> 0 | JE9: =JD9+JE8 -> 0 | JF9: =IF(IO9=1,1,0) -> 0 | JG9: =JF9+JG8 -> 0 | JH9: =IF(IO9=2,1,0) -> 1 | JI9: =JH9+JI8 -> 3 | JJ9: =IF(IO9>=3,1,0) -> 0 | JK9: =JJ9+JK8 -> 4 | JN9: =IF($E9=5,IM9-5,NA()) -> 4 | JO9: =IM9-'Zusammenfassung Tag1-4'!$J$2/18 -> 6.6666667 | JP9: =JO9+JP8 -> 34.666667 | JT9: =JS9+JT8 -> 0 | JU9: =IF(JQ9-JS9<=$E9-2,1,0) -> 1 | JV9: =JU9+JV8 -> 7 | JW9: =IF(JU9=0,IF(JQ9=$E9,1,0),0) -> 0 | JX9: =JW9+JX8 -> 0 | JZ9: =IF($E9-JQ9=1,1,0) -> 0 | KA9: =JZ9+KA8 -> 0 | KB9: =IF(JQ9=$E9,1,0) -> 0 | KC9: =KB9+KC8 -> 0 | KD9: =IF(JQ9-$E9=1,1,0) -> 0 | KE9: =KD9+KE8 -> 0 | KF9: =IF(JQ9-$E9>=2,1,0) -> 0 | KG9: =KF9+KG8 -> 0 | KH9: =IF(JS9=0,1,0) -> 1 | KI9: =KH9+KI8 -> 7 | KJ9: =IF(JS9=1,1,0) -> 0 | KK9: =KJ9+KK8 -> 0 | KL9: =IF(JS9=2,1,0) -> 0 | KM9: =KL9+KM8 -> 0 | KN9: =IF(JS9>=3,1,0) -> 0 | KO9: =KN9+KO8 -> 0 | KR9: =IF($E9=5,JQ9-5,NA()) -> -5 | KS9: =JQ9-'Zusammenfassung Tag1-4'!#REF!/18 -> #REF! | KT9: =KS9+KT8 -> #REF!
