Workbook

Sheet Rohdaten
A1: Tag 1 Zuoz | B1: Course | G1: Manu | AJ1: Parli | BM1: Meiky | CP1: Pulfer | DS1: Andrea | EV1: Jens | FY1: Köbi | HB1: Lenz | IE1: Justine | JH1: Thömme
B2: Abschnitt | C2: Loch | D2: Loch kum | E2: Par | F2: Par kum | G2: Schläge | H2: Schläge kum | I2: Putts | J2: Putts kum | K2: GIR | L2: GIR kum | M2: Up/Down | N2: Up/Down kum | O2: Birdie | P2: Birdie kum | Q2: Pars | R2: Pars kum | S2: Bogeys | T2: Bogeys kum | U2: D.Bogey+ | V2: D.Bogey+ kum | W2: Chip in | X2: Chip in kum | Y2: 1 Put | Z2: 1 Put kum | AA2: 2 Put | AB2: 2 Put kum | AC2: 3+ Put | AD2: 3+ Put kum | AE2: Par3 Perf | AF2: Par4 Perf | AG2: Par5 Perf | AH2: Netto | AI2: Netto kum | AJ2: Schläge | AK2: Schläge kum | AL2: Putts | AM2: Putts kum | AN2: GIR | AO2: GIR kum | AP2: Up/Down | AQ2: Up/Down kum | AR2: Birdie | AS2: Birdie kum | AT2: Pars | AU2: Pars kum | AV2: Bogeys | AW2: Bogeys kum | AX2: D.Bogey+ | AY2: D.Bogey+ kum | AZ2: Chip in | BA2: Chip in kum | BB2: 1 Put | BC2: 1 Put kum | BD2: 2 Put | BE2: 2 Put kum | BF2: 3+ Put | BG2: 3+ Put kum | BH2: Par3 Perf | BI2: Par4 Perf | BJ2: Par5 Perf | BK2: Netto | BL2: Netto kum | BM2: Schläge | BN2: Schläge kum | BO2: Putts | BP2: Putts kum | BQ2: GIR | BR2: GIR kum | BS2: Up/Down | BT2: Up/Down kum | BU2: Birdie | BV2: Birdie kum | BW2: Pars | BX2: Pars kum | BY2: Bogeys | BZ2: Bogeys kum | CA2: D.Bogey+ | CB2: D.Bogey+ kum | CC2: Chip in | CD2: Chip in kum | CE2: 1 Put | CF2: 1 Put kum | CG2: 2 Put | CH2: 2 Put kum | CI2: 3+ Put | CJ2: 3+ Put kum | CK2: Par3 Perf | CL2: Par4 Perf | CM2: Par5 Perf | CN2: Netto | CO2: Netto kum | CP2: Schläge | CQ2: Schläge kum | CR2: Putts | CS2: Putts kum | CT2: GIR | CU2: GIR kum | CV2: Up/Down | CW2: Up/Down kum | CX2: Birdie | CY2: Birdie kum | CZ2: Pars | DA2: Pars kum | DB2: Bogeys | DC2: Bogeys kum | DD2: D.Bogey+ | DE2: D.Bogey+ kum | DF2: Chip in | DG2: Chip in kum | DH2: 1 Put | DI2: 1 Put kum | DJ2: 2 Put | DK2: 2 Put kum | DL2: 3+ Put | DM2: 3+ Put kum | DN2: Par3 Perf | DO2: Par4 Perf | DP2: Par5 Perf | DQ2: Netto | DR2: Netto kum | DS2: Schläge | DT2: Schläge kum | DU2: Putts | DV2: Putts kum | DW2: GIR | DX2: GIR kum | DY2: Up/Down | DZ2: Up/Down kum | EA2: Birdie | EB2: Birdie kum | EC2: Pars | ED2: Pars kum | EE2: Bogeys | EF2: Bogeys kum | EG2: D.Bogey+ | EH2: D.Bogey+ kum | EI2: Chip in | EJ2: Chip in kum | EK2: 1 Put | EL2: 1 Put kum | EM2: 2 Put | EN2: 2 Put kum | EO2: 3+ Put | EP2: 3+ Put kum | EQ2: Par3 Perf | ER2: Par4 Perf | ES2: Par5 Perf | ET2: Netto | EU2: Netto kum | EV2: Schläge | EW2: Schläge kum | EX2: Putts | EY2: Putts kum | EZ2: GIR | FA2: GIR kum | FB2: Up/Down | FC2: Up/Down kum | FD2: Birdie | FE2: Birdie kum | FF2: Pars | FG2: Pars kum | FH2: Bogeys | FI2: Bogeys kum | FJ2: D.Bogey+ | FK2: D.Bogey+ kum | FL2: Chip in | FM2: Chip in kum | FN2: 1 Put | FO2: 1 Put kum | FP2: 2 Put | FQ2: 2 Put kum | FR2: 3+ Put | FS2: 3+ Put kum | FT2: Par3 Perf | FU2: Par4 Perf | FV2: Par5 Perf | FW2: Netto | FX2: Netto kum | FY2: Schläge | FZ2: Schläge kum | GA2: Putts | GB2: Putts kum | GC2: GIR | GD2: GIR kum | GE2: Up/Down | GF2: Up/Down kum | GG2: Birdie | GH2: Birdie kum | GI2: Pars | GJ2: Pars kum | GK2: Bogeys | GL2: Bogeys kum | GM2: D.Bogey+ | GN2: D.Bogey+ kum | GO2: Chip in | GP2: Chip in kum | GQ2: 1 Put | GR2: 1 Put kum | GS2: 2 Put | GT2: 2 Put kum | GU2: 3+ Put | GV2: 3+ Put kum | GW2: Par3 Perf | GX2: Par4 Perf | GY2: Par5 Perf | GZ2: Netto | HA2: Netto kum | HB2: Schläge | HC2: Schläge kum | HD2: Putts | HE2: Putts kum | HF2: GIR | HG2: GIR kum | HH2: Up/Down | HI2: Up/Down kum | HJ2: Birdie | HK2: Birdie kum | HL2: Pars | HM2: Pars kum | HN2: Bogeys | HO2: Bogeys kum | HP2: D.Bogey+ | HQ2: D.Bogey+ kum | HR2: Chip in | HS2: Chip in kum | HT2: 1 Put | HU2: 1 Put kum | HV2: 2 Put | HW2: 2 Put kum | HX2: 3+ Put | HY2: 3+ Put kum | HZ2: Par3 Perf | IA2: Par4 Perf | IB2: Par5 Perf | IC2: Netto | ID2: Netto kum | IE2: Schläge | IF2: Schläge kum | IG2: Putts | IH2: Putts kum | II2: GIR | IJ2: GIR kum | IK2: Up/Down | IL2: Up/Down kum | IM2: Birdie | IN2: Birdie kum | IO2: Pars | IP2: Pars kum | IQ2: Bogeys | IR2: Bogeys kum | IS2: D.Bogey+ | IT2: D.Bogey+ kum | IU2: Chip in | IV2: Chip in kum | IW2: 1 Put | IX2: 1 Put kum | IY2: 2 Put | IZ2: 2 Put kum | JA2: 3+ Put | JB2: 3+ Put kum | JC2: Par3 Perf | JD2: Par4 Perf | JE2: Par5 Perf | JF2: Netto | JG2: Netto kum | JH2: Schläge | JI2: Schläge kum | JJ2: Putts | JK2: Putts kum | JL2: GIR | JM2: GIR kum | JN2: Up/Down | JO2: Up/Down kum | JP2: Birdie | JQ2: Birdie kum | JR2: Pars | JS2: Pars kum | JT2: Bogeys | JU2: Bogeys kum | JV2: D.Bogey+ | JW2: D.Bogey+ kum | JX2: Chip in | JY2: Chip in kum | JZ2: 1 Put | KA2: 1 Put kum | KB2: 2 Put | KC2: 2 Put kum | KD2: 3+ Put | KE2: 3+ Put kum | KF2: Par3 Perf | KG2: Par4 Perf | KH2: Par5 Perf | KI2: Netto | KJ2: Netto kum
B3: Front Nine | C3: 1 | D3: =C3 -> 1 | E3: 4 | F3: =E3 -> 4 | G3: 4 | H3: =G3 -> 4 | I3: 2 | J3: =I3 -> 2 | K3: =IF(G3-I3<=$E3-2,1,0) -> 1 | L3: =K3 -> 1 | M3: =IF(K3=0,IF(G3=$E3,1,0),0) -> 0 | N3: =M3 -> 0 | O3: =IF($E3-G3=1,1,0) -> 0 | P3: =O3 -> 0 | Q3: =IF(G3=$E3,1,0) -> 1 | R3: =Q3 -> 1 | S3: =IF(G3-$E3=1,1,0) -> 0 | T3: =S3 -> 0 | U3: =IF(G3-$E3>=2,1,0) -> 0 | V3: =U3 -> 0 | W3: =IF(I3=0,1,0) -> 0 | X3: =W3 -> 0 | Y3: =IF(I3=1,1,0) -> 0 | Z3: =Y3 -> 0 | AA3: =IF(I3=2,1,0) -> 1 | AB3: =AA3 -> 1 | AC3: =IF(I3>=3,1,0) -> 0 | AD3: =AC3 -> 0 | AF3: =IF($E3=4,G3-4,NA()) -> 0 | AH3: =G3-'Zusammenfassung Tag1-4'!$B$2/18 -> 2.8888889 | AI3: =AH3 -> 2.8888889 | AJ3: 4 | AK3: =AJ3 -> 4 | AL3: 2 | AM3: =AL3 -> 2 | AN3: =IF(AJ3-AL3<=$E3-2,1,0) -> 1 | AO3: =AN3 -> 1 | AP3: =IF(AN3=0,IF(AJ3=$E3,1,0),0) -> 0 | AQ3: =AP3 -> 0 | AR3: =IF($E3-AJ3=1,1,0) -> 0 | AS3: =AR3 -> 0 | AT3: =IF(AJ3=$E3,1,0) -> 1 | AU3: =AT3 -> 1 | AV3: =IF(AJ3-$E3=1,1,0) -> 0 | AW3: =AV3 -> 0 | AX3: =IF(AJ3-$E3>=2,1,0) -> 0 | AY3: =AX3 -> 0 | AZ3: =IF(AL3=0,1,0) -> 0 | BA3: =AZ3 -> 0 | BB3: =IF(AL3=1,1,0) -> 0 | BC3: =BB3 -> 0 | BD3: =IF(AL3=2,1,0) -> 1 | BE3: =BD3 -> 1 | BF3: =IF(AL3>=3,1,0) -> 0 | BG3: =BF3 -> 0 | BI3: =IF($E3=4,AJ3-4,NA()) -> 0 | BK3: =AJ3-'Zusammenfassung Tag1-4'!$C$2/18 -> 3.3333333 | BL3: =BK3 -> 3.3333333 | BM3: 4 | BN3: =BM3 -> 4 | BO3: 1 | BP3: =BO3 -> 1 | BQ3: =IF(BM3-BO3<=$E3-2,1,0) -> 0 | BR3: =BQ3 -> 0 | BS3: =IF(BQ3=0,IF(BM3=$E3,1,0),0) -> 1 | BT3: =BS3 -> 1 | BU3: =IF($E3-BM3=1,1,0) -> 0 | BV3: =BU3 -> 0 | BW3: =IF(BM3=$E3,1,0) -> 1 | BX3: =BW3 -> 1 | BY3: =IF(BM3-$E3=1,1,0) -> 0 | BZ3: =BY3 -> 0 | CA3: =IF(BM3-$E3>=2,1,0) -> 0 | CB3: =CA3 -> 0 | CC3: =IF(BO3=0,1,0) -> 0 | CD3: =CC3 -> 0 | CE3: =IF(BO3=1,1,0) -> 1 | CF3: =CE3 -> 1 | CG3: =IF(BO3=2,1,0) -> 0 | CH3: =CG3 -> 0 | CI3: =IF(BO3>=3,1,0) -> 0 | CJ3: =CI3 -> 0 | CL3: =IF($E3=4,BM3-4,NA()) -> 0 | CN3: =BM3-'Zusammenfassung Tag1-4'!$D$2/18 -> 2.6666667 | CO3: =CN3 -> 2.6666667 | CP3: 4 | CQ3: =CP3 -> 4 | CR3: 2 | CS3: =CR3 -> 2 | CT3: =IF(CP3-CR3<=$E3-2,1,0) -> 1 | CU3: =CT3 -> 1 | CV3: =IF(CT3=0,IF(CP3=$E3,1,0),0) -> 0 | CW3: =CV3 -> 0 | CX3: =IF($E3-CP3=1,1,0) -> 0 | CY3: =CX3 -> 0 | CZ3: =IF(CP3=$E3,1,0) -> 1 | DA3: =CZ3 -> 1 | DB3: =IF(CP3-$E3=1,1,0) -> 0 | DC3: =DB3 -> 0 | DD3: =IF(CP3-$E3>=2,1,0) -> 0 | DE3: =DD3 -> 0 | DF3: =IF(CR3=0,1,0) -> 0 | DG3: =DF3 -> 0 | DH3: =IF(CR3=1,1,0) -> 0 | DI3: =DH3 -> 0 | DJ3: =IF(CR3=2,1,0) -> 1 | DK3: =DJ3 -> 1 | DL3: =IF(CR3>=3,1,0) -> 0 | DM3: =DL3 -> 0 | DO3: =IF($E3=4,CP3-4,NA()) -> 0 | DQ3: =CP3-'Zusammenfassung Tag1-4'!$E$2/18 -> 2.7222222 | DR3: =DQ3 -> 2.7222222 | DS3: 7 | DT3: =DS3 -> 7 | DU3: 2 | DV3: =DU3 -> 2 | DW3: =IF(DS3-DU3<=$E3-2,1,0) -> 0 | DX3: =DW3 -> 0 | DY3: =IF(DW3=0,IF(DS3=$E3,1,0),0) -> 0 | DZ3: =DY3 -> 0 | EA3: =IF($E3-DS3=1,1,0) -> 0 | EB3: =EA3 -> 0 | EC3: =IF(DS3=$E3,1,0) -> 0 | ED3: =EC3 -> 0 | EE3: =IF(DS3-$E3=1,1,0) -> 0 | EF3: =EE3 -> 0 | EG3: =IF(DS3-$E3>=2,1,0) -> 1 | EH3: =EG3 -> 1 | EI3: =IF(DU3=0,1,0) -> 0 | EJ3: =EI3 -> 0 | EK3: =IF(DU3=1,1,0) -> 0 | EL3: =EK3 -> 0 | EM3: =IF(DU3=2,1,0) -> 1 | EN3: =EM3 -> 1 | EO3: =IF(DU3>=3,1,0) -> 0 | EP3: =EO3 -> 0 | ER3: =IF($E3=4,DS3-4,NA()) -> 3 | ET3: =DS3-'Zusammenfassung Tag1-4'!$F$2/18 -> 4 | EU3: =ET3 -> 4 | EV3: 4 | EW3: =EV3 -> 4 | EX3: 2 | EY3: =EX3 -> 2 | EZ3: =IF(EV3-EX3<=$E3-2,1,0) -> 1 | FA3: =EZ3 -> 1 | FB3: =IF(EZ3=0,IF(EV3=$E3,1,0),0) -> 0 | FC3: =FB3 -> 0 | FD3: =IF($E3-EV3=1,1,0) -> 0 | FE3: =FD3 -> 0 | FF3: =IF(EV3=$E3,1,0) -> 1 | FG3: =FF3 -> 1 | FH3: =IF(EV3-$E3=1,1,0) -> 0 | FI3: =FH3 -> 0 | FJ3: =IF(EV3-$E3>=2,1,0) -> 0 | FK3: =FJ3 -> 0 | FL3: =IF(EX3=0,1,0) -> 0 | FM3: =FL3 -> 0 | FN3: =IF(EX3=1,1,0) -> 0 | FO3: =FN3 -> 0 | FP3: =IF(EX3=2,1,0) -> 1 | FQ3: =FP3 -> 1 | FR3: =IF(EX3>=3,1,0) -> 0 | FS3: =FR3 -> 0 | FU3: =IF($E3=4,EV3-4,NA()) -> 0 | FW3: =EV3-'Zusammenfassung Tag1-4'!$G$2/18 -> 2.5 | FX3: =FW3 -> 2.5 | FY3: 5 | FZ3: =FY3 -> 5 | GA3: 3 | GB3: =GA3 -> 3 | GC3: =IF(FY3-GA3<=$E3-2,1,0) -> 1 | GD3: =GC3 -> 1 | GE3: =IF(GC3=0,IF(FY3=$E3,1,0),0) -> 0 | GF3: =GE3 -> 0 | GG3: =IF($E3-FY3=1,1,0) -> 0 | GH3: =GG3 -> 0 | GI3: =IF(FY3=$E3,1,0) -> 0 | GJ3: =GI3 -> 0 | GK3: =IF(FY3-$E3=1,1,0) -> 1 | GL3: =GK3 -> 1 | GM3: =IF(FY3-$E3>=2,1,0) -> 0 | GN3: =GM3 -> 0 | GO3: =IF(GA3=0,1,0) -> 0 | GP3: =GO3 -> 0 | GQ3: =IF(GA3=1,1,0) -> 0 | GR3: =GQ3 -> 0 | GS3: =IF(GA3=2,1,0) -> 0 | GT3: =GS3 -> 0 | GU3: =IF(GA3>=3,1,0) -> 1 | GV3: =GU3 -> 1 | GX3: =IF($E3=4,FY3-4,NA()) -> 1 | GZ3: =FY3-'Zusammenfassung Tag1-4'!$H$2/18 -> 2 | HA3: =GZ3 -> 2 | HB3: 5 | HC3: =HB3 -> 5 | HD3: 3 | HE3: =HD3 -> 3 | HF3: =IF(HB3-HD3<=$E3-2,1,0) -> 1 | HG3: =HF3 -> 1 | HH3: =IF(HF3=0,IF(HB3=$E3,1,0),0) -> 0 | HI3: =HH3 -> 0 | HJ3: =IF($E3-HB3=1,1,0) -> 0 | HK3: =HJ3 -> 0 | HL3: =IF(HB3=$E3,1,0) -> 0 | HM3: =HL3 -> 0 | HN3: =IF(HB3-$E3=1,1,0) -> 1 | HO3: =HN3 -> 1 | HP3: =IF(HB3-$E3>=2,1,0) -> 0 | HQ3: =HP3 -> 0 | HR3: =IF(HD3=0,1,0) -> 0 | HS3: =HR3 -> 0 | HT3: =IF(HD3=1,1,0) -> 0 | HU3: =HT3 -> 0 | HV3: =IF(HD3=2,1,0) -> 0 | HW3: =HV3 -> 0 | HX3: =IF(HD3>=3,1,0) -> 1 | HY3: =HX3 -> 1 | IA3: =IF($E3=4,HB3-4,NA()) -> 1 | IC3: =HB3-'Zusammenfassung Tag1-4'!$I$2/18 -> 4 | ID3: =IC3 -> 4 | IF3: =IE3 -> 0 | IH3: =IG3 -> 0 | II3: =IF(IE3-IG3<=$E3-2,1,0) -> 1 | IJ3: =II3 -> 1 | IK3: =IF(II3=0,IF(IE3=$E3,1,0),0) -> 0 | IL3: =IK3 -> 0 | IM3: =IF($E3-IE3=1,1,0) -> 0 | IN3: =IM3 -> 0 | IO3: =IF(IE3=$E3,1,0) -> 0 | IP3: =IO3 -> 0 | IQ3: =IF(IE3-$E3=1,1,0) -> 0 | IR3: =IQ3 -> 0 | IS3: =IF(IE3-$E3>=2,1,0) -> 0 | IT3: =IS3 -> 0 | IU3: =IF(IG3=0,1,0) -> 1 | IV3: =IU3 -> 1 | IW3: =IF(IG3=1,1,0) -> 0 | IX3: =IW3 -> 0 | IY3: =IF(IG3=2,1,0) -> 0 | IZ3: =IY3 -> 0 | JA3: =IF(IG3>=3,1,0) -> 0 | JB3: =JA3 -> 0 | JD3: =IF($E3=4,IE3-4,NA()) -> -4 | JF3: =IE3-'Zusammenfassung Tag1-4'!$J$2/18 -> -3 | JG3: =JF3 -> -3 | JI3: =JH3 -> 0 | JK3: =JJ3 -> 0 | JL3: =IF(JH3-JJ3<=$E3-2,1,0) -> 1 | JM3: =JL3 -> 1 | JN3: =IF(JL3=0,IF(JH3=$E3,1,0),0) -> 0 | JO3: =JN3 -> 0 | JP3: =IF($E3-JH3=1,1,0) -> 0 | JQ3: =JP3 -> 0 | JR3: =IF(JH3=$E3,1,0) -> 0 | JS3: =JR3 -> 0 | JT3: =IF(JH3-$E3=1,1,0) -> 0 | JU3: =JT3 -> 0 | JV3: =IF(JH3-$E3>=2,1,0) -> 0 | JW3: =JV3 -> 0 | JX3: =IF(JJ3=0,1,0) -> 1 | JY3: =JX3 -> 1 | JZ3: =IF(JJ3=1,1,0) -> 0 | KA3: =JZ3 -> 0 | KB3: =IF(JJ3=2,1,0) -> 0 | KC3: =KB3 -> 0 | KD3: =IF(JJ3>=3,1,0) -> 0 | KE3: =KD3 -> 0 | KG3: =IF($E3=4,JH3-4,NA()) -> -4 | KI3: =JH3-'Zusammenfassung Tag1-4'!$K$2/18 -> -0.77777778 | KJ3: =KI3 -> -0.77777778
C4: 2 | D4: =D3+1 -> 2 | E4: 5 | F4: =E4+F3 -> 9 | G4: 5 | H4: =G4+H3 -> 9 | I4: 2 | J4: =I4+J3 -> 4 | K4: =IF(G4-I4<=$E4-2,1,0) -> 1 | L4: =K4+L3 -> 2 | M4: =IF(K4=0,IF(G4=$E4,1,0),0) -> 0 | N4: =M4+N3 -> 0 | O4: =IF($E4-G4=1,1,0) -> 0 | P4: =O4+P3 -> 0 | Q4: =IF(G4=$E4,1,0) -> 1 | R4: =Q4+R3 -> 2 | S4: =IF(G4-$E4=1,1,0) -> 0 | T4: =S4+T3 -> 0 | U4: =IF(G4-$E4>=2,1,0) -> 0 | V4: =U4+V3 -> 0 | W4: =IF(I4=0,1,0) -> 0 | X4: =W4+X3 -> 0 | Y4: =IF(I4=1,1,0) -> 0 | Z4: =Y4+Z3 -> 0 | AA4: =IF(I4=2,1,0) -> 1 | AB4: =AA4+AB3 -> 2 | AC4: =IF(I4>=3,1,0) -> 0 | AD4: =AC4+AD3 -> 0 | AG4: =IF($E4=5,G4-5,NA()) -> 0 | AH4: =G4-'Zusammenfassung Tag1-4'!$B$2/18 -> 3.8888889 | AI4: =AH4+AI3 -> 6.7777778 | AJ4: 5 | AK4: =AJ4+AK3 -> 9 | AL4: 2 | AM4: =AL4+AM3 -> 4 | AN4: =IF(AJ4-AL4<=$E4-2,1,0) -> 1 | AO4: =AN4+AO3 -> 2 | AP4: =IF(AN4=0,IF(AJ4=$E4,1,0),0) -> 0 | AQ4: =AP4+AQ3 -> 0 | AR4: =IF($E4-AJ4=1,1,0) -> 0 | AS4: =AR4+AS3 -> 0 | AT4: =IF(AJ4=$E4,1,0) -> 1 | AU4: =AT4+AU3 -> 2 | AV4: =IF(AJ4-$E4=1,1,0) -> 0 | AW4: =AV4+AW3 -> 0 | AX4: =IF(AJ4-$E4>=2,1,0) -> 0 | AY4: =AX4+AY3 -> 0 | AZ4: =IF(AL4=0,1,0) -> 0 | BA4: =AZ4+BA3 -> 0 | BB4: =IF(AL4=1,1,0) -> 0 | BC4: =BB4+BC3 -> 0 | BD4: =IF(AL4=2,1,0) -> 1 | BE4: =BD4+BE3 -> 2 | BF4: =IF(AL4>=3,1,0) -> 0 | BG4: =BF4+BG3 -> 0 | BJ4: =IF($E4=5,AJ4-5,NA()) -> 0 | BK4: =AJ4-'Zusammenfassung Tag1-4'!$C$2/18 -> 4.3333333 | BL4: =BK4+BL3 -> 7.6666667 | BM4: 8 | BN4: =BM4+BN3 -> 12 | BO4: 3 | BP4: =BO4+BP3 -> 4 | BQ4: =IF(BM4-BO4<=$E4-2,1,0) -> 0 | BR4: =BQ4+BR3 -> 0 | BS4: =IF(BQ4=0,IF(BM4=$E4,1,0),0) -> 0 | BT4: =BS4+BT3 -> 1 | BU4: =IF($E4-BM4=1,1,0) -> 0 | BV4: =BU4+BV3 -> 0 | BW4: =IF(BM4=$E4,1,0) -> 0 | BX4: =BW4+BX3 -> 1 | BY4: =IF(BM4-$E4=1,1,0) -> 0 | BZ4: =BY4+BZ3 -> 0 | CA4: =IF(BM4-$E4>=2,1,0) -> 1 | CB4: =CA4+CB3 -> 1 | CC4: =IF(BO4=0,1,0) -> 0 | CD4: =CC4+CD3 -> 0 | CE4: =IF(BO4=1,1,0) -> 0 | CF4: =CE4+CF3 -> 1 | CG4: =IF(BO4=2,1,0) -> 0 | CH4: =CG4+CH3 -> 0 | CI4: =IF(BO4>=3,1,0) -> 1 | CJ4: =CI4+CJ3 -> 1 | CM4: =IF($E4=5,BM4-5,NA()) -> 3 | CN4: =BM4-'Zusammenfassung Tag1-4'!$D$2/18 -> 6.6666667 | CO4: =CN4+CO3 -> 9.3333333 | CP4: 7 | CQ4: =CP4+CQ3 -> 11 | CR4: 2 | CS4: =CR4+CS3 -> 4 | CT4: =IF(CP4-CR4<=$E4-2,1,0) -> 0 | CU4: =CT4+CU3 -> 1 | CV4: =IF(CT4=0,IF(CP4=$E4,1,0),0) -> 0 | CW4: =CV4+CW3 -> 0 | CX4: =IF($E4-CP4=1,1,0) -> 0 | CY4: =CX4+CY3 -> 0 | CZ4: =IF(CP4=$E4,1,0) -> 0 | DA4: =CZ4+DA3 -> 1 | DB4: =IF(CP4-$E4=1,1,0) -> 0 | DC4: =DB4+DC3 -> 0 | DD4: =IF(CP4-$E4>=2,1,0) -> 1 | DE4: =DD4+DE3 -> 1 | DF4: =IF(CR4=0,1,0) -> 0 | DG4: =DF4+DG3 -> 0 | DH4: =IF(CR4=1,1,0) -> 0 | DI4: =DH4+DI3 -> 0 | DJ4: =IF(CR4=2,1,0) -> 1 | DK4: =DJ4+DK3 -> 2 | DL4: =IF(CR4>=3,1,0) -> 0 | DM4: =DL4+DM3 -> 0 | DP4: =IF($E4=5,CP4-5,NA()) -> 2 | DQ4: =CP4-'Zusammenfassung Tag1-4'!$E$2/18 -> 5.7222222 | DR4: =DQ4+DR3 -> 8.4444444 | DS4: 10 | DT4: =DS4+DT3 -> 17 | DU4: 2 | DV4: =DU4+DV3 -> 4 | DW4: =IF(DS4-DU4<=$E4-2,1,0) -> 0 | DX4: =DW4+DX3 -> 0 | DY4: =IF(DW4=0,IF(DS4=$E4,1,0),0) -> 0 | DZ4: =DY4+DZ3 -> 0 | EA4: =IF($E4-DS4=1,1,0) -> 0 | EB4: =EA4+EB3 -> 0 | EC4: =IF(DS4=$E4,1,0) -> 0 | ED4: =EC4+ED3 -> 0 | EE4: =IF(DS4-$E4=1,1,0) -> 0 | EF4: =EE4+EF3 -> 0 | EG4: =IF(DS4-$E4>=2,1,0) -> 1 | EH4: =EG4+EH3 -> 2 | EI4: =IF(DU4=0,1,0) -> 0 | EJ4: =EI4+EJ3 -> 0 | EK4: =IF(DU4=1,1,0) -> 0 | EL4: =EK4+EL3 -> 0 | EM4: =IF(DU4=2,1,0) -> 1 | EN4: =EM4+EN3 -> 2 | EO4: =IF(DU4>=3,1,0) -> 0 | EP4: =EO4+EP3 -> 0 | ES4: =IF($E4=5,DS4-5,NA()) -> 5 | ET4: =DS4-'Zusammenfassung Tag1-4'!$F$2/18 -> 7 | EU4: =ET4+EU3 -> 11 | EV4: 6 | EW4: =EV4+EW3 -> 10 | EX4: 3 | EY4: =EX4+EY3 -> 5 | EZ4: =IF(EV4-EX4<=$E4-2,1,0) -> 1 | FA4: =EZ4+FA3 -> 2 | FB4: =IF(EZ4=0,IF(EV4=$E4,1,0),0) -> 0 | FC4: =FB4+FC3 -> 0 | FD4: =IF($E4-EV4=1,1,0) -> 0 | FE4: =FD4+FE3 -> 0 | FF4: =IF(EV4=$E4,1,0) -> 0 | FG4: =FF4+FG3 -> 1 | FH4: =IF(EV4-$E4=1,1,0) -> 1 | FI4: =FH4+FI3 -> 1 | FJ4: =IF(EV4-$E4>=2,1,0) -> 0 | FK4: =FJ4+FK3 -> 0 | FL4: =IF(EX4=0,1,0) -> 0 | FM4: =FL4+FM3 -> 0 | FN4: =IF(EX4=1,1,0) -> 0 | FO4: =FN4+FO3 -> 0 | FP4: =IF(EX4=2,1,0) -> 0 | FQ4: =FP4+FQ3 -> 1 | FR4: =IF(EX4>=3,1,0) -> 1 | FS4: =FR4+FS3 -> 1 | FV4: =IF($E4=5,EV4-5,NA()) -> 1 | FW4: =EV4-'Zusammenfassung Tag1-4'!$G$2/18 -> 4.5 | FX4: =FW4+FX3 -> 7 | FY4: 8 | FZ4: =FY4+FZ3 -> 13 | GA4: 3 | GB4: =GA4+GB3 -> 6 | GC4: =IF(FY4-GA4<=$E4-2,1,0) -> 0 | GD4: =GC4+GD3 -> 1 | GE4: =IF(GC4=0,IF(FY4=$E4,1,0),0) -> 0 | GF4: =GE4+GF3 -> 0 | GG4: =IF($E4-FY4=1,1,0) -> 0 | GH4: =GG4+GH3 -> 0 | GI4: =IF(FY4=$E4,1,0) -> 0 | GJ4: =GI4+GJ3 -> 0 | GK4: =IF(FY4-$E4=1,1,0) -> 0 | GL4: =GK4+GL3 -> 1 | GM4: =IF(FY4-$E4>=2,1,0) -> 1 | GN4: =GM4+GN3 -> 1 | GO4: =IF(GA4=0,1,0) -> 0 | GP4: =GO4+GP3 -> 0 | GQ4: =IF(GA4=1,1,0) -> 0 | GR4: =GQ4+GR3 -> 0 | GS4: =IF(GA4=2,1,0) -> 0 | GT4: =GS4+GT3 -> 0 | GU4: =IF(GA4>=3,1,0) -> 1 | GV4: =GU4+GV3 -> 2 | GY4: =IF($E4=5,FY4-5,NA()) -> 3 | GZ4: =FY4-'Zusammenfassung Tag1-4'!$H$2/18 -> 5 | HA4: =GZ4+HA3 -> 7 | HB4: 5 | HC4: =HB4+HC3 -> 10 | HD4: 1 | HE4: =HD4+HE3 -> 4 | HF4: =IF(HB4-HD4<=$E4-2,1,0) -> 0 | HG4: =HF4+HG3 -> 1 | HH4: =IF(HF4=0,IF(HB4=$E4,1,0),0) -> 1 | HI4: =HH4+HI3 -> 1 | HJ4: =IF($E4-HB4=1,1,0) -> 0 | HK4: =HJ4+HK3 -> 0 | HL4: =IF(HB4=$E4,1,0) -> 1 | HM4: =HL4+HM3 -> 1 | HN4: =IF(HB4-$E4=1,1,0) -> 0 | HO4: =HN4+HO3 -> 1 | HP4: =IF(HB4-$E4>=2,1,0) -> 0 | HQ4: =HP4+HQ3 -> 0 | HR4: =IF(HD4=0,1,0) -> 0 | HS4: =HR4+HS3 -> 0 | HT4: =IF(HD4=1,1,0) -> 1 | HU4: =HT4+HU3 -> 1 | HV4: =IF(HD4=2,1,0) -> 0 | HW4: =HV4+HW3 -> 0 | HX4: =IF(HD4>=3,1,0) -> 0 | HY4: =HX4+HY3 -> 1 | IB4: =IF($E4=5,HB4-5,NA()) -> 0 | IC4: =HB4-'Zusammenfassung Tag1-4'!$I$2/18 -> 4 | ID4: =IC4+ID3 -> 8 | IF4: =IE4+IF3 -> 0 | IH4: =IG4+IH3 -> 0 | II4: =IF(IE4-IG4<=$E4-2,1,0) -> 1 | IJ4: =II4+IJ3 -> 2 | IK4: =IF(II4=0,IF(IE4=$E4,1,0),0) -> 0 | IL4: =IK4+IL3 -> 0 | IM4: =IF($E4-IE4=1,1,0) -> 0 | IN4: =IM4+IN3 -> 0 | IO4: =IF(IE4=$E4,1,0) -> 0 | IP4: =IO4+IP3 -> 0 | IQ4: =IF(IE4-$E4=1,1,0) -> 0 | IR4: =IQ4+IR3 -> 0 | IS4: =IF(IE4-$E4>=2,1,0) -> 0 | IT4: =IS4+IT3 -> 0 | IU4: =IF(IG4=0,1,0) -> 1 | IV4: =IU4+IV3 -> 2 | IW4: =IF(IG4=1,1,0) -> 0 | IX4: =IW4+IX3 -> 0 | IY4: =IF(IG4=2,1,0) -> 0 | IZ4: =IY4+IZ3 -> 0 | JA4: =IF(IG4>=3,1,0) -> 0 | JB4: =JA4+JB3 -> 0 | JE4: =IF($E4=5,IE4-5,NA()) -> -5 | JF4: =IE4-'Zusammenfassung Tag1-4'!$J$2/18 -> -3 | JG4: =JF4+JG3 -> -6 | JI4: =JH4+JI3 -> 0 | JK4: =JJ4+JK3 -> 0 | JL4: =IF(JH4-JJ4<=$E4-2,1,0) -> 1 | JM4: =JL4+JM3 -> 2 | JN4: =IF(JL4=0,IF(JH4=$E4,1,0),0) -> 0 | JO4: =JN4+JO3 -> 0 | JP4: =IF($E4-JH4=1,1,0) -> 0 | JQ4: =JP4+JQ3 -> 0 | JR4: =IF(JH4=$E4,1,0) -> 0 | JS4: =JR4+JS3 -> 0 | JT4: =IF(JH4-$E4=1,1,0) -> 0 | JU4: =JT4+JU3 -> 0 | JV4: =IF(JH4-$E4>=2,1,0) -> 0 | JW4: =JV4+JW3 -> 0 | JX4: =IF(JJ4=0,1,0) -> 1 | JY4: =JX4+JY3 -> 2 | JZ4: =IF(JJ4=1,1,0) -> 0 | KA4: =JZ4+KA3 -> 0 | KB4: =IF(JJ4=2,1,0) -> 0 | KC4: =KB4+KC3 -> 0 | KD4: =IF(JJ4>=3,1,0) -> 0 | KE4: =KD4+KE3 -> 0 | KH4: =IF($E4=5,JH4-5,NA()) -> -5 | KI4: =JH4-'Zusammenfassung Tag1-4'!$K$2/18 -> -0.77777778 | KJ4: =KI4+KJ3 -> -1.5555556
C5: 3 | D5: =D4+1 -> 3 | E5: 4 | F5: =E5+F4 -> 13 | G5: 6 | H5: =G5+H4 -> 15 | I5: 2 | J5: =I5+J4 -> 6 | K5: =IF(G5-I5<=$E5-2,1,0) -> 0 | L5: =K5+L4 -> 2 | M5: =IF(K5=0,IF(G5=$E5,1,0),0) -> 0 | N5: =M5+N4 -> 0 | O5: =IF($E5-G5=1,1,0) -> 0 | P5: =O5+P4 -> 0 | Q5: =IF(G5=$E5,1,0) -> 0 | R5: =Q5+R4 -> 2 | S5: =IF(G5-$E5=1,1,0) -> 0 | T5: =S5+T4 -> 0 | U5: =IF(G5-$E5>=2,1,0) -> 1 | V5: =U5+V4 -> 1 | W5: =IF(I5=0,1,0) -> 0 | X5: =W5+X4 -> 0 | Y5: =IF(I5=1,1,0) -> 0 | Z5: =Y5+Z4 -> 0 | AA5: =IF(I5=2,1,0) -> 1 | AB5: =AA5+AB4 -> 3 | AC5: =IF(I5>=3,1,0) -> 0 | AD5: =AC5+AD4 -> 0 | AF5: =IF($E5=4,G5-4,NA()) -> 2 | AH5: =G5-'Zusammenfassung Tag1-4'!$B$2/18 -> 4.8888889 | AI5: =AH5+AI4 -> 11.666667 | AJ5: 4 | AK5: =AJ5+AK4 -> 13 | AL5: 2 | AM5: =AL5+AM4 -> 6 | AN5: =IF(AJ5-AL5<=$E5-2,1,0) -> 1 | AO5: =AN5+AO4 -> 3 | AP5: =IF(AN5=0,IF(AJ5=$E5,1,0),0) -> 0 | AQ5: =AP5+AQ4 -> 0 | AR5: =IF($E5-AJ5=1,1,0) -> 0 | AS5: =AR5+AS4 -> 0 | AT5: =IF(AJ5=$E5,1,0) -> 1 | AU5: =AT5+AU4 -> 3 | AV5: =IF(AJ5-$E5=1,1,0) -> 0 | AW5: =AV5+AW4 -> 0 | AX5: =IF(AJ5-$E5>=2,1,0) -> 0 | AY5: =AX5+AY4 -> 0 | AZ5: =IF(AL5=0,1,0) -> 0 | BA5: =AZ5+BA4 -> 0 | BB5: =IF(AL5=1,1,0) -> 0 | BC5: =BB5+BC4 -> 0 | BD5: =IF(AL5=2,1,0) -> 1 | BE5: =BD5+BE4 -> 3 | BF5: =IF(AL5>=3,1,0) -> 0 | BG5: =BF5+BG4 -> 0 | BI5: =IF($E5=4,AJ5-4,NA()) -> 0 | BK5: =AJ5-'Zusammenfassung Tag1-4'!$C$2/18 -> 3.3333333 | BL5: =BK5+BL4 -> 11 | BM5: 4 | BN5: =BM5+BN4 -> 16 | BO5: 2 | BP5: =BO5+BP4 -> 6 | BQ5: =IF(BM5-BO5<=$E5-2,1,0) -> 1 | BR5: =BQ5+BR4 -> 1 | BS5: =IF(BQ5=0,IF(BM5=$E5,1,0),0) -> 0 | BT5: =BS5+BT4 -> 1 | BU5: =IF($E5-BM5=1,1,0) -> 0 | BV5: =BU5+BV4 -> 0 | BW5: =IF(BM5=$E5,1,0) -> 1 | BX5: =BW5+BX4 -> 2 | BY5: =IF(BM5-$E5=1,1,0) -> 0 | BZ5: =BY5+BZ4 -> 0 | CA5: =IF(BM5-$E5>=2,1,0) -> 0 | CB5: =CA5+CB4 -> 1 | CC5: =IF(BO5=0,1,0) -> 0 | CD5: =CC5+CD4 -> 0 | CE5: =IF(BO5=1,1,0) -> 0 | CF5: =CE5+CF4 -> 1 | CG5: =IF(BO5=2,1,0) -> 1 | CH5: =CG5+CH4 -> 1 | CI5: =IF(BO5>=3,1,0) -> 0 | CJ5: =CI5+CJ4 -> 1 | CL5: =IF($E5=4,BM5-4,NA()) -> 0 | CN5: =BM5-'Zusammenfassung Tag1-4'!$D$2/18 -> 2.6666667 | CO5: =CN5+CO4 -> 12 | CP5: 4 | CQ5: =CP5+CQ4 -> 15 | CR5: 2 | CS5: =CR5+CS4 -> 6 | CT5: =IF(CP5-CR5<=$E5-2,1,0) -> 1 | CU5: =CT5+CU4 -> 2 | CV5: =IF(CT5=0,IF(CP5=$E5,1,0),0) -> 0 | CW5: =CV5+CW4 -> 0 | CX5: =IF($E5-CP5=1,1,0) -> 0 | CY5: =CX5+CY4 -> 0 | CZ5: =IF(CP5=$E5,1,0) -> 1 | DA5: =CZ5+DA4 -> 2 | DB5: =IF(CP5-$E5=1,1,0) -> 0 | DC5: =DB5+DC4 -> 0 | DD5: =IF(CP5-$E5>=2,1,0) -> 0 | DE5: =DD5+DE4 -> 1 | DF5: =IF(CR5=0,1,0) -> 0 | DG5: =DF5+DG4 -> 0 | DH5: =IF(CR5=1,1,0) -> 0 | DI5: =DH5+DI4 -> 0 | DJ5: =IF(CR5=2,1,0) -> 1 | DK5: =DJ5+DK4 -> 3 | DL5: =IF(CR5>=3,1,0) -> 0 | DM5: =DL5+DM4 -> 0 | DO5: =IF($E5=4,CP5-4,NA()) -> 0 | DQ5: =CP5-'Zusammenfassung Tag1-4'!$E$2/18 -> 2.7222222 | DR5: =DQ5+DR4 -> 11.166667 | DS5: 8 | DT5: =DS5+DT4 -> 25 | DU5: 2 | DV5: =DU5+DV4 -> 6 | DW5: =IF(DS5-DU5<=$E5-2,1,0) -> 0 | DX5: =DW5+DX4 -> 0 | DY5: =IF(DW5=0,IF(DS5=$E5,1,0),0) -> 0 | DZ5: =DY5+DZ4 -> 0 | EA5: =IF($E5-DS5=1,1,0) -> 0 | EB5: =EA5+EB4 -> 0 | EC5: =IF(DS5=$E5,1,0) -> 0 | ED5: =EC5+ED4 -> 0 | EE5: =IF(DS5-$E5=1,1,0) -> 0 | EF5: =EE5+EF4 -> 0 | EG5: =IF(DS5-$E5>=2,1,0) -> 1 | EH5: =EG5+EH4 -> 3 | EI5: =IF(DU5=0,1,0) -> 0 | EJ5: =EI5+EJ4 -> 0 | EK5: =IF(DU5=1,1,0) -> 0 | EL5: =EK5+EL4 -> 0 | EM5: =IF(DU5=2,1,0) -> 1 | EN5: =EM5+EN4 -> 3 | EO5: =IF(DU5>=3,1,0) -> 0 | EP5: =EO5+EP4 -> 0 | ER5: =IF($E5=4,DS5-4,NA()) -> 4 | ET5: =DS5-'Zusammenfassung Tag1-4'!$F$2/18 -> 5 | EU5: =ET5+EU4 -> 16 | EV5: 7 | EW5: =EV5+EW4 -> 17 | EX5: 2 | EY5: =EX5+EY4 -> 7 | EZ5: =IF(EV5-EX5<=$E5-2,1,0) -> 0 | FA5: =EZ5+FA4 -> 2 | FB5: =IF(EZ5=0,IF(EV5=$E5,1,0),0) -> 0 | FC5: =FB5+FC4 -> 0 | FD5: =IF($E5-EV5=1,1,0) -> 0 | FE5: =FD5+FE4 -> 0 | FF5: =IF(EV5=$E5,1,0) -> 0 | FG5: =FF5+FG4 -> 1 | FH5: =IF(EV5-$E5=1,1,0) -> 0 | FI5: =FH5+FI4 -> 1 | FJ5: =IF(EV5-$E5>=2,1,0) -> 1 | FK5: =FJ5+FK4 -> 1 | FL5: =IF(EX5=0,1,0) -> 0 | FM5: =FL5+FM4 -> 0 | FN5: =IF(EX5=1,1,0) -> 0 | FO5: =FN5+FO4 -> 0 | FP5: =IF(EX5=2,1,0) -> 1 | FQ5: =FP5+FQ4 -> 2 | FR5: =IF(EX5>=3,1,0) -> 0 | FS5: =FR5+FS4 -> 1 | FU5: =IF($E5=4,EV5-4,NA()) -> 3 | FW5: =EV5-'Zusammenfassung Tag1-4'!$G$2/18 -> 5.5 | FX5: =FW5+FX4 -> 12.5 | FY5: 10 | FZ5: =FY5+FZ4 -> 23 | GA5: 2 | GB5: =GA5+GB4 -> 8 | GC5: =IF(FY5-GA5<=$E5-2,1,0) -> 0 | GD5: =GC5+GD4 -> 1 | GE5: =IF(GC5=0,IF(FY5=$E5,1,0),0) -> 0 | GF5: =GE5+GF4 -> 0 | GG5: =IF($E5-FY5=1,1,0) -> 0 | GH5: =GG5+GH4 -> 0 | GI5: =IF(FY5=$E5,1,0) -> 0 | GJ5: =GI5+GJ4 -> 0 | GK5: =IF(FY5-$E5=1,1,0) -> 0 | GL5: =GK5+GL4 -> 1 | GM5: =IF(FY5-$E5>=2,1,0) -> 1 | GN5: =GM5+GN4 -> 2 | GO5: =IF(GA5=0,1,0) -> 0 | GP5: =GO5+GP4 -> 0 | GQ5: =IF(GA5=1,1,0) -> 0 | GR5: =GQ5+GR4 -> 0 | GS5: =IF(GA5=2,1,0) -> 1 | GT5: =GS5+GT4 -> 1 | GU5: =IF(GA5>=3,1,0) -> 0 | GV5: =GU5+GV4 -> 2 | GX5: =IF($E5=4,FY5-4,NA()) -> 6 | GZ5: =FY5-'Zusammenfassung Tag1-4'!$H$2/18 -> 7 | HA5: =GZ5+HA4 -> 14 | HB5: 4 | HC5: =HB5+HC4 -> 14 | HD5: 2 | HE5: =HD5+HE4 -> 6 | HF5: =IF(HB5-HD5<=$E5-2,1,0) -> 1 | HG5: =HF5+HG4 -> 2 | HH5: =IF(HF5=0,IF(HB5=$E5,1,0),0) -> 0 | HI5: =HH5+HI4 -> 1 | HJ5: =IF($E5-HB5=1,1,0) -> 0 | HK5: =HJ5+HK4 -> 0 | HL5: =IF(HB5=$E5,1,0) -> 1 | HM5: =HL5+HM4 -> 2 | HN5: =IF(HB5-$E5=1,1,0) -> 0 | HO5: =HN5+HO4 -> 1 | HP5: =IF(HB5-$E5>=2,1,0) -> 0 | HQ5: =HP5+HQ4 -> 0 | HR5: =IF(HD5=0,1,0) -> 0 | HS5: =HR5+HS4 -> 0 | HT5: =IF(HD5=1,1,0) -> 0 | HU5: =HT5+HU4 -> 1 | HV5: =IF(HD5=2,1,0) -> 1 | HW5: =HV5+HW4 -> 1 | HX5: =IF(HD5>=3,1,0) -> 0 | HY5: =HX5+HY4 -> 1 | IA5: =IF($E5=4,HB5-4,NA()) -> 0 | IC5: =HB5-'Zusammenfassung Tag1-4'!$I$2/18 -> 3 | ID5: =IC5+ID4 -> 11 | IF5: =IE5+IF4 -> 0 | IH5: =IG5+IH4 -> 0 | II5: =IF(IE5-IG5<=$E5-2,1,0) -> 1 | IJ5: =II5+IJ4 -> 3 | IK5: =IF(II5=0,IF(IE5=$E5,1,0),0) -> 0 | IL5: =IK5+IL4 -> 0 | IM5: =IF($E5-IE5=1,1,0) -> 0 | IN5: =IM5+IN4 -> 0 | IO5: =IF(IE5=$E5,1,0) -> 0 | IP5: =IO5+IP4 -> 0 | IQ5: =IF(IE5-$E5=1,1,0) -> 0 | IR5: =IQ5+IR4 -> 0 | IS5: =IF(IE5-$E5>=2,1,0) -> 0 | IT5: =IS5+IT4 -> 0 | IU5: =IF(IG5=0,1,0) -> 1 | IV5: =IU5+IV4 -> 3 | IW5: =IF(IG5=1,1,0) -> 0 | IX5: =IW5+IX4 -> 0 | IY5: =IF(IG5=2,1,0) -> 0 | IZ5: =IY5+IZ4 -> 0 | JA5: =IF(IG5>=3,1,0) -> 0 | JB5: =JA5+JB4 -> 0 | JD5: =IF($E5=4,IE5-4,NA()) -> -4 | JF5: =IE5-'Zusammenfassung Tag1-4'!$J$2/18 -> -3 | JG5: =JF5+JG4 -> -9 | JI5: =JH5+JI4 -> 0 | JK5: =JJ5+JK4 -> 0 | JL5: =IF(JH5-JJ5<=$E5-2,1,0) -> 1 | JM5: =JL5+JM4 -> 3 | JN5: =IF(JL5=0,IF(JH5=$E5,1,0),0) -> 0 | JO5: =JN5+JO4 -> 0 | JP5: =IF($E5-JH5=1,1,0) -> 0 | JQ5: =JP5+JQ4 -> 0 | JR5: =IF(JH5=$E5,1,0) -> 0 | JS5: =JR5+JS4 -> 0 | JT5: =IF(JH5-$E5=1,1,0) -> 0 | JU5: =JT5+JU4 -> 0 | JV5: =IF(JH5-$E5>=2,1,0) -> 0 | JW5: =JV5+JW4 -> 0 | JX5: =IF(JJ5=0,1,0) -> 1 | JY5: =JX5+JY4 -> 3 | JZ5: =IF(JJ5=1,1,0) -> 0 | KA5: =JZ5+KA4 -> 0 | KB5: =IF(JJ5=2,1,0) -> 0 | KC5: =KB5+KC4 -> 0 | KD5: =IF(JJ5>=3,1,0) -> 0 | KE5: =KD5+KE4 -> 0 | KG5: =IF($E5=4,JH5-4,NA()) -> -4 | KI5: =JH5-'Zusammenfassung Tag1-4'!$K$2/18 -> -0.77777778 | KJ5: =KI5+KJ4 -> -2.3333333
C6: 4 | D6: =D5+1 -> 4 | E6: 3 | F6: =E6+F5 -> 16 | G6: 5 | H6: =G6+H5 -> 20 | I6: 4 | J6: =I6+J5 -> 10 | K6: =IF(G6-I6<=$E6-2,1,0) -> 1 | L6: =K6+L5 -> 3 | M6: =IF(K6=0,IF(G6=$E6,1,0),0) -> 0 | N6: =M6+N5 -> 0 | O6: =IF($E6-G6=1,1,0) -> 0 | P6: =O6+P5 -> 0 | Q6: =IF(G6=$E6,1,0) -> 0 | R6: =Q6+R5 -> 2 | S6: =IF(G6-$E6=1,1,0) -> 0 | T6: =S6+T5 -> 0 | U6: =IF(G6-$E6>=2,1,0) -> 1 | V6: =U6+V5 -> 2 | W6: =IF(I6=0,1,0) -> 0 | X6: =W6+X5 -> 0 | Y6: =IF(I6=1,1,0) -> 0 | Z6: =Y6+Z5 -> 0 | AA6: =IF(I6=2,1,0) -> 0 | AB6: =AA6+AB5 -> 3 | AC6: =IF(I6>=3,1,0) -> 1 | AD6: =AC6+AD5 -> 1 | AE6: =IF($E6=3,G6-3,NA()) -> 2 | AH6: =G6-'Zusammenfassung Tag1-4'!$B$2/18 -> 3.8888889 | AI6: =AH6+AI5 -> 15.555556 | AJ6: 4 | AK6: =AJ6+AK5 -> 17 | AL6: 3 | AM6: =AL6+AM5 -> 9 | AN6: =IF(AJ6-AL6<=$E6-2,1,0) -> 1 | AO6: =AN6+AO5 -> 4 | AP6: =IF(AN6=0,IF(AJ6=$E6,1,0),0) -> 0 | AQ6: =AP6+AQ5 -> 0 | AR6: =IF($E6-AJ6=1,1,0) -> 0 | AS6: =AR6+AS5 -> 0 | AT6: =IF(AJ6=$E6,1,0) -> 0 | AU6: =AT6+AU5 -> 3 | AV6: =IF(AJ6-$E6=1,1,0) -> 1 | AW6: =AV6+AW5 -> 1 | AX6: =IF(AJ6-$E6>=2,1,0) -> 0 | AY6: =AX6+AY5 -> 0 | AZ6: =IF(AL6=0,1,0) -> 0 | BA6: =AZ6+BA5 -> 0 | BB6: =IF(AL6=1,1,0) -> 0 | BC6: =BB6+BC5 -> 0 | BD6: =IF(AL6=2,1,0) -> 0 | BE6: =BD6+BE5 -> 3 | BF6: =IF(AL6>=3,1,0) -> 1 | BG6: =BF6+BG5 -> 1 | BH6: =IF($E6=3,AJ6-3,NA()) -> 1 | BK6: =AJ6-'Zusammenfassung Tag1-4'!$C$2/18 -> 3.3333333 | BL6: =BK6+BL5 -> 14.333333 | BM6: 3 | BN6: =BM6+BN5 -> 19 | BO6: 2 | BP6: =BO6+BP5 -> 8 | BQ6: =IF(BM6-BO6<=$E6-2,1,0) -> 1 | BR6: =BQ6+BR5 -> 2 | BS6: =IF(BQ6=0,IF(BM6=$E6,1,0),0) -> 0 | BT6: =BS6+BT5 -> 1 | BU6: =IF($E6-BM6=1,1,0) -> 0 | BV6: =BU6+BV5 -> 0 | BW6: =IF(BM6=$E6,1,0) -> 1 | BX6: =BW6+BX5 -> 3 | BY6: =IF(BM6-$E6=1,1,0) -> 0 | BZ6: =BY6+BZ5 -> 0 | CA6: =IF(BM6-$E6>=2,1,0) -> 0 | CB6: =CA6+CB5 -> 1 | CC6: =IF(BO6=0,1,0) -> 0 | CD6: =CC6+CD5 -> 0 | CE6: =IF(BO6=1,1,0) -> 0 | CF6: =CE6+CF5 -> 1 | CG6: =IF(BO6=2,1,0) -> 1 | CH6: =CG6+CH5 -> 2 | CI6: =IF(BO6>=3,1,0) -> 0 | CJ6: =CI6+CJ5 -> 1 | CK6: =IF($E6=3,BM6-3,NA()) -> 0 | CN6: =BM6-'Zusammenfassung Tag1-4'!$D$2/18 -> 1.6666667 | CO6: =CN6+CO5 -> 13.666667 | CP6: 4 | CQ6: =CP6+CQ5 -> 19 | CR6: 2 | CS6: =CR6+CS5 -> 8 | CT6: =IF(CP6-CR6<=$E6-2,1,0) -> 0 | CU6: =CT6+CU5 -> 2 | CV6: =IF(CT6=0,IF(CP6=$E6,1,0),0) -> 0 | CW6: =CV6+CW5 -> 0 | CX6: =IF($E6-CP6=1,1,0) -> 0 | CY6: =CX6+CY5 -> 0 | CZ6: =IF(CP6=$E6,1,0) -> 0 | DA6: =CZ6+DA5 -> 2 | DB6: =IF(CP6-$E6=1,1,0) -> 1 | DC6: =DB6+DC5 -> 1 | DD6: =IF(CP6-$E6>=2,1,0) -> 0 | DE6: =DD6+DE5 -> 1 | DF6: =IF(CR6=0,1,0) -> 0 | DG6: =DF6+DG5 -> 0 | DH6: =IF(CR6=1,1,0) -> 0 | DI6: =DH6+DI5 -> 0 | DJ6: =IF(CR6=2,1,0) -> 1 | DK6: =DJ6+DK5 -> 4 | DL6: =IF(CR6>=3,1,0) -> 0 | DM6: =DL6+DM5 -> 0 | DN6: =IF($E6=3,CP6-3,NA()) -> 1 | DQ6: =CP6-'Zusammenfassung Tag1-4'!$E$2/18 -> 2.7222222 | DR6: =DQ6+DR5 -> 13.888889 | DS6: 3 | DT6: =DS6+DT5 -> 28 | DU6: 2 | DV6: =DU6+DV5 -> 8 | DW6: =IF(DS6-DU6<=$E6-2,1,0) -> 1 | DX6: =DW6+DX5 -> 1 | DY6: =IF(DW6=0,IF(DS6=$E6,1,0),0) -> 0 | DZ6: =DY6+DZ5 -> 0 | EA6: =IF($E6-DS6=1,1,0) -> 0 | EB6: =EA6+EB5 -> 0 | EC6: =IF(DS6=$E6,1,0) -> 1 | ED6: =EC6+ED5 -> 1 | EE6: =IF(DS6-$E6=1,1,0) -> 0 | EF6: =EE6+EF5 -> 0 | EG6: =IF(DS6-$E6>=2,1,0) -> 0 | EH6: =EG6+EH5 -> 3 | EI6: =IF(DU6=0,1,0) -> 0 | EJ6: =EI6+EJ5 -> 0 | EK6: =IF(DU6=1,1,0) -> 0 | EL6: =EK6+EL5 -> 0 | EM6: =IF(DU6=2,1,0) -> 1 | EN6: =EM6+EN5 -> 4 | EO6: =IF(DU6>=3,1,0) -> 0 | EP6: =EO6+EP5 -> 0 | EQ6: =IF($E6=3,DS6-3,NA()) -> 0 | ET6: =DS6-'Zusammenfassung Tag1-4'!$F$2/18 -> 0 | EU6: =ET6+EU5 -> 16 | EV6: 5 | EW6: =EV6+EW5 -> 22 | EX6: 3 | EY6: =EX6+EY5 -> 10 | EZ6: =IF(EV6-EX6<=$E6-2,1,0) -> 0 | FA6: =EZ6+FA5 -> 2 | FB6: =IF(EZ6=0,IF(EV6=$E6,1,0),0) -> 0 | FC6: =FB6+FC5 -> 0 | FD6: =IF($E6-EV6=1,1,0) -> 0 | FE6: =FD6+FE5 -> 0 | FF6: =IF(EV6=$E6,1,0) -> 0 | FG6: =FF6+FG5 -> 1 | FH6: =IF(EV6-$E6=1,1,0) -> 0 | FI6: =FH6+FI5 -> 1 | FJ6: =IF(EV6-$E6>=2,1,0) -> 1 | FK6: =FJ6+FK5 -> 2 | FL6: =IF(EX6=0,1,0) -> 0 | FM6: =FL6+FM5 -> 0 | FN6: =IF(EX6=1,1,0) -> 0 | FO6: =FN6+FO5 -> 0 | FP6: =IF(EX6=2,1,0) -> 0 | FQ6: =FP6+FQ5 -> 2 | FR6: =IF(EX6>=3,1,0) -> 1 | FS6: =FR6+FS5 -> 2 | FT6: =IF($E6=3,EV6-3,NA()) -> 2 | FW6: =EV6-'Zusammenfassung Tag1-4'!$G$2/18 -> 3.5 | FX6: =FW6+FX5 -> 16 | FY6: 7 | FZ6: =FY6+FZ5 -> 30 | GA6: 2 | GB6: =GA6+GB5 -> 10 | GC6: =IF(FY6-GA6<=$E6-2,1,0) -> 0 | GD6: =GC6+GD5 -> 1 | GE6: =IF(GC6=0,IF(FY6=$E6,1,0),0) -> 0 | GF6: =GE6+GF5 -> 0 | GG6: =IF($E6-FY6=1,1,0) -> 0 | GH6: =GG6+GH5 -> 0 | GI6: =IF(FY6=$E6,1,0) -> 0 | GJ6: =GI6+GJ5 -> 0 | GK6: =IF(FY6-$E6=1,1,0) -> 0 | GL6: =GK6+GL5 -> 1 | GM6: =IF(FY6-$E6>=2,1,0) -> 1 | GN6: =GM6+GN5 -> 3 | GO6: =IF(GA6=0,1,0) -> 0 | GP6: =GO6+GP5 -> 0 | GQ6: =IF(GA6=1,1,0) -> 0 | GR6: =GQ6+GR5 -> 0 | GS6: =IF(GA6=2,1,0) -> 1 | GT6: =GS6+GT5 -> 2 | GU6: =IF(GA6>=3,1,0) -> 0 | GV6: =GU6+GV5 -> 2 | GW6: =IF($E6=3,FY6-3,NA()) -> 4 | GZ6: =FY6-'Zusammenfassung Tag1-4'!$H$2/18 -> 4 | HA6: =GZ6+HA5 -> 18 | HB6: 4 | HC6: =HB6+HC5 -> 18 | HD6: 2 | HE6: =HD6+HE5 -> 8 | HF6: =IF(HB6-HD6<=$E6-2,1,0) -> 0 | HG6: =HF6+HG5 -> 2 | HH6: =IF(HF6=0,IF(HB6=$E6,1,0),0) -> 0 | HI6: =HH6+HI5 -> 1 | HJ6: =IF($E6-HB6=1,1,0) -> 0 | HK6: =HJ6+HK5 -> 0 | HL6: =IF(HB6=$E6,1,0) -> 0 | HM6: =HL6+HM5 -> 2 | HN6: =IF(HB6-$E6=1,1,0) -> 1 | HO6: =HN6+HO5 -> 2 | HP6: =IF(HB6-$E6>=2,1,0) -> 0 | HQ6: =HP6+HQ5 -> 0 | HR6: =IF(HD6=0,1,0) -> 0 | HS6: =HR6+HS5 -> 0 | HT6: =IF(HD6=1,1,0) -> 0 | HU6: =HT6+HU5 -> 1 | HV6: =IF(HD6=2,1,0) -> 1 | HW6: =HV6+HW5 -> 2 | HX6: =IF(HD6>=3,1,0) -> 0 | HY6: =HX6+HY5 -> 1 | HZ6: =IF($E6=3,HB6-3,NA()) -> 1 | IC6: =HB6-'Zusammenfassung Tag1-4'!$I$2/18 -> 3 | ID6: =IC6+ID5 -> 14 | IF6: =IE6+IF5 -> 0 | IH6: =IG6+IH5 -> 0 | II6: =IF(IE6-IG6<=$E6-2,1,0) -> 1 | IJ6: =II6+IJ5 -> 4 | IK6: =IF(II6=0,IF(IE6=$E6,1,0),0) -> 0 | IL6: =IK6+IL5 -> 0 | IM6: =IF($E6-IE6=1,1,0) -> 0 | IN6: =IM6+IN5 -> 0 | IO6: =IF(IE6=$E6,1,0) -> 0 | IP6: =IO6+IP5 -> 0 | IQ6: =IF(IE6-$E6=1,1,0) -> 0 | IR6: =IQ6+IR5 -> 0 | IS6: =IF(IE6-$E6>=2,1,0) -> 0 | IT6: =IS6+IT5 -> 0 | IU6: =IF(IG6=0,1,0) -> 1 | IV6: =IU6+IV5 -> 4 | IW6: =IF(IG6=1,1,0) -> 0 | IX6: =IW6+IX5 -> 0 | IY6: =IF(IG6=2,1,0) -> 0 | IZ6: =IY6+IZ5 -> 0 | JA6: =IF(IG6>=3,1,0) -> 0 | JB6: =JA6+JB5 -> 0 | JC6: =IF($E6=3,IE6-3,NA()) -> -3 | JF6: =IE6-'Zusammenfassung Tag1-4'!$J$2/18 -> -3 | JG6: =JF6+JG5 -> -12 | JI6: =JH6+JI5 -> 0 | JK6: =JJ6+JK5 -> 0 | JL6: =IF(JH6-JJ6<=$E6-2,1,0) -> 1 | JM6: =JL6+JM5 -> 4 | JN6: =IF(JL6=0,IF(JH6=$E6,1,0),0) -> 0 | JO6: =JN6+JO5 -> 0 | JP6: =IF($E6-JH6=1,1,0) -> 0 | JQ6: =JP6+JQ5 -> 0 | JR6: =IF(JH6=$E6,1,0) -> 0 | JS6: =JR6+JS5 -> 0 | JT6: =IF(JH6-$E6=1,1,0) -> 0 | JU6: =JT6+JU5 -> 0 | JV6: =IF(JH6-$E6>=2,1,0) -> 0 | JW6: =JV6+JW5 -> 0 | JX6: =IF(JJ6=0,1,0) -> 1 | JY6: =JX6+JY5 -> 4 | JZ6: =IF(JJ6=1,1,0) -> 0 | KA6: =JZ6+KA5 -> 0 | KB6: =IF(JJ6=2,1,0) -> 0 | KC6: =KB6+KC5 -> 0 | KD6: =IF(JJ6>=3,1,0) -> 0 | KE6: =KD6+KE5 -> 0 | KF6: =IF($E6=3,JH6-3,NA()) -> -3 | KI6: =JH6-'Zusammenfassung Tag1-4'!$K$2/18 -> -0.77777778 | KJ6: =KI6+KJ5 -> -3.1111111
C7: 5 | D7: =D6+1 -> 5 | E7: 4 | F7: =E7+F6 -> 20 | G7: 5 | H7: =G7+H6 -> 25 | I7: 2 | J7: =I7+J6 -> 12 | K7: =IF(G7-I7<=$E7-2,1,0) -> 0 | L7: =K7+L6 -> 3 | M7: =IF(K7=0,IF(G7=$E7,1,0),0) -> 0 | N7: =M7+N6 -> 0 | O7: =IF($E7-G7=1,1,0) -> 0 | P7: =O7+P6 -> 0 | Q7: =IF(G7=$E7,1,0) -> 0 | R7: =Q7+R6 -> 2 | S7: =IF(G7-$E7=1,1,0) -> 1 | T7: =S7+T6 -> 1 | U7: =IF(G7-$E7>=2,1,0) -> 0 | V7: =U7+V6 -> 2 | W7: =IF(I7=0,1,0) -> 0 | X7: =W7+X6 -> 0 | Y7: =IF(I7=1,1,0) -> 0 | Z7: =Y7+Z6 -> 0 | AA7: =IF(I7=2,1,0) -> 1 | AB7: =AA7+AB6 -> 4 | AC7: =IF(I7>=3,1,0) -> 0 | AD7: =AC7+AD6 -> 1 | AF7: =IF($E7=4,G7-4,NA()) -> 1 | AH7: =G7-'Zusammenfassung Tag1-4'!$B$2/18 -> 3.8888889 | AI7: =AH7+AI6 -> 19.444444 | AJ7: 4 | AK7: =AJ7+AK6 -> 21 | AL7: 1 | AM7: =AL7+AM6 -> 10 | AN7: =IF(AJ7-AL7<=$E7-2,1,0) -> 0 | AO7: =AN7+AO6 -> 4 | AP7: =IF(AN7=0,IF(AJ7=$E7,1,0),0) -> 1 | AQ7: =AP7+AQ6 -> 1 | AR7: =IF($E7-AJ7=1,1,0) -> 0 | AS7: =AR7+AS6 -> 0 | AT7: =IF(AJ7=$E7,1,0) -> 1 | AU7: =AT7+AU6 -> 4 | AV7: =IF(AJ7-$E7=1,1,0) -> 0 | AW7: =AV7+AW6 -> 1 | AX7: =IF(AJ7-$E7>=2,1,0) -> 0 | AY7: =AX7+AY6 -> 0 | AZ7: =IF(AL7=0,1,0) -> 0 | BA7: =AZ7+BA6 -> 0 | BB7: =IF(AL7=1,1,0) -> 1 | BC7: =BB7+BC6 -> 1 | BD7: =IF(AL7=2,1,0) -> 0 | BE7: =BD7+BE6 -> 3 | BF7: =IF(AL7>=3,1,0) -> 0 | BG7: =BF7+BG6 -> 1 | BI7: =IF($E7=4,AJ7-4,NA()) -> 0 | BK7: =AJ7-'Zusammenfassung Tag1-4'!$C$2/18 -> 3.3333333 | BL7: =BK7+BL6 -> 17.666667 | BM7: 4 | BN7: =BM7+BN6 -> 23 | BO7: 2 | BP7: =BO7+BP6 -> 10 | BQ7: =IF(BM7-BO7<=$E7-2,1,0) -> 1 | BR7: =BQ7+BR6 -> 3 | BS7: =IF(BQ7=0,IF(BM7=$E7,1,0),0) -> 0 | BT7: =BS7+BT6 -> 1 | BU7: =IF($E7-BM7=1,1,0) -> 0 | BV7: =BU7+BV6 -> 0 | BW7: =IF(BM7=$E7,1,0) -> 1 | BX7: =BW7+BX6 -> 4 | BY7: =IF(BM7-$E7=1,1,0) -> 0 | BZ7: =BY7+BZ6 -> 0 | CA7: =IF(BM7-$E7>=2,1,0) -> 0 | CB7: =CA7+CB6 -> 1 | CC7: =IF(BO7=0,1,0) -> 0 | CD7: =CC7+CD6 -> 0 | CE7: =IF(BO7=1,1,0) -> 0 | CF7: =CE7+CF6 -> 1 | CG7: =IF(BO7=2,1,0) -> 1 | CH7: =CG7+CH6 -> 3 | CI7: =IF(BO7>=3,1,0) -> 0 | CJ7: =CI7+CJ6 -> 1 | CL7: =IF($E7=4,BM7-4,NA()) -> 0 | CN7: =BM7-'Zusammenfassung Tag1-4'!$D$2/18 -> 2.6666667 | CO7: =CN7+CO6 -> 16.333333 | CP7: 5 | CQ7: =CP7+CQ6 -> 24 | CR7: 2 | CS7: =CR7+CS6 -> 10 | CT7: =IF(CP7-CR7<=$E7-2,1,0) -> 0 | CU7: =CT7+CU6 -> 2 | CV7: =IF(CT7=0,IF(CP7=$E7,1,0),0) -> 0 | CW7: =CV7+CW6 -> 0 | CX7: =IF($E7-CP7=1,1,0) -> 0 | CY7: =CX7+CY6 -> 0 | CZ7: =IF(CP7=$E7,1,0) -> 0 | DA7: =CZ7+DA6 -> 2 | DB7: =IF(CP7-$E7=1,1,0) -> 1 | DC7: =DB7+DC6 -> 2 | DD7: =IF(CP7-$E7>=2,1,0) -> 0 | DE7: =DD7+DE6 -> 1 | DF7: =IF(CR7=0,1,0) -> 0 | DG7: =DF7+DG6 -> 0 | DH7: =IF(CR7=1,1,0) -> 0 | DI7: =DH7+DI6 -> 0 | DJ7: =IF(CR7=2,1,0) -> 1 | DK7: =DJ7+DK6 -> 5 | DL7: =IF(CR7>=3,1,0) -> 0 | DM7: =DL7+DM6 -> 0 | DO7: =IF($E7=4,CP7-4,NA()) -> 1 | DQ7: =CP7-'Zusammenfassung Tag1-4'!$E$2/18 -> 3.7222222 | DR7: =DQ7+DR6 -> 17.611111 | DS7: 7 | DT7: =DS7+DT6 -> 35 | DU7: 3 | DV7: =DU7+DV6 -> 11 | DW7: =IF(DS7-DU7<=$E7-2,1,0) -> 0 | DX7: =DW7+DX6 -> 1 | DY7: =IF(DW7=0,IF(DS7=$E7,1,0),0) -> 0 | DZ7: =DY7+DZ6 -> 0 | EA7: =IF($E7-DS7=1,1,0) -> 0 | EB7: =EA7+EB6 -> 0 | EC7: =IF(DS7=$E7,1,0) -> 0 | ED7: =EC7+ED6 -> 1 | EE7: =IF(DS7-$E7=1,1,0) -> 0 | EF7: =EE7+EF6 -> 0 | EG7: =IF(DS7-$E7>=2,1,0) -> 1 | EH7: =EG7+EH6 -> 4 | EI7: =IF(DU7=0,1,0) -> 0 | EJ7: =EI7+EJ6 -> 0 | EK7: =IF(DU7=1,1,0) -> 0 | EL7: =EK7+EL6 -> 0 | EM7: =IF(DU7=2,1,0) -> 0 | EN7: =EM7+EN6 -> 4 | EO7: =IF(DU7>=3,1,0) -> 1 | EP7: =EO7+EP6 -> 1 | ER7: =IF($E7=4,DS7-4,NA()) -> 3 | ET7: =DS7-'Zusammenfassung Tag1-4'!$F$2/18 -> 4 | EU7: =ET7+EU6 -> 20 | EV7: 6 | EW7: =EV7+EW6 -> 28 | EX7: 3 | EY7: =EX7+EY6 -> 13 | EZ7: =IF(EV7-EX7<=$E7-2,1,0) -> 0 | FA7: =EZ7+FA6 -> 2 | FB7: =IF(EZ7=0,IF(EV7=$E7,1,0),0) -> 0 | FC7: =FB7+FC6 -> 0 | FD7: =IF($E7-EV7=1,1,0) -> 0 | FE7: =FD7+FE6 -> 0 | FF7: =IF(EV7=$E7,1,0) -> 0 | FG7: =FF7+FG6 -> 1 | FH7: =IF(EV7-$E7=1,1,0) -> 0 | FI7: =FH7+FI6 -> 1 | FJ7: =IF(EV7-$E7>=2,1,0) -> 1 | FK7: =FJ7+FK6 -> 3 | FL7: =IF(EX7=0,1,0) -> 0 | FM7: =FL7+FM6 -> 0 | FN7: =IF(EX7=1,1,0) -> 0 | FO7: =FN7+FO6 -> 0 | FP7: =IF(EX7=2,1,0) -> 0 | FQ7: =FP7+FQ6 -> 2 | FR7: =IF(EX7>=3,1,0) -> 1 | FS7: =FR7+FS6 -> 3 | FU7: =IF($E7=4,EV7-4,NA()) -> 2 | FW7: =EV7-'Zusammenfassung Tag1-4'!$G$2/18 -> 4.5 | FX7: =FW7+FX6 -> 20.5 | FY7: 8 | FZ7: =FY7+FZ6 -> 38 | GA7: 3 | GB7: =GA7+GB6 -> 13 | GC7: =IF(FY7-GA7<=$E7-2,1,0) -> 0 | GD7: =GC7+GD6 -> 1 | GE7: =IF(GC7=0,IF(FY7=$E7,1,0),0) -> 0 | GF7: =GE7+GF6 -> 0 | GG7: =IF($E7-FY7=1,1,0) -> 0 | GH7: =GG7+GH6 -> 0 | GI7: =IF(FY7=$E7,1,0) -> 0 | GJ7: =GI7+GJ6 -> 0 | GK7: =IF(FY7-$E7=1,1,0) -> 0 | GL7: =GK7+GL6 -> 1 | GM7: =IF(FY7-$E7>=2,1,0) -> 1 | GN7: =GM7+GN6 -> 4 | GO7: =IF(GA7=0,1,0) -> 0 | GP7: =GO7+GP6 -> 0 | GQ7: =IF(GA7=1,1,0) -> 0 | GR7: =GQ7+GR6 -> 0 | GS7: =IF(GA7=2,1,0) -> 0 | GT7: =GS7+GT6 -> 2 | GU7: =IF(GA7>=3,1,0) -> 1 | GV7: =GU7+GV6 -> 3 | GX7: =IF($E7=4,FY7-4,NA()) -> 4 | GZ7: =FY7-'Zusammenfassung Tag1-4'!$H$2/18 -> 5 | HA7: =GZ7+HA6 -> 23 | HB7: 7 | HC7: =HB7+HC6 -> 25 | HD7: 2 | HE7: =HD7+HE6 -> 10 | HF7: =IF(HB7-HD7<=$E7-2,1,0) -> 0 | HG7: =HF7+HG6 -> 2 | HH7: =IF(HF7=0,IF(HB7=$E7,1,0),0) -> 0 | HI7: =HH7+HI6 -> 1 | HJ7: =IF($E7-HB7=1,1,0) -> 0 | HK7: =HJ7+HK6 -> 0 | HL7: =IF(HB7=$E7,1,0) -> 0 | HM7: =HL7+HM6 -> 2 | HN7: =IF(HB7-$E7=1,1,0) -> 0 | HO7: =HN7+HO6 -> 2 | HP7: =IF(HB7-$E7>=2,1,0) -> 1 | HQ7: =HP7+HQ6 -> 1 | HR7: =IF(HD7=0,1,0) -> 0 | HS7: =HR7+HS6 -> 0 | HT7: =IF(HD7=1,1,0) -> 0 | HU7: =HT7+HU6 -> 1 | HV7: =IF(HD7=2,1,0) -> 1 | HW7: =HV7+HW6 -> 3 | HX7: =IF(HD7>=3,1,0) -> 0 | HY7: =HX7+HY6 -> 1 | IA7: =IF($E7=4,HB7-4,NA()) -> 3 | IC7: =HB7-'Zusammenfassung Tag1-4'!$I$2/18 -> 6 | ID7: =IC7+ID6 -> 20 | IF7: =IE7+IF6 -> 0 | IH7: =IG7+IH6 -> 0 | II7: =IF(IE7-IG7<=$E7-2,1,0) -> 1 | IJ7: =II7+IJ6 -> 5 | IK7: =IF(II7=0,IF(IE7=$E7,1,0),0) -> 0 | IL7: =IK7+IL6 -> 0 | IM7: =IF($E7-IE7=1,1,0) -> 0 | IN7: =IM7+IN6 -> 0 | IO7: =IF(IE7=$E7,1,0) -> 0 | IP7: =IO7+IP6 -> 0 | IQ7: =IF(IE7-$E7=1,1,0) -> 0 | IR7: =IQ7+IR6 -> 0 | IS7: =IF(IE7-$E7>=2,1,0) -> 0 | IT7: =IS7+IT6 -> 0 | IU7: =IF(IG7=0,1,0) -> 1 | IV7: =IU7+IV6 -> 5 | IW7: =IF(IG7=1,1,0) -> 0 | IX7: =IW7+IX6 -> 0 | IY7: =IF(IG7=2,1,0) -> 0 | IZ7: =IY7+IZ6 -> 0 | JA7: =IF(IG7>=3,1,0) -> 0 | JB7: =JA7+JB6 -> 0 | JD7: =IF($E7=4,IE7-4,NA()) -> -4 | JF7: =IE7-'Zusammenfassung Tag1-4'!$J$2/18 -> -3 | JG7: =JF7+JG6 -> -15 | JI7: =JH7+JI6 -> 0 | JK7: =JJ7+JK6 -> 0 | JL7: =IF(JH7-JJ7<=$E7-2,1,0) -> 1 | JM7: =JL7+JM6 -> 5 | JN7: =IF(JL7=0,IF(JH7=$E7,1,0),0) -> 0 | JO7: =JN7+JO6 -> 0 | JP7: =IF($E7-JH7=1,1,0) -> 0 | JQ7: =JP7+JQ6 -> 0 | JR7: =IF(JH7=$E7,1,0) -> 0 | JS7: =JR7+JS6 -> 0 | JT7: =IF(JH7-$E7=1,1,0) -> 0 | JU7: =JT7+JU6 -> 0 | JV7: =IF(JH7-$E7>=2,1,0) -> 0 | JW7: =JV7+JW6 -> 0 | JX7: =IF(JJ7=0,1,0) -> 1 | JY7: =JX7+JY6 -> 5 | JZ7: =IF(JJ7=1,1,0) -> 0 | KA7: =JZ7+KA6 -> 0 | KB7: =IF(JJ7=2,1,0) -> 0 | KC7: =KB7+KC6 -> 0 | KD7: =IF(JJ7>=3,1,0) -> 0 | KE7: =KD7+KE6 -> 0 | KG7: =IF($E7=4,JH7-4,NA()) -> -4 | KI7: =JH7-'Zusammenfassung Tag1-4'!$K$2/18 -> -0.77777778 | KJ7: =KI7+KJ6 -> -3.8888889
C8: 6 | D8: =D7+1 -> 6 | E8: 4 | F8: =E8+F7 -> 24 | G8: 5 | H8: =G8+H7 -> 30 | I8: 1 | J8: =I8+J7 -> 13 | K8: =IF(G8-I8<=$E8-2,1,0) -> 0 | L8: =K8+L7 -> 3 | M8: =IF(K8=0,IF(G8=$E8,1,0),0) -> 0 | N8: =M8+N7 -> 0 | O8: =IF($E8-G8=1,1,0) -> 0 | P8: =O8+P7 -> 0 | Q8: =IF(G8=$E8,1,0) -> 0 | R8: =Q8+R7 -> 2 | S8: =IF(G8-$E8=1,1,0) -> 1 | T8: =S8+T7 -> 2 | U8: =IF(G8-$E8>=2,1,0) -> 0 | V8: =U8+V7 -> 2 | W8: =IF(I8=0,1,0) -> 0 | X8: =W8+X7 -> 0 | Y8: =IF(I8=1,1,0) -> 1 | Z8: =Y8+Z7 -> 1 | AA8: =IF(I8=2,1,0) -> 0 | AB8: =AA8+AB7 -> 4 | AC8: =IF(I8>=3,1,0) -> 0 | AD8: =AC8+AD7 -> 1 | AF8: =IF($E8=4,G8-4,NA()) -> 1 | AH8: =G8-'Zusammenfassung Tag1-4'!$B$2/18 -> 3.8888889 | AI8: =AH8+AI7 -> 23.333333 | AJ8: 5 | AK8: =AJ8+AK7 -> 26 | AL8: 3 | AM8: =AL8+AM7 -> 13 | AN8: =IF(AJ8-AL8<=$E8-2,1,0) -> 1 | AO8: =AN8+AO7 -> 5 | AP8: =IF(AN8=0,IF(AJ8=$E8,1,0),0) -> 0 | AQ8: =AP8+AQ7 -> 1 | AR8: =IF($E8-AJ8=1,1,0) -> 0 | AS8: =AR8+AS7 -> 0 | AT8: =IF(AJ8=$E8,1,0) -> 0 | AU8: =AT8+AU7 -> 4 | AV8: =IF(AJ8-$E8=1,1,0) -> 1 | AW8: =AV8+AW7 -> 2 | AX8: =IF(AJ8-$E8>=2,1,0) -> 0 | AY8: =AX8+AY7 -> 0 | AZ8: =IF(AL8=0,1,0) -> 0 | BA8: =AZ8+BA7 -> 0 | BB8: =IF(AL8=1,1,0) -> 0 | BC8: =BB8+BC7 -> 1 | BD8: =IF(AL8=2,1,0) -> 0 | BE8: =BD8+BE7 -> 3 | BF8: =IF(AL8>=3,1,0) -> 1 | BG8: =BF8+BG7 -> 2 | BI8: =IF($E8=4,AJ8-4,NA()) -> 1 | BK8: =AJ8-'Zusammenfassung Tag1-4'!$C$2/18 -> 4.3333333 | BL8: =BK8+BL7 -> 22 | BM8: 8 | BN8: =BM8+BN7 -> 31 | BO8: 2 | BP8: =BO8+BP7 -> 12 | BQ8: =IF(BM8-BO8<=$E8-2,1,0) -> 0 | BR8: =BQ8+BR7 -> 3 | BS8: =IF(BQ8=0,IF(BM8=$E8,1,0),0) -> 0 | BT8: =BS8+BT7 -> 1 | BU8: =IF($E8-BM8=1,1,0) -> 0 | BV8: =BU8+BV7 -> 0 | BW8: =IF(BM8=$E8,1,0) -> 0 | BX8: =BW8+BX7 -> 4 | BY8: =IF(BM8-$E8=1,1,0) -> 0 | BZ8: =BY8+BZ7 -> 0 | CA8: =IF(BM8-$E8>=2,1,0) -> 1 | CB8: =CA8+CB7 -> 2 | CC8: =IF(BO8=0,1,0) -> 0 | CD8: =CC8+CD7 -> 0 | CE8: =IF(BO8=1,1,0) -> 0 | CF8: =CE8+CF7 -> 1 | CG8: =IF(BO8=2,1,0) -> 1 | CH8: =CG8+CH7 -> 4 | CI8: =IF(BO8>=3,1,0) -> 0 | CJ8: =CI8+CJ7 -> 1 | CL8: =IF($E8=4,BM8-4,NA()) -> 4 | CN8: =BM8-'Zusammenfassung Tag1-4'!$D$2/18 -> 6.6666667 | CO8: =CN8+CO7 -> 23 | CP8: 6 | CQ8: =CP8+CQ7 -> 30 | CR8: 2 | CS8: =CR8+CS7 -> 12 | CT8: =IF(CP8-CR8<=$E8-2,1,0) -> 0 | CU8: =CT8+CU7 -> 2 | CV8: =IF(CT8=0,IF(CP8=$E8,1,0),0) -> 0 | CW8: =CV8+CW7 -> 0 | CX8: =IF($E8-CP8=1,1,0) -> 0 | CY8: =CX8+CY7 -> 0 | CZ8: =IF(CP8=$E8,1,0) -> 0 | DA8: =CZ8+DA7 -> 2 | DB8: =IF(CP8-$E8=1,1,0) -> 0 | DC8: =DB8+DC7 -> 2 | DD8: =IF(CP8-$E8>=2,1,0) -> 1 | DE8: =DD8+DE7 -> 2 | DF8: =IF(CR8=0,1,0) -> 0 | DG8: =DF8+DG7 -> 0 | DH8: =IF(CR8=1,1,0) -> 0 | DI8: =DH8+DI7 -> 0 | DJ8: =IF(CR8=2,1,0) -> 1 | DK8: =DJ8+DK7 -> 6 | DL8: =IF(CR8>=3,1,0) -> 0 | DM8: =DL8+DM7 -> 0 | DO8: =IF($E8=4,CP8-4,NA()) -> 2 | DQ8: =CP8-'Zusammenfassung Tag1-4'!$E$2/18 -> 4.7222222 | DR8: =DQ8+DR7 -> 22.333333 | DS8: 8 | DT8: =DS8+DT7 -> 43 | DU8: 4 | DV8: =DU8+DV7 -> 15 | DW8: =IF(DS8-DU8<=$E8-2,1,0) -> 0 | DX8: =DW8+DX7 -> 1 | DY8: =IF(DW8=0,IF(DS8=$E8,1,0),0) -> 0 | DZ8: =DY8+DZ7 -> 0 | EA8: =IF($E8-DS8=1,1,0) -> 0 | EB8: =EA8+EB7 -> 0 | EC8: =IF(DS8=$E8,1,0) -> 0 | ED8: =EC8+ED7 -> 1 | EE8: =IF(DS8-$E8=1,1,0) -> 0 | EF8: =EE8+EF7 -> 0 | EG8: =IF(DS8-$E8>=2,1,0) -> 1 | EH8: =EG8+EH7 -> 5 | EI8: =IF(DU8=0,1,0) -> 0 | EJ8: =EI8+EJ7 -> 0 | EK8: =IF(DU8=1,1,0) -> 0 | EL8: =EK8+EL7 -> 0 | EM8: =IF(DU8=2,1,0) -> 0 | EN8: =EM8+EN7 -> 4 | EO8: =IF(DU8>=3,1,0) -> 1 | EP8: =EO8+EP7 -> 2 | ER8: =IF($E8=4,DS8-4,NA()) -> 4 | ET8: =DS8-'Zusammenfassung Tag1-4'!$F$2/18 -> 5 | EU8: =ET8+EU7 -> 25 | EV8: 6 | EW8: =EV8+EW7 -> 34 | EX8: 3 | EY8: =EX8+EY7 -> 16 | EZ8: =IF(EV8-EX8<=$E8-2,1,0) -> 0 | FA8: =EZ8+FA7 -> 2 | FB8: =IF(EZ8=0,IF(EV8=$E8,1,0),0) -> 0 | FC8: =FB8+FC7 -> 0 | FD8: =IF($E8-EV8=1,1,0) -> 0 | FE8: =FD8+FE7 -> 0 | FF8: =IF(EV8=$E8,1,0) -> 0 | FG8: =FF8+FG7 -> 1 | FH8: =IF(EV8-$E8=1,1,0) -> 0 | FI8: =FH8+FI7 -> 1 | FJ8: =IF(EV8-$E8>=2,1,0) -> 1 | FK8: =FJ8+FK7 -> 4 | FL8: =IF(EX8=0,1,0) -> 0 | FM8: =FL8+FM7 -> 0 | FN8: =IF(EX8=1,1,0) -> 0 | FO8: =FN8+FO7 -> 0 | FP8: =IF(EX8=2,1,0) -> 0 | FQ8: =FP8+FQ7 -> 2 | FR8: =IF(EX8>=3,1,0) -> 1 | FS8: =FR8+FS7 -> 4 | FU8: =IF($E8=4,EV8-4,NA()) -> 2 | FW8: =EV8-'Zusammenfassung Tag1-4'!$G$2/18 -> 4.5 | FX8: =FW8+FX7 -> 25 | FY8: 7 | FZ8: =FY8+FZ7 -> 45 | GA8: 2 | GB8: =GA8+GB7 -> 15 | GC8: =IF(FY8-GA8<=$E8-2,1,0) -> 0 | GD8: =GC8+GD7 -> 1 | GE8: =IF(GC8=0,IF(FY8=$E8,1,0),0) -> 0 | GF8: =GE8+GF7 -> 0 | GG8: =IF($E8-FY8=1,1,0) -> 0 | GH8: =GG8+GH7 -> 0 | GI8: =IF(FY8=$E8,1,0) -> 0 | GJ8: =GI8+GJ7 -> 0 | GK8: =IF(FY8-$E8=1,1,0) -> 0 | GL8: =GK8+GL7 -> 1 | GM8: =IF(FY8-$E8>=2,1,0) -> 1 | GN8: =GM8+GN7 -> 5 | GO8: =IF(GA8=0,1,0) -> 0 | GP8: =GO8+GP7 -> 0 | GQ8: =IF(GA8=1,1,0) -> 0 | GR8: =GQ8+GR7 -> 0 | GS8: =IF(GA8=2,1,0) -> 1 | GT8: =GS8+GT7 -> 3 | GU8: =IF(GA8>=3,1,0) -> 0 | GV8: =GU8+GV7 -> 3 | GX8: =IF($E8=4,FY8-4,NA()) -> 3 | GZ8: =FY8-'Zusammenfassung Tag1-4'!$H$2/18 -> 4 | HA8: =GZ8+HA7 -> 27 | HB8: 5 | HC8: =HB8+HC7 -> 30 | HD8: 2 | HE8: =HD8+HE7 -> 12 | HF8: =IF(HB8-HD8<=$E8-2,1,0) -> 0 | HG8: =HF8+HG7 -> 2 | HH8: =IF(HF8=0,IF(HB8=$E8,1,0),0) -> 0 | HI8: =HH8+HI7 -> 1 | HJ8: =IF($E8-HB8=1,1,0) -> 0 | HK8: =HJ8+HK7 -> 0 | HL8: =IF(HB8=$E8,1,0) -> 0 | HM8: =HL8+HM7 -> 2 | HN8: =IF(HB8-$E8=1,1,0) -> 1 | HO8: =HN8+HO7 -> 3 | HP8: =IF(HB8-$E8>=2,1,0) -> 0 | HQ8: =HP8+HQ7 -> 1 | HR8: =IF(HD8=0,1,0) -> 0 | HS8: =HR8+HS7 -> 0 | HT8: =IF(HD8=1,1,0) -> 0 | HU8: =HT8+HU7 -> 1 | HV8: =IF(HD8=2,1,0) -> 1 | HW8: =HV8+HW7 -> 4 | HX8: =IF(HD8>=3,1,0) -> 0 | HY8: =HX8+HY7 -> 1 | IA8: =IF($E8=4,HB8-4,NA()) -> 1 | IC8: =HB8-'Zusammenfassung Tag1-4'!$I$2/18 -> 4 | ID8: =IC8+ID7 -> 24 | IF8: =IE8+IF7 -> 0 | IH8: =IG8+IH7 -> 0 | II8: =IF(IE8-IG8<=$E8-2,1,0) -> 1 | IJ8: =II8+IJ7 -> 6 | IK8: =IF(II8=0,IF(IE8=$E8,1,0),0) -> 0 | IL8: =IK8+IL7 -> 0 | IM8: =IF($E8-IE8=1,1,0) -> 0 | IN8: =IM8+IN7 -> 0 | IO8: =IF(IE8=$E8,1,0) -> 0 | IP8: =IO8+IP7 -> 0 | IQ8: =IF(IE8-$E8=1,1,0) -> 0 | IR8: =IQ8+IR7 -> 0 | IS8: =IF(IE8-$E8>=2,1,0) -> 0 | IT8: =IS8+IT7 -> 0 | IU8: =IF(IG8=0,1,0) -> 1 | IV8: =IU8+IV7 -> 6 | IW8: =IF(IG8=1,1,0) -> 0 | IX8: =IW8+IX7 -> 0 | IY8: =IF(IG8=2,1,0) -> 0 | IZ8: =IY8+IZ7 -> 0 | JA8: =IF(IG8>=3,1,0) -> 0 | JB8: =JA8+JB7 -> 0 | JD8: =IF($E8=4,IE8-4,NA()) -> -4 | JF8: =IE8-'Zusammenfassung Tag1-4'!$J$2/18 -> -3 | JG8: =JF8+JG7 -> -18 | JI8: =JH8+JI7 -> 0 | JK8: =JJ8+JK7 -> 0 | JL8: =IF(JH8-JJ8<=$E8-2,1,0) -> 1 | JM8: =JL8+JM7 -> 6 | JN8: =IF(JL8=0,IF(JH8=$E8,1,0),0) -> 0 | JO8: =JN8+JO7 -> 0 | JP8: =IF($E8-JH8=1,1,0) -> 0 | JQ8: =JP8+JQ7 -> 0 | JR8: =IF(JH8=$E8,1,0) -> 0 | JS8: =JR8+JS7 -> 0 | JT8: =IF(JH8-$E8=1,1,0) -> 0 | JU8: =JT8+JU7 -> 0 | JV8: =IF(JH8-$E8>=2,1,0) -> 0 | JW8: =JV8+JW7 -> 0 | JX8: =IF(JJ8=0,1,0) -> 1 | JY8: =JX8+JY7 -> 6 | JZ8: =IF(JJ8=1,1,0) -> 0 | KA8: =JZ8+KA7 -> 0 | KB8: =IF(JJ8=2,1,0) -> 0 | KC8: =KB8+KC7 -> 0 | KD8: =IF(JJ8>=3,1,0) -> 0 | KE8: =KD8+KE7 -> 0 | KG8: =IF($E8=4,JH8-4,NA()) -> -4 | KI8: =JH8-'Zusammenfassung Tag1-4'!$K$2/18 -> -0.77777778 | KJ8: =KI8+KJ7 -> -4.6666667
C9: 7 | D9: =D8+1 -> 7 | E9: 5 | F9: =E9+F8 -> 29 | G9: 7 | H9: =G9+H8 -> 37 | I9: 3 | J9: =I9+J8 -> 16 | K9: =IF(G9-I9<=$E9-2,1,0) -> 0 | L9: =K9+L8 -> 3 | M9: =IF(K9=0,IF(G9=$E9,1,0),0) -> 0 | N9: =M9+N8 -> 0 | O9: =IF($E9-G9=1,1,0) -> 0 | P9: =O9+P8 -> 0 | Q9: =IF(G9=$E9,1,0) -> 0 | R9: =Q9+R8 -> 2 | S9: =IF(G9-$E9=1,1,0) -> 0 | T9: =S9+T8 -> 2 | U9: =IF(G9-$E9>=2,1,0) -> 1 | V9: =U9+V8 -> 3 | W9: =IF(I9=0,1,0) -> 0 | X9: =W9+X8 -> 0 | Y9: =IF(I9=1,1,0) -> 0 | Z9: =Y9+Z8 -> 1 | AA9: =IF(I9=2,1,0) -> 0 | AB9: =AA9+AB8 -> 4 | AC9: =IF(I9>=3,1,0) -> 1 | AD9: =AC9+AD8 -> 2 | AG9: =IF($E9=5,G9-5,NA()) -> 2 | AH9: =G9-'Zusammenfassung Tag1-4'!$B$2/18 -> 5.8888889 | AI9: =AH9+AI8 -> 29.222222 | AJ9: 5 | AK9: =AJ9+AK8 -> 31 | AL9: 2 | AM9: =AL9+AM8 -> 15 | AN9: =IF(AJ9-AL9<=$E9-2,1,0) -> 1 | AO9: =AN9+AO8 -> 6 | AP9: =IF(AN9=0,IF(AJ9=$E9,1,0),0) -> 0 | AQ9: =AP9+AQ8 -> 1 | AR9: =IF($E9-AJ9=1,1,0) -> 0 | AS9: =AR9+AS8 -> 0 | AT9: =IF(AJ9=$E9,1,0) -> 1 | AU9: =AT9+AU8 -> 5 | AV9: =IF(AJ9-$E9=1,1,0) -> 0 | AW9: =AV9+AW8 -> 2 | AX9: =IF(AJ9-$E9>=2,1,0) -> 0 | AY9: =AX9+AY8 -> 0 | AZ9: =IF(AL9=0,1,0) -> 0 | BA9: =AZ9+BA8 -> 0 | BB9: =IF(AL9=1,1,0) -> 0 | BC9: =BB9+BC8 -> 1 | BD9: =IF(AL9=2,1,0) -> 1 | BE9: =BD9+BE8 -> 4 | BF9: =IF(AL9>=3,1,0) -> 0 | BG9: =BF9+BG8 -> 2 | BJ9: =IF($E9=5,AJ9-5,NA()) -> 0 | BK9: =AJ9-'Zusammenfassung Tag1-4'!$C$2/18 -> 4.3333333 | BL9: =BK9+BL8 -> 26.333333 | BM9: 6 | BN9: =BM9+BN8 -> 37 | BO9: 1 | BP9: =BO9+BP8 -> 13 | BQ9: =IF(BM9-BO9<=$E9-2,1,0) -> 0 | BR9: =BQ9+BR8 -> 3 | BS9: =IF(BQ9=0,IF(BM9=$E9,1,0),0) -> 0 | BT9: =BS9+BT8 -> 1 | BU9: =IF($E9-BM9=1,1,0) -> 0 | BV9: =BU9+BV8 -> 0 | BW9: =IF(BM9=$E9,1,0) -> 0 | BX9: =BW9+BX8 -> 4 | BY9: =IF(BM9-$E9=1,1,0) -> 1 | BZ9: =BY9+BZ8 -> 1 | CA9: =IF(BM9-$E9>=2,1,0) -> 0 | CB9: =CA9+CB8 -> 2 | CC9: =IF(BO9=0,1,0) -> 0 | CD9: =CC9+CD8 -> 0 | CE9: =IF(BO9=1,1,0) -> 1 | CF9: =CE9+CF8 -> 2 | CG9: =IF(BO9=2,1,0) -> 0 | CH9: =CG9+CH8 -> 4 | CI9: =IF(BO9>=3,1,0) -> 0 | CJ9: =CI9+CJ8 -> 1 | CM9: =IF($E9=5,BM9-5,NA()) -> 1 | CN9: =BM9-'Zusammenfassung Tag1-4'!$D$2/18 -> 4.6666667 | CO9: =CN9+CO8 -> 27.666667 | CP9: 7 | CQ9: =CP9+CQ8 -> 37 | CR9: 1 | CS9: =CR9+CS8 -> 13 | CT9: =IF(CP9-CR9<=$E9-2,1,0) -> 0 | CU9: =CT9+CU8 -> 2 | CV9: =IF(CT9=0,IF(CP9=$E9,1,0),0) -> 0 | CW9: =CV9+CW8 -> 0 | CX9: =IF($E9-CP9=1,1,0) -> 0 | CY9: =CX9+CY8 -> 0 | CZ9: =IF(CP9=$E9,1,0) -> 0 | DA9: =CZ9+DA8 -> 2 | DB9: =IF(CP9-$E9=1,1,0) -> 0 | DC9: =DB9+DC8 -> 2 | DD9: =IF(CP9-$E9>=2,1,0) -> 1 | DE9: =DD9+DE8 -> 3 | DF9: =IF(CR9=0,1,0) -> 0 | DG9: =DF9+DG8 -> 0 | DH9: =IF(CR9=1,1,0) -> 1 | DI9: =DH9+DI8 -> 1 | DJ9: =IF(CR9=2,1,0) -> 0 | DK9: =DJ9+DK8 -> 6 | DL9: =IF(CR9>=3,1,0) -> 0 | DM9: =DL9+DM8 -> 0 | DP9: =IF($E9=5,CP9-5,NA()) -> 2 | DQ9: =CP9-'Zusammenfassung Tag1-4'!$E$2/18 -> 5.7222222 | DR9: =DQ9+DR8 -> 28.055556 | DS9: 10 | DT9: =DS9+DT8 -> 53 | DU9: 2 | DV9: =DU9+DV8 -> 17 | DW9: =IF(DS9-DU9<=$E9-2,1,0) -> 0 | DX9: =DW9+DX8 -> 1 | DY9: =IF(DW9=0,IF(DS9=$E9,1,0),0) -> 0 | DZ9: =DY9+DZ8 -> 0 | EA9: =IF($E9-DS9=1,1,0) -> 0 | EB9: =EA9+EB8 -> 0 | EC9: =IF(DS9=$E9,1,0) -> 0 | ED9: =EC9+ED8 -> 1 | EE9: =IF(DS9-$E9=1,1,0) -> 0 | EF9: =EE9+EF8 -> 0 | EG9: =IF(DS9-$E9>=2,1,0) -> 1 | EH9: =EG9+EH8 -> 6 | EI9: =IF(DU9=0,1,0) -> 0 | EJ9: =EI9+EJ8 -> 0 | EK9: =IF(DU9=1,1,0) -> 0 | EL9: =EK9+EL8 -> 0 | EM9: =IF(DU9=2,1,0) -> 1 | EN9: =EM9+EN8 -> 5 | EO9: =IF(DU9>=3,1,0) -> 0 | EP9: =EO9+EP8 -> 2 | ES9: =IF($E9=5,DS9-5,NA()) -> 5 | ET9: =DS9-'Zusammenfassung Tag1-4'!$F$2/18 -> 7 | EU9: =ET9+EU8 -> 32 | EV9: 7 | EW9: =EV9+EW8 -> 41 | EX9: 1 | EY9: =EX9+EY8 -> 17 | EZ9: =IF(EV9-EX9<=$E9-2,1,0) -> 0 | FA9: =EZ9+FA8 -> 2 | FB9: =IF(EZ9=0,IF(EV9=$E9,1,0),0) -> 0 | FC9: =FB9+FC8 -> 0 | FD9: =IF($E9-EV9=1,1,0) -> 0 | FE9: =FD9+FE8 -> 0 | FF9: =IF(EV9=$E9,1,0) -> 0 | FG9: =FF9+FG8 -> 1 | FH9: =IF(EV9-$E9=1,1,0) -> 0 | FI9: =FH9+FI8 -> 1 | FJ9: =IF(EV9-$E9>=2,1,0) -> 1 | FK9: =FJ9+FK8 -> 5 | FL9: =IF(EX9=0,1,0) -> 0 | FM9: =FL9+FM8 -> 0 | FN9: =IF(EX9=1,1,0) -> 1 | FO9: =FN9+FO8 -> 1 | FP9: =IF(EX9=2,1,0) -> 0 | FQ9: =FP9+FQ8 -> 2 | FR9: =IF(EX9>=3,1,0) -> 0 | FS9: =FR9+FS8 -> 4 | FV9: =IF($E9=5,EV9-5,NA()) -> 2 | FW9: =EV9-'Zusammenfassung Tag1-4'!$G$2/18 -> 5.5 | FX9: =FW9+FX8 -> 30.5 | FY9: 10 | FZ9: =FY9+FZ8 -> 55 | GA9: 2 | GB9: =GA9+GB8 -> 17 | GC9: =IF(FY9-GA9<=$E9-2,1,0) -> 0 | GD9: =GC9+GD8 -> 1 | GE9: =IF(GC9=0,IF(FY9=$E9,1,0),0) -> 0 | GF9: =GE9+GF8 -> 0 | GG9: =IF($E9-FY9=1,1,0) -> 0 | GH9: =GG9+GH8 -> 0 | GI9: =IF(FY9=$E9,1,0) -> 0 | GJ9: =GI9+GJ8 -> 0 | GK9: =IF(FY9-$E9=1,1,0) -> 0 | GL9: =GK9+GL8 -> 1 | GM9: =IF(FY9-$E9>=2,1,0) -> 1 | GN9: =GM9+GN8 -> 6 | GO9: =IF(GA9=0,1,0) -> 0 | GP9: =GO9+GP8 -> 0 | GQ9: =IF(GA9=1,1,0) -> 0 | GR9: =GQ9+GR8 -> 0 | GS9: =IF(GA9=2,1,0) -> 1 | GT9: =GS9+GT8 -> 4 | GU9: =IF(GA9>=3,1,0) -> 0 | GV9: =GU9+GV8 -> 3 | GY9: =IF($E9=5,FY9-5,NA()) -> 5 | GZ9: =FY9-'Zusammenfassung Tag1-4'!$H$2/18 -> 7 | HA9: =GZ9+HA8 -> 34 | HB9: 6 | HC9: =HB9+HC8 -> 36 | HD9: 2 | HE9: =HD9+HE8 -> 14 | HF9: =IF(HB9-HD9<=$E9-2,1,0) -> 0 | HG9: =HF9+HG8 -> 2 | HH9: =IF(HF9=0,IF(HB9=$E9,1,0),0) -> 0 | HI9: =HH9+HI8 -> 1 | HJ9: =IF($E9-HB9=1,1,0) -> 0 | HK9: =HJ9+HK8 -> 0 | HL9: =IF(HB9=$E9,1,0) -> 0 | HM9: =HL9+HM8 -> 2 | HN9: =IF(HB9-$E9=1,1,0) -> 1 | HO9: =HN9+HO8 -> 4 | HP9: =IF(HB9-$E9>=2,1,0) -> 0 | HQ9: =HP9+HQ8 -> 1 | HR9: =IF(HD9=0,1,0) -> 0 | HS9: =HR9+HS8 -> 0 | HT9: =IF(HD9=1,1,0) -> 0 | HU9: =HT9+HU8 -> 1 | HV9: =IF(HD9=2,1,0) -> 1 | HW9: =HV9+HW8 -> 5 | HX9: =IF(HD9>=3,1,0) -> 0 | HY9: =HX9+HY8 -> 1 | IB9: =IF($E9=5,HB9-5,NA()) -> 1 | IC9: =HB9-'Zusammenfassung Tag1-4'!$I$2/18 -> 5 | ID9: =IC9+ID8 -> 29 | IF9: =IE9+IF8 -> 0 | IH9: =IG9+IH8 -> 0 | II9: =IF(IE9-IG9<=$E9-2,1,0) -> 1 | IJ9: =II9+IJ8 -> 7 | IK9: =IF(II9=0,IF(IE9=$E9,1,0),0) -> 0 | IL9: =IK9+IL8 -> 0 | IM9: =IF($E9-IE9=1,1,0) -> 0 | IN9: =IM9+IN8 -> 0 | IO9: =IF(IE9=$E9,1,0) -> 0 | IP9: =IO9+IP8 -> 0 | IQ9: =IF(IE9-$E9=1,1,0) -> 0 | IR9: =IQ9+IR8 -> 0 | IS9: =IF(IE9-$E9>=2,1,0) -> 0 | IT9: =IS9+IT8 -> 0 | IU9: =IF(IG9=0,1,0) -> 1 | IV9: =IU9+IV8 -> 7 | IW9: =IF(IG9=1,1,0) -> 0 | IX9: =IW9+IX8 -> 0 | IY9: =IF(IG9=2,1,0) -> 0 | IZ9: =IY9+IZ8 -> 0 | JA9: =IF(IG9>=3,1,0) -> 0 | JB9: =JA9+JB8 -> 0 | JE9: =IF($E9=5,IE9-5,NA()) -> -5 | JF9: =IE9-'Zusammenfassung Tag1-4'!$J$2/18 -> -3 | JG9: =JF9+JG8 -> -21 | JI9: =JH9+JI8 -> 0 | JK9: =JJ9+JK8 -> 0 | JL9: =IF(JH9-JJ9<=$E9-2,1,0) -> 1 | JM9: =JL9+JM8 -> 7 | JN9: =IF(JL9=0,IF(JH9=$E9,1,0),0) -> 0 | JO9: =JN9+JO8 -> 0 | JP9: =IF($E9-JH9=1,1,0) -> 0 | JQ9: =JP9+JQ8 -> 0 | JR9: =IF(JH9=$E9,1,0) -> 0 | JS9: =JR9+JS8 -> 0 | JT9: =IF(JH9-$E9=1,1,0) -> 0 | JU9: =JT9+JU8 -> 0 | JV9: =IF(JH9-$E9>=2,1,0) -> 0 | JW9: =JV9+JW8 -> 0 | JX9: =IF(JJ9=0,1,0) -> 1 | JY9: =JX9+JY8 -> 7 | JZ9: =IF(JJ9=1,1,0) -> 0 | KA9: =JZ9+KA8 -> 0 | KB9: =IF(JJ9=2,1,0) -> 0 | KC9: =KB9+KC8 -> 0 | KD9: =IF(JJ9>=3,1,0) -> 0 | KE9: =KD9+KE8 -> 0 | KH9: =IF($E9=5,JH9-5,NA()) -> -5 | KI9: =JH9-'Zusammenfassung Tag1-4'!$K$2/18 -> -0.77777778 | KJ9: =KI9+KJ8 -> -5.4444444
